Workbook
Name __gdp2: #REF!
Name __nlp2: #REF!
Name __Old3: '[1]T103'!#REF!
Name __Old4: '[1]T208'!#REF!
Name __Old5: '[1]T208'!#REF!
Name __Old6: '[1]T208'!#REF!
Name __Old7: '[1]T208'!#REF!
Name __old8: '[1]T208'!#REF!
Name _gdp2: #REF!
Name _nlp2: #REF!
Name _PMI2: #REF!
Name bad_debt: #REF!
Name bankruptcy: #REF!
Name BoxPlot: "BoxPlot"
Name Bubble: "Bubble"
Name buy_rent_gap: #REF!
Name CAB: #REF!
Name Candlestick: "Candlestick"
Name car: #REF!
Name Chart: "Chart"
Name ChartImage: "ChartImage"
Name CMTH5: '[1]T208'!#REF!
Name CMTH6: '[1]T208'!#REF!
Name CMTH7: '[1]T208'!#REF!
Name ColumnRange: "ColumnRange"
Name cpi: #REF!
Name DATA: '[1]T5011'!#REF!
Name DATA1: '[1]T502'!#REF!
Name DATA2: '[1]T502'!#REF!
Name deposits: #REF!
Name Dumbbell: "Dumbbell"
Name equity: #REF!
Name fiscal: #REF!
Name fwd: #REF!
Name gdp: #REF!
Name Heatmap: "Heatmap"
Name Histogram: "Histogram"
Name insert: [2]!insert
Name interest: #REF!
Name IQ_CH: 110000
Name IQ_CQ: 5000
Name IQ_CY: 10000
Name IQ_DAILY: 500000
Name IQ_FH: 100000
Name IQ_FQ: 500
Name IQ_FY: 1000
Name IQ_LTM: 2000
Name IQ_MONTH: 15000
Name IQ_NTM: 6000
Name IQ_WEEK: 50000
Name IQ_YTD: 3000
Name labour: #REF!
Name loan: #REF!
Name loans: #REF!
Name LTD: #REF!
Name Map: "Map"
Name mci: #REF!
Name money: #REF!
Name Month_date: '[1]T305'!#REF!
Name NIM: #REF!

Sheet 00 Index
B2: Hong Kong Loan Composition — Data Workbook
B3: 香港贷款结构数据簿 ｜ aligned to HK_Loan_Composition_Report_EN.html
B4: As-of: HKMA end-June 2026 (headline) ｜ KPMG lender ranking: 2024 ｜ Unit: HK$ million unless noted ｜ Rebuilt 2026-10-02
A7: # | B7: Sheet | C7: 报表对应 | D7: What it holds / 内容 | E7: Kept because | F7: Source
A8: 1 | B8: 01 Snapshot | C8: Headline KPIs + composition table | D8: Total / in-HK / outside-HK; property*, trade finance, manufacturing, wholesale & retail; other-in-HK selected items | E8: HTML slide 1 | F8: HKMA 1.2 + 3.4.1 + 3.5.1
A9: 2 | B9: 02 Trade finance trend | C9: Trade-financing time series | D9: Dec-2021 … Jun-2026 seven points used in the report, plus HKD / FC mix (84% FX at Jun-2026) | E9: HTML slide 2 | F9: HKMA 3.4.1
A10: 3 | B10: 03 Lenders 2024 | C10: Top 10 + concentration | D10: Top 10 names/shares; Top 10 76% / 11–20 14% / Other 10%; 11–20 kept as supporting rows | E10: HTML slide 3 | F10: KPMG 2024
A11: 4 | B11: 04 Sources | C11: Footnotes / sources | D11: Official HKMA Monthly Statistical Bulletin tables + KPMG landscape only | E11: HTML footnotes | F11: HKMA / KPMG
A12: 5 | B12: A HKMA 1.2 | C12: Appendix — banking aggregates | D12: Loans for use in HK / outside HK / total only (deposits, NPL, assets dropped) | E12: Feeds Snapshot KPIs | F12: HKMA Table 1.2
A13: 6 | B13: A HKMA 3.4.1 | C13: Appendix — loans by type | D13: Hong Kong goods trade finance + offshore merchandising; HKD / FC split | E13: Feeds TF stock & FX share | F13: HKMA Table 3.4.1
A14: 7 | B14: A HKMA 3.5.1 | C14: Appendix — use in HK by sector | D14: Only sectors cited in the report (property, manufacturing, W&R, financial, personal, transport, IT, electricity & gas) | E14: Feeds composition | F14: HKMA Table 3.5.1
B16: Removed from the previous workbook / 已删除
B17: # | C17: Old sheet / table | D17: Why removed / 删除原因
B18: Chart | C18: Empty sheet; no series, no chart object used by the HTML report.
B19: 3.13.1 Mainland-related lending | C19: Not cited in the loan-composition report.
B20: Economics Sectors(integrate) | C20: 2003– quarterly history; report only uses Dec-2021…Jun-2026 TF points already in 3.4.1.
B21: Summary — manufacturing / agriculture / transport / utilities sub-tree | C21: HTML does not publish textiles, fisheries, taxis, HOS flats, etc.
B22: Data Source — C&SD / TID / TDC trade links | C22: Leftover from the goods-trade workbook; not a source for this slide.
B23: 1.2 unused columns | C23: Deposits, external claims, classified loans, mortgage delinquency, card charge-off dropped.
B24: 3.5.1 unused columns | C24: All sector sub-rows not named on the slide dropped.
B25: KPMG slide OCR dump | C25: Full page-22 transcription removed; definition + source kept on 03 / 04.
B27: Backup of the file before this rebuild: financial_datasummit_backup_20261002.xlsx (same folder). An earlier copy also exists as financial_datasummit_backup_original.xlsx. Numbers on 01 / 02 are Excel formulas pointing at the appendix sheets — do not overwrite appendix period keys.

Sheet 01 Snapshot
A1: 01 Headline snapshot & loan composition
A2: Report date: end-June 2026 vs end-June 2025. Amounts in HK$ million. Shares of total loans (Table 1.2). YoY and share-ppt change are formulas.
A4: A. Headline KPIs
A5: Item | B5: 项目 | C5: Jun-2026 | D5: Share of total | E5: YoY | F5: Jun-2025 | G5: Source table | H5: Note
A6: Total loans and advances | B6: 贷款及垫款总额 | C6: =INDEX('A HKMA 1.2'!D:D,MATCH("2026-06",'A HKMA 1.2'!A:A,0)) -> 10787896 | D6: =C6/$C$6 -> 1 | E6: =C6/F6-1 -> 0.061969943 | F6: =INDEX('A HKMA 1.2'!D:D,MATCH("2025-06",'A HKMA 1.2'!A:A,0)) -> 10158381 | G6: HKMA 1.2 | H6: HTML: HK$10.79 tn +6.2%
A7: Loans for use in Hong Kong | B7: 在香港使用的贷款 | C7: =INDEX('A HKMA 1.2'!B:B,MATCH("2026-06",'A HKMA 1.2'!A:A,0)) -> 8095245.2 | D7: =C7/$C$6 -> 0.75040076 | E7: =C7/F7-1 -> 0.058187952 | F7: =INDEX('A HKMA 1.2'!B:B,MATCH("2025-06",'A HKMA 1.2'!A:A,0)) -> 7650101.4 | G7: HKMA 1.2 | H7: HTML: 75.0% HK$8.10 tn +5.8%
A8: Loans for use outside Hong Kong | B8: 在香港以外使用的贷款 | C8: =INDEX('A HKMA 1.2'!C:C,MATCH("2026-06",'A HKMA 1.2'!A:A,0)) -> 2692650.5 | D8: =C8/$C$6 -> 0.24959924 | E8: =C8/F8-1 -> 0.073504786 | F8: =INDEX('A HKMA 1.2'!C:C,MATCH("2025-06",'A HKMA 1.2'!A:A,0)) -> 2508280 | G8: HKMA 1.2 | H8: HTML: 25.0% HK$2.69 tn +7.4%
A10: B. Composition — segments shown on the slide
A11: Segment | B11: 分项 | C11: Jun-2026 | D11: Share of total | E11: YoY | F11: Share ppt chg | G11: Jun-2025 | H11: Construction / 构成 | I11: Source table
A12: Property lending* | B12: 物业相关贷款* | C12: =INDEX('A HKMA 3.5.1'!L:L,MATCH("2026-06",'A HKMA 3.5.1'!A:A,0)) -> 3272236.5 | D12: =C12/$C$6 -> 0.30332482 | E12: =IF(G12=0,NA(),C12/G12-1) -> -0.018856645 | F12: =(D12-G12/$F$6)*100 -> -2.4987898 | G12: =INDEX('A HKMA 3.5.1'!L:L,MATCH("2025-06",'A HKMA 3.5.1'!A:A,0)) -> 3335125.8 | H12: Development & investment + purchase of other residential | I12: HKMA 3.5.1
A13: of which: property development & investment | B13: 其中：物业发展及投资 | C13: =INDEX('A HKMA 3.5.1'!C:C,MATCH("2026-06",'A HKMA 3.5.1'!A:A,0)) -> 1313893.8 | D13: =C13/$C$6 -> 0.12179334 | E13: =IF(G13=0,NA(),C13/G13-1) -> -0.091231718 | F13: =(D13-G13/$F$6)*100 -> -2.0532123 | G13: =INDEX('A HKMA 3.5.1'!C:C,MATCH("2025-06",'A HKMA 3.5.1'!A:A,0)) -> 1445796.3 | H13: HTML: HK$1,314 bn 12.2% −9.1% | I13: HKMA 3.5.1
A14: of which: purchase of other residential property | B14: 其中：购买其他住宅楼宇 | C14: =INDEX('A HKMA 3.5.1'!D:D,MATCH("2026-06",'A HKMA 3.5.1'!A:A,0)) -> 1958342.7 | D14: =C14/$C$6 -> 0.18153148 | E14: =IF(G14=0,NA(),C14/G14-1) -> 0.036527879 | F14: =(D14-G14/$F$6)*100 -> -0.44557755 | G14: =INDEX('A HKMA 3.5.1'!D:D,MATCH("2025-06",'A HKMA 3.5.1'!A:A,0)) -> 1889329.5 | H14: HTML: HK$1,958 bn 18.2% +3.7% | I14: HKMA 3.5.1
A15: Trade financing | B15: 贸易融资 | C15: =INDEX('A HKMA 3.4.1'!H:H,MATCH("2026-06",'A HKMA 3.4.1'!A:A,0)) -> 436089.19 | D15: =C15/$C$6 -> 0.040423935 | E15: =IF(G15=0,NA(),C15/G15-1) -> 0.1591215 | F15: =(D15-G15/$F$6)*100 -> 0.33881247 | G15: =INDEX('A HKMA 3.4.1'!H:H,MATCH("2025-06",'A HKMA 3.4.1'!A:A,0)) -> 376223.88 | H15: HK goods TF + offshore merchandising | I15: HKMA 3.4.1
A16: Manufacturing | B16: 制造业 | C16: =INDEX('A HKMA 3.5.1'!B:B,MATCH("2026-06",'A HKMA 3.5.1'!A:A,0)) -> 363633.97 | D16: =C16/$C$6 -> 0.03370759 | E16: =IF(G16=0,NA(),C16/G16-1) -> 0.11931883 | F16: =(D16-G16/$F$6)*100 -> 0.1727026 | G16: =INDEX('A HKMA 3.5.1'!B:B,MATCH("2025-06",'A HKMA 3.5.1'!A:A,0)) -> 324870.77 | H16: Table 3.5.1 manufacturing total (sub-industries not shown) | I16: HKMA 3.5.1
A17: Wholesale and retail trade | B17: 批发及零售业 | C17: =INDEX('A HKMA 3.5.1'!E:E,MATCH("2026-06",'A HKMA 3.5.1'!A:A,0)) -> 312060.83 | D17: =C17/$C$6 -> 0.028926941 | E17: =IF(G17=0,NA(),C17/G17-1) -> 0.062694715 | F17: =(D17-G17/$F$6)*100 -> 0.0019728555 | G17: =INDEX('A HKMA 3.5.1'!E:E,MATCH("2025-06",'A HKMA 3.5.1'!A:A,0)) -> 293650.49 | I17: HKMA 3.5.1
A18: Other uses in Hong Kong (residual) | B18: 在港其他用途（残差） | C18: =C7-C12-C16-C17-C15 -> 3711224.7 | D18: =C18/$C$6 -> 0.34401748 | E18: =IF(G18=0,NA(),C18/G18-1) -> 0.11776116 | F18: =(D18-G18/$F$6)*100 -> 1.7171067 | G18: =INDEX('A HKMA 1.2'!B:B,MATCH("2025-06",'A HKMA 1.2'!A:A,0))-G12-G16-G17-G15 -> 3320230.5 | H18: HTML: 34.4% — residual after property / TF / mfg / W&R | I18: Derived
A20: C. Selected items inside “other uses in HK”
A21: Item | B21: 项目 | C21: Jun-2026 | D21: Share of total | E21: YoY | F21: Jun-2025 | G21: Source table | H21: HTML readout
A22: Financial concerns | B22: 与财务及金融有关公司 | C22: =INDEX('A HKMA 3.5.1'!F:F,MATCH("2026-06",'A HKMA 3.5.1'!A:A,0)) -> 1032728.3 | D22: =C22/$C$6 -> 0.095730281 | E22: =C22/F22-1 -> 0.13429924 | F22: =INDEX('A HKMA 3.5.1'!F:F,MATCH("2025-06",'A HKMA 3.5.1'!A:A,0)) -> 910454.89 | G22: HKMA 3.5.1 | H22: 9.6%
A23: Other private purposes (personal) | B23: 其他私人用途 | C23: =INDEX('A HKMA 3.5.1'!G:G,MATCH("2026-06",'A HKMA 3.5.1'!A:A,0)) -> 794177.67 | D23: =C23/$C$6 -> 0.073617478 | E23: =C23/F23-1 -> 0.19433895 | F23: =INDEX('A HKMA 3.5.1'!G:G,MATCH("2025-06",'A HKMA 3.5.1'!A:A,0)) -> 664951.66 | G23: HKMA 3.5.1 | H23: 7.4%
A24: Transport and transport equipment | B24: 运输及运输设备 | C24: =INDEX('A HKMA 3.5.1'!H:H,MATCH("2026-06",'A HKMA 3.5.1'!A:A,0)) -> 331240.65 | D24: =C24/$C$6 -> 0.030704843 | E24: =C24/F24-1 -> 0.1664319 | F24: =INDEX('A HKMA 3.5.1'!H:H,MATCH("2025-06",'A HKMA 3.5.1'!A:A,0)) -> 283977.7 | G24: HKMA 3.5.1 | H24: 3.1%
A25: Information technology | B25: 资讯科技 | C25: =INDEX('A HKMA 3.5.1'!I:I,MATCH("2026-06",'A HKMA 3.5.1'!A:A,0)) -> 228617.92 | D25: =C25/$C$6 -> 0.021192077 | E25: =C25/F25-1 -> 0.12703082 | F25: =INDEX('A HKMA 3.5.1'!I:I,MATCH("2025-06",'A HKMA 3.5.1'!A:A,0)) -> 202849.75 | G25: HKMA 3.5.1 | H25: 2.1%
A26: Electricity and gas | B26: 电力及气体燃料 | C26: =INDEX('A HKMA 3.5.1'!J:J,MATCH("2026-06",'A HKMA 3.5.1'!A:A,0)) -> 215920.42 | D26: =C26/$C$6 -> 0.020015064 | E26: =C26/F26-1 -> 0.0042161509 | F26: =INDEX('A HKMA 3.5.1'!J:J,MATCH("2025-06",'A HKMA 3.5.1'!A:A,0)) -> 215013.89 | G26: HKMA 3.5.1 | H26: 2.0%
A28: * Property lending = loans for property development and investment + loans for the purchase of other residential property. Excludes loans for the purchase of Home Ownership Scheme / Private Sector Participation Scheme / Tenants Purchase Scheme flats. Table 3.5.1 classifies loans by economic use and excludes trade-financing loans; trade financing is taken from Table 3.4.1. Almost all trade-financing stock sits inside Table 1.2 “loans for use in Hong Kong”, so the residual “other uses in HK” is in-HK minus property* minus manufacturing minus wholesale & retail minus trade financing.

Sheet 02 Trade finance trend
A1: 02 Trade-financing stock — report series
A2: Seven period-ends published on the HTML slide. Amounts in HK$ million. FX share at end-June 2026 is the FC portion of Table 3.4.1 trade finance.
A4: A. Periods used in the report
A5: Period | B5: HK goods trade finance | C5: Offshore merchandising | D5: Trade finance total | E5: of which HKD | F5: of which FC | G5: FC share | H5: HTML readout (HK$ bn)
A6: 2021-12 | B6: =INDEX('A HKMA 3.4.1'!D:D,MATCH("2021-12",'A HKMA 3.4.1'!A:A,0)) -> 291386.29 | C6: =INDEX('A HKMA 3.4.1'!G:G,MATCH("2021-12",'A HKMA 3.4.1'!A:A,0)) -> 193643.95 | D6: =B6+C6 -> 485030.24 | E6: =INDEX('A HKMA 3.4.1'!I:I,MATCH("2021-12",'A HKMA 3.4.1'!A:A,0)) -> 68943.894 | F6: =INDEX('A HKMA 3.4.1'!J:J,MATCH("2021-12",'A HKMA 3.4.1'!A:A,0)) -> 416086.35 | G6: =F6/D6 -> 0.85785651 | H6: 485
A7: 2022-12 | B7: =INDEX('A HKMA 3.4.1'!D:D,MATCH("2022-12",'A HKMA 3.4.1'!A:A,0)) -> 247483.5 | C7: =INDEX('A HKMA 3.4.1'!G:G,MATCH("2022-12",'A HKMA 3.4.1'!A:A,0)) -> 172208.27 | D7: =B7+C7 -> 419691.78 | E7: =INDEX('A HKMA 3.4.1'!I:I,MATCH("2022-12",'A HKMA 3.4.1'!A:A,0)) -> 70691.279 | F7: =INDEX('A HKMA 3.4.1'!J:J,MATCH("2022-12",'A HKMA 3.4.1'!A:A,0)) -> 349000.5 | G7: =F7/D7 -> 0.83156382 | H7: 420
A8: 2023-12 | B8: =INDEX('A HKMA 3.4.1'!D:D,MATCH("2023-12",'A HKMA 3.4.1'!A:A,0)) -> 205113.08 | C8: =INDEX('A HKMA 3.4.1'!G:G,MATCH("2023-12",'A HKMA 3.4.1'!A:A,0)) -> 159512.79 | D8: =B8+C8 -> 364625.87 | E8: =INDEX('A HKMA 3.4.1'!I:I,MATCH("2023-12",'A HKMA 3.4.1'!A:A,0)) -> 65989.26 | F8: =INDEX('A HKMA 3.4.1'!J:J,MATCH("2023-12",'A HKMA 3.4.1'!A:A,0)) -> 298636.61 | G8: =F8/D8 -> 0.819022 | H8: 365
A9: 2024-12 | B9: =INDEX('A HKMA 3.4.1'!D:D,MATCH("2024-12",'A HKMA 3.4.1'!A:A,0)) -> 231747.78 | C9: =INDEX('A HKMA 3.4.1'!G:G,MATCH("2024-12",'A HKMA 3.4.1'!A:A,0)) -> 149495.09 | D9: =B9+C9 -> 381242.87 | E9: =INDEX('A HKMA 3.4.1'!I:I,MATCH("2024-12",'A HKMA 3.4.1'!A:A,0)) -> 71266.122 | F9: =INDEX('A HKMA 3.4.1'!J:J,MATCH("2024-12",'A HKMA 3.4.1'!A:A,0)) -> 309976.75 | G9: =F9/D9 -> 0.81306897 | H9: 381
A10: 2025-06 | B10: =INDEX('A HKMA 3.4.1'!D:D,MATCH("2025-06",'A HKMA 3.4.1'!A:A,0)) -> 223874.52 | C10: =INDEX('A HKMA 3.4.1'!G:G,MATCH("2025-06",'A HKMA 3.4.1'!A:A,0)) -> 152349.36 | D10: =B10+C10 -> 376223.88 | E10: =INDEX('A HKMA 3.4.1'!I:I,MATCH("2025-06",'A HKMA 3.4.1'!A:A,0)) -> 77937.981 | F10: =INDEX('A HKMA 3.4.1'!J:J,MATCH("2025-06",'A HKMA 3.4.1'!A:A,0)) -> 298285.9 | G10: =F10/D10 -> 0.79284148 | H10: 376
A11: 2025-12 | B11: =INDEX('A HKMA 3.4.1'!D:D,MATCH("2025-12",'A HKMA 3.4.1'!A:A,0)) -> 242164.48 | C11: =INDEX('A HKMA 3.4.1'!G:G,MATCH("2025-12",'A HKMA 3.4.1'!A:A,0)) -> 148615.73 | D11: =B11+C11 -> 390780.21 | E11: =INDEX('A HKMA 3.4.1'!I:I,MATCH("2025-12",'A HKMA 3.4.1'!A:A,0)) -> 70403.018 | F11: =INDEX('A HKMA 3.4.1'!J:J,MATCH("2025-12",'A HKMA 3.4.1'!A:A,0)) -> 320377.19 | G11: =F11/D11 -> 0.81983986 | H11: 391
A12: 2026-06 | B12: =INDEX('A HKMA 3.4.1'!D:D,MATCH("2026-06",'A HKMA 3.4.1'!A:A,0)) -> 262817.16 | C12: =INDEX('A HKMA 3.4.1'!G:G,MATCH("2026-06",'A HKMA 3.4.1'!A:A,0)) -> 173272.03 | D12: =B12+C12 -> 436089.19 | E12: =INDEX('A HKMA 3.4.1'!I:I,MATCH("2026-06",'A HKMA 3.4.1'!A:A,0)) -> 69891.593 | F12: =INDEX('A HKMA 3.4.1'!J:J,MATCH("2026-06",'A HKMA 3.4.1'!A:A,0)) -> 366197.6 | G12: =F12/D12 -> 0.83973097 | H12: 436
A14: B. Currency mix at end-June 2026 (HTML: about 84% foreign-currency)
A28: Monthly history for 2018-12 to 2026-07 is on sheet A HKMA 3.4.1. KPMG’s 2024 market total of HK$500.9 billion is a lender-side ranking and is not comparable with the HKMA 3.4.1 stock (HK$381 billion at end-December 2024).

Sheet 03 Lenders 2024
A1: 03 Hong Kong trade-finance lenders, 2024 | Z1: 500.9
A2: KPMG: 77 authorized institutions and local representative offices; advances of HK$500.9 billion. Parent groups aggregated (e.g. DBS Bank (Hong Kong) + DBS Bank Ltd. = DBS Bank). Unit: HK$ billion. | Z2: KPMG market total HK$ bn
A4: A. Top 10 (shown on the slide)
A5: Rank | B5: Institution (EN) | C5: 机构（中文） | D5: Advances (HK$ bn) | E5: Share of market | F5: Band | G5: HTML share
A6: 1 | B6: HSBC | C6: 汇丰银行 | D6: 153.1 | E6: =D6/$Z$1 -> 0.30564983 | F6: Top 10 | G6: 30.6%
A7: 2 | B7: Standard Chartered Bank | C7: 渣打银行 | D7: 63.5 | E7: =D7/$Z$1 -> 0.12677181 | F7: Top 10 | G7: 12.7%
A8: 3 | B8: Bank of China | C8: 中国银行 | D8: 47 | E8: =D8/$Z$1 -> 0.093831104 | F8: Top 10 | G8: 9.4%
A9: 4 | B9: Hang Seng Bank | C9: 恒生银行 | D9: 30.5 | E9: =D9/$Z$1 -> 0.060890397 | F9: Top 10 | G9: 6.1%
A10: 5 | B10: DBS Bank | C10: 星展银行 | D10: 27.8 | E10: =D10/$Z$1 -> 0.0555001 | F10: Top 10 | G10: 5.6%
A11: 6 | B11: United Overseas Bank | C11: 大华银行 | D11: 16.9 | E11: =D11/$Z$1 -> 0.033739269 | F11: Top 10 | G11: 3.4%
A12: 7 | B12: Banco Santander, S.A. | C12: 桑坦德银行 | D12: 10.8 | E12: =D12/$Z$1 -> 0.02156119 | F12: Top 10 | G12: 2.2%
A13: 8 | B13: Banco Bilbao Vizcaya Argentaria S.A. | C13: 西班牙对外银行（BBVA） | D13: 10.4 | E13: =D13/$Z$1 -> 0.020762627 | F13: Top 10 | G13: 2.1%
A14: 9 | B14: BNP Paribas | C14: 法国巴黎银行 | D14: 9.8 | E14: =D14/$Z$1 -> 0.019564783 | F14: Top 10 | G14: 2.0%
A15: 10 | B15: ICBC | C15: 中国工商银行 | D15: 9.7 | E15: =D15/$Z$1 -> 0.019365143 | F15: Top 10 | G15: 1.9%
A16: 11 | B16: Citibank | C16: 花旗银行 | D16: 9.7 | E16: =D16/$Z$1 -> 0.019365143 | F16: 11–20
A17: 12 | B17: Deutsche Bank Aktiengesellschaft | C17: 德意志银行 | D17: 9.6 | E17: =D17/$Z$1 -> 0.019165502 | F17: 11–20
A18: 13 | B18: Nanyang Commercial Bank | C18: 南洋商业银行 | D18: 8.9 | E18: =D18/$Z$1 -> 0.017768018 | F18: 11–20
A19: 14 | B19: Shanghai Commercial Bank | C19: 上海商业银行 | D19: 7.6 | E19: =D19/$Z$1 -> 0.015172689 | F19: 11–20
A20: 15 | B20: China Citic | C20: 中信银行 | D20: 7.2 | E20: =D20/$Z$1 -> 0.014374127 | F20: 11–20
A21: 16 | B21: Bank of East Asia | C21: 东亚银行 | D21: 6.9 | E21: =D21/$Z$1 -> 0.013775205 | F21: 11–20
A22: 17 | B22: OCBC Bank | C22: 华侨银行 | D22: 6.5 | E22: =D22/$Z$1 -> 0.012976642 | F22: 11–20
A23: 18 | B23: Bank of America National Association | C23: 美国银行 | D23: 6.4 | E23: =D23/$Z$1 -> 0.012777001 | F23: 11–20
A24: 19 | B24: Dah Sing Bank | C24: 大新银行 | D24: 4.9 | E24: =D24/$Z$1 -> 0.0097823917 | F24: 11–20
A25: 20 | B25: Fubon | C25: 富邦银行 | D25: 4.7 | E25: =D25/$Z$1 -> 0.0093831104 | F25: 11–20
A26: — | B26: Others | C26: 其他 | D26: 49.1 | E26: =D26/$Z$1 -> 0.098023558 | F26: Other | G26: 10%
A29: B. Concentration bands (HTML: Top 10 76% · 11–20 14% · Other 10%)
A30: Band | B30: Advances (HK$ bn) | C30: Share of market | D30: HTML
A31: Top 10 | B31: =SUM(D6:D15) -> 379.5 | C31: =B31/$Z$1 -> 0.75763625 | D31: 76%
A32: 11–20 | B32: =SUM(D16:D25) -> 72.4 | C32: =B32/$Z$1 -> 0.14453983 | D32: 14%
A33: Other | B33: =D26 -> 49.1 | C33: =B33/$Z$1 -> 0.098023558 | D33: 10%
A34: Total | B34: =B31+B32+B33 -> 501 | C34: =B34/$Z$1 -> 1.0001996
A36: Ranks 11–20 are not listed on the HTML slide but are retained here because they support the 14% band. Shares are computed on the KPMG market total of HK$500.9 billion (cell Z1). This lender-side stock is not comparable with the HKMA Table 3.4.1 trade-finance stock (HK$381 billion at end-December 2024; HK$436 billion at end-June 2026). Source: company financial disclosures, HKMA, KPMG analysis.

Sheet 04 Sources
A1: 04 Sources
A2: Only sources used by HK_Loan_Composition_Report_EN.html. Trade-statistics leftovers (C&SD / TID / TDC) and HKMA 3.13.1 have been dropped.
A4: # | B4: Table / item | C4: Description | D4: Link | E4: Used on
A5: 1 | B5: HKMA Table 1.2 | C5: Monthly Statistical Bulletin — banking statistics (loans for use in / outside Hong Kong, total loans) | D5: https://apidocs.hkma.gov.hk/apidata/?api=market-data-and-statistics.monthly-statistical-bulletin.financial.banking-statistics&page=1 | E5: 01 Snapshot KPIs
A6: 2 | B6: HKMA Table 3.4.1 | C6: Loans and advances by type — authorized institutions (trade financing of HK goods + offshore merchandising, HKD / FC) | D6: https://apidocs.hkma.gov.hk/documentation/market-data-and-statistics/monthly-statistical-bulletin/banking/loans-by-type/ | E6: 01 Snapshot TF; 02 trend
A7: 3 | B7: HKMA Table 3.5.1 | C7: Loans and advances for use in Hong Kong by economic sector — authorized institutions (excludes trade financing) | D7: https://apidocs.hkma.gov.hk/apidata/?api=market-data-and-statistics.monthly-statistical-bulletin.banking.loans-by-sector-ais | E7: 01 Snapshot composition
A8: 4 | B8: KPMG 2024 landscape | C8: Hong Kong trade finance lenders landscape, p.22 — top 20 by advances to customers; market total HK$500.9 billion | D8: Company financial disclosures, HKMA, KPMG analysis | E8: 03 Lenders 2024
B10: Bulletin source: Hong Kong Monetary Authority, Monthly Statistical Bulletin. KPMG definition: trade finance covers finance of imports to Hong Kong, exports and re-exports from Hong Kong, and merchandising trade, classified with reference to HKMA guidelines. Do not add the KPMG 2024 total to, or subtract it from, the HKMA 3.4.1 stock.

Sheet A HKMA 1.2
A1: Appendix — HKMA Monthly Statistical Bulletin Table 1.2
A2: Banking statistics, authorized institutions. Unit: HK$ million. Periods labelled YYYY-00 in the source extract are year-end (equal to December of that year).
A4: Period | B4: Loans for use in HK | C4: Loans for use outside HK | D4: Total loans and advances | E4: Period type
A5: 2026-07 | B5: 8070867 | C5: 2738987.2 | D5: 10809854 | E5: month-end
A6: 2026-06 | B6: 8095245.2 | C6: 2692650.5 | D6: 10787896 | E6: month-end
A7: 2026-05 | B7: 7981206.3 | C7: 2664945.9 | D7: 10646152 | E7: month-end
A8: 2026-04 | B8: 7869195.5 | C8: 2627662.1 | D8: 10496858 | E8: month-end
A9: 2026-03 | B9: 7861821.8 | C9: 2578456.3 | D9: 10440278 | E9: month-end
A10: 2026-02 | B10: 7721916.9 | C10: 2580372.9 | D10: 10302290 | E10: month-end
A11: 2026-01 | B11: 7688694.2 | C11: 2556717.2 | D11: 10245411 | E11: month-end
A12: 2025-12 | B12: 7635305.1 | C12: 2500837.4 | D12: 10136142 | E12: month-end
A13: 2025-11 | B13: 7546764.4 | C13: 2455791.4 | D13: 10002556 | E13: month-end
A14: 2025-10 | B14: 7551750.3 | C14: 2445317.2 | D14: 9997067.5 | E14: month-end
A15: 2025-09 | B15: 7617255.6 | C15: 2451320.5 | D15: 10068576 | E15: month-end
A16: 2025-08 | B16: 7570020.6 | C16: 2433495.8 | D16: 10003516 | E16: month-end
... A23: 2021-00 | B23: 7712295.5 | C23: 3180851.8 | D23: 10893147 | E23: year-end

Sheet A HKMA 3.4.1
A1: Appendix — HKMA Monthly Statistical Bulletin Table 3.4.1
A2: Loans and advances by type. Trade financing = finance of HK imports / exports / re-exports + merchandising trade not touching HK. Unit: HK$ million.
A4: Period | B4: HK goods TF — HKD | C4: HK goods TF — FC | D4: HK goods TF — total | E4: Offshore merch. — HKD | F4: Offshore merch. — FC | G4: Offshore merch. — total | H4: Trade finance total | I4: of which HKD | J4: of which FC | K4: FC share
A5: 2026-07 | B5: 56511.102 | C5: 193800.71 | D5: 250311.81 | E5: 13053.365 | F5: 158463.42 | G5: 171516.78 | H5: =D5+G5 -> 421828.59 | I5: =B5+E5 -> 69564.467 | J5: =C5+F5 -> 352264.12 | K5: =IF(H5=0,NA(),J5/H5) -> 0.83508831
A6: 2026-06 | B6: 57111.395 | C6: 205705.76 | D6: 262817.16 | E6: 12780.198 | F6: 160491.84 | G6: 173272.03 | H6: =D6+G6 -> 436089.19 | I6: =B6+E6 -> 69891.593 | J6: =C6+F6 -> 366197.6 | K6: =IF(H6=0,NA(),J6/H6) -> 0.83973097
A7: 2026-05 | B7: 57013.091 | C7: 186630.31 | D7: 243643.4 | E7: 12466.324 | F7: 158653.3 | G7: 171119.62 | H7: =D7+G7 -> 414763.02 | I7: =B7+E7 -> 69479.415 | J7: =C7+F7 -> 345283.6 | K7: =IF(H7=0,NA(),J7/H7) -> 0.83248406
A8: 2026-04 | B8: 59126.986 | C8: 173799.62 | D8: 232926.61 | E8: 11984.01 | F8: 160556.36 | G8: 172540.37 | H8: =D8+G8 -> 405466.98 | I8: =B8+E8 -> 71110.996 | J8: =C8+F8 -> 334355.98 | K8: =IF(H8=0,NA(),J8/H8) -> 0.82461951
A9: 2026-03 | B9: 59339.624 | C9: 182422.15 | D9: 241761.77 | E9: 11972.022 | F9: 167767.32 | G9: 179739.34 | H9: =D9+G9 -> 421501.11 | I9: =B9+E9 -> 71311.646 | J9: =C9+F9 -> 350189.46 | K9: =IF(H9=0,NA(),J9/H9) -> 0.83081505
A10: 2026-02 | B10: 58040.729 | C10: 172201.21 | D10: 230241.94 | E10: 13041.727 | F10: 126050.45 | G10: 139092.18 | H10: =D10+G10 -> 369334.12 | I10: =B10+E10 -> 71082.456 | J10: =C10+F10 -> 298251.66 | K10: =IF(H10=0,NA(),J10/H10) -> 0.80753889
A11: 2026-01 | B11: 58057.961 | C11: 166061.31 | D11: 224119.27 | E11: 13924.763 | F11: 121553.74 | G11: 135478.5 | H11: =D11+G11 -> 359597.78 | I11: =B11+E11 -> 71982.724 | J11: =C11+F11 -> 287615.05 | K11: =IF(H11=0,NA(),J11/H11) -> 0.79982434
A12: 2025-12 | B12: 55987.338 | C12: 186177.14 | D12: 242164.48 | E12: 14415.68 | F12: 134200.05 | G12: 148615.73 | H12: =D12+G12 -> 390780.21 | I12: =B12+E12 -> 70403.018 | J12: =C12+F12 -> 320377.19 | K12: =IF(H12=0,NA(),J12/H12) -> 0.81983986
A13: 2025-11 | B13: 58570.371 | C13: 154966.04 | D13: 213536.41 | E13: 13974.943 | F13: 116204.61 | G13: 130179.55 | H13: =D13+G13 -> 343715.96 | I13: =B13+E13 -> 72545.314 | J13: =C13+F13 -> 271170.65 | K13: =IF(H13=0,NA(),J13/H13) -> 0.78893819
A14: 2025-10 | B14: 57795.635 | C14: 153915.67 | D14: 211711.3 | E14: 14483.044 | F14: 113621.16 | G14: 128104.21 | H14: =D14+G14 -> 339815.51 | I14: =B14+E14 -> 72278.679 | J14: =C14+F14 -> 267536.83 | K14: =IF(H14=0,NA(),J14/H14) -> 0.78730023
A15: 2025-09 | B15: 61251.15 | C15: 166019.3 | D15: 227270.45 | E15: 15221.531 | F15: 131263.17 | G15: 146484.71 | H15: =D15+G15 -> 373755.16 | I15: =B15+E15 -> 76472.681 | J15: =C15+F15 -> 297282.48 | K15: =IF(H15=0,NA(),J15/H15) -> 0.79539365
A16: 2025-08 | B16: 64970.17 | C16: 148628.36 | D16: 213598.53 | E16: 15025.371 | F16: 121429.41 | G16: 136454.78 | H16: =D16+G16 -> 350053.31 | I16: =B16+E16 -> 79995.541 | J16: =C16+F16 -> 270057.77 | K16: =IF(H16=0,NA(),J16/H16) -> 0.77147612
... A96: 2018-12 | B96: 74875.096 | C96: 202995.69 | D96: 277870.79 | E96: 12467.458 | F96: 165653.27 | G96: 178120.73 | H96: =D96+G96 -> 455991.51 | I96: =B96+E96 -> 87342.554 | J96: =C96+F96 -> 368648.96 | K96: =IF(H96=0,NA(),J96/H96) -> 0.80845575

Sheet A HKMA 3.5.1
A1: Appendix — HKMA Monthly Statistical Bulletin Table 3.5.1
A2: Loans and advances for use in Hong Kong by economic sector (authorized institutions). This table excludes trade-financing loans. Unit: HK$ million. Quarterly.
A3: Property lending* in the report = property development & investment + purchase of other residential property (excludes HOS / PSPS / TPS flats).
A5: Period | B5: Manufacturing | C5: Property development & investment | D5: Purchase of other residential | E5: Wholesale & retail | F5: Financial concerns | G5: Other private purposes | H5: Transport | I5: Information technology | J5: Electricity & gas | K5: Use in HK (ex-TF) | L5: Property lending*
A6: 2026-06 | B6: 363633.97 | C6: 1313893.8 | D6: 1958342.7 | E6: 312060.83 | F6: 1032728.3 | G6: 794177.67 | H6: 331240.65 | I6: 228617.92 | J6: 215920.42 | K6: 7659001.8 | L6: =C6+D6 -> 3272236.5
A7: 2026-03 | B7: 328188.24 | C7: 1339249.2 | D7: 1937565.9 | E7: 284551.08 | F7: 984139.37 | G7: 748476.8 | H7: 302874.14 | I7: 215874.99 | J7: 205053.45 | K7: 7440320.7 | L7: =C7+D7 -> 3276815.1
A8: 2025-12 | B8: 306596.64 | C8: 1372331.1 | D8: 1920476.5 | E8: 278886.35 | F8: 940367.2 | G8: 685669.35 | H8: 285580.51 | I8: 203059.65 | J8: 194690 | K8: 7244524.9 | L8: =C8+D8 -> 3292807.6
A9: 2025-09 | B9: 322774.75 | C9: 1388211 | D9: 1894347 | E9: 282430.92 | F9: 938125.02 | G9: 682089.89 | H9: 282034.28 | I9: 197962.55 | J9: 213416.25 | K9: 7243500.5 | L9: =C9+D9 -> 3282558
A10: 2025-06 | B10: 324870.77 | C10: 1445796.3 | D10: 1889329.5 | E10: 293650.49 | F10: 910454.89 | G10: 664951.66 | H10: 283977.7 | I10: 202849.75 | J10: 215013.89 | K10: 7273877.6 | L10: =C10+D10 -> 3335125.8
A11: 2025-03 | B11: 310084.31 | C11: 1446113.9 | D11: 1880587.6 | E11: 286619.04 | F11: 877063.12 | G11: 645367.03 | H11: 297595.2 | I11: 201060.38 | J11: 184154.22 | K11: 7164140.5 | L11: =C11+D11 -> 3326701.6
A12: 2024-12 | B12: 295132.54 | C12: 1488357.5 | D12: 1873532.5 | E12: 292621.66 | F12: 840262.48 | G12: 629430.8 | H12: 293659.3 | I12: 183124.3 | J12: 190847.02 | K12: 7108739.3 | L12: =C12+D12 -> 3361890

Sheet Summary
F3: Table 3.5.1 : Authorized institutions (HK$ million, unless otherwise specified) | H3: 1.2 | J3: 2026-07 | K3: 2026-07 | L3: 2026-07 | M3: =TEXT(EOMONTH(DATE(LEFT(L3,4),RIGHT(L3,2),1),-1),"yyyy-mm") -> 2026-06 | N3: =M3 -> 2026-06 | O3: =N3 -> 2026-06 | P3: =TEXT(EOMONTH(DATE(LEFT(O3,4),RIGHT(O3,2),1),-1),"yyyy-mm") -> 2026-05 | Q3: =P3 -> 2026-05 | R3: =Q3 -> 2026-05 | S3: =TEXT(EOMONTH(DATE(LEFT(R3,4),RIGHT(R3,2),1),-1),"yyyy-mm") -> 2026-04 | T3: =S3 -> 2026-04 | U3: =T3 -> 2026-04 | V3: =TEXT(EOMONTH(DATE(LEFT(U3,4),RIGHT(U3,2),1),-1),"yyyy-mm") -> 2026-03 | W3: =V3 -> 2026-03 | X3: =W3 -> 2026-03 | Y3: =TEXT(EOMONTH(DATE(LEFT(X3,4),RIGHT(X3,2),1),-1),"yyyy-mm") -> 2026-02 | Z3: =Y3 -> 2026-02 | AA3: =Z3 -> 2026-02 | AB3: =TEXT(EOMONTH(DATE(LEFT(AA3,4),RIGHT(AA3,2),1),-1),"yyyy-mm") -> 2026-01 | AC3: =AB3 -> 2026-01 | AD3: =AC3 -> 2026-01 | AE3: =TEXT(EOMONTH(DATE(LEFT(AD3,4),RIGHT(AD3,2),1),-1),"yyyy-mm") -> 2025-12 | AF3: =AE3 -> 2025-12 | AG3: =AF3 -> 2025-12 | AH3: =TEXT(EOMONTH(DATE(LEFT(AG3,4),RIGHT(AG3,2),1),-1),"yyyy-mm") -> 2025-11 | AI3: =AH3 -> 2025-11 | AJ3: =AI3 -> 2025-11 | AK3: =TEXT(EOMONTH(DATE(LEFT(AJ3,4),RIGHT(AJ3,2),1),-1),"yyyy-mm") -> 2025-10 | AL3: =AK3 -> 2025-10 | AM3: =AL3 -> 2025-10 | AN3: =TEXT(EOMONTH(DATE(LEFT(AM3,4),RIGHT(AM3,2),1),-1),"yyyy-mm") -> 2025-09 | AO3: =AN3 -> 2025-09 | AP3: =AO3 -> 2025-09 | AQ3: =TEXT(EOMONTH(DATE(LEFT(AP3,4),RIGHT(AP3,2),1),-1),"yyyy-mm") -> 2025-08 | AR3: =AQ3 -> 2025-08 | AS3: =AR3 -> 2025-08 | AT3: =TEXT(EOMONTH(DATE(LEFT(AS3,4),RIGHT(AS3,2),1),-1),"yyyy-mm") -> 2025-07 | AU3: =AT3 -> 2025-07 | AV3: =AU3 -> 2025-07 | AW3: =TEXT(EOMONTH(DATE(LEFT(AV3,4),RIGHT(AV3,2),1),-1),"yyyy-mm") -> 2025-06 | AX3: =AW3 -> 2025-06 | AY3: =AX3 -> 2025-06 | AZ3: 2024-00 | BA3: =AZ3 -> 2024-00 | BB3: =BA3 -> 2024-00 | BC3: 2023-00 | BD3: =BC3 -> 2023-00 | BE3: =BD3 -> 2023-00 | BF3: 2022-00 | BG3: =BF3 -> 2022-00 | BH3: =BG3 -> 2022-00 | BI3: 2021-00 | BJ3: =BI3 -> 2021-00 | BK3: =BJ3 -> 2021-00
F4: 認可機構 (百萬港元, 另有說明者除外) | H4: 3.4.1 | J4: =J3 -> 2026-07 | K4: =K3 -> 2026-07 | L4: =L3 -> 2026-07 | M4: =M3 -> 2026-06 | N4: =N3 -> 2026-06 | O4: =O3 -> 2026-06 | P4: =P3 -> 2026-05 | Q4: =Q3 -> 2026-05 | ... AY4: =AY3 -> 2025-06 | AZ4: 2024-12 | BA4: 2024-12 | BB4: 2024-12 | BC4: 2023-12 | BD4: 2023-12 | BE4: 2023-12 | BF4: 2022-12 | BG4: 2022-12 | BH4: 2022-12 | BI4: 2021-12 | BJ4: 2021-12 | BK4: 2021-12
F9: Table : Loans and advances
F10: 貸款及墊款 | L10: =TEXT(DATE(LEFT(L3,4),RIGHT(L3,2),1),"[$-en-US]mmmm yyyy") -> July 2026 | O10: =TEXT(DATE(LEFT(O3,4),RIGHT(O3,2),1),"[$-en-US]mmmm yyyy") -> June 2026 | R10: =TEXT(DATE(LEFT(R3,4),RIGHT(R3,2),1),"[$-en-US]mmmm yyyy") -> May 2026 | U10: =TEXT(DATE(LEFT(U3,4),RIGHT(U3,2),1),"[$-en-US]mmmm yyyy") -> April 2026 | X10: =TEXT(DATE(LEFT(X3,4),RIGHT(X3,2),1),"[$-en-US]mmmm yyyy") -> March 2026 | AA10: =TEXT(DATE(LEFT(AA3,4),RIGHT(AA3,2),1),"[$-en-US]mmmm yyyy") -> February 2026 | AD10: =TEXT(DATE(LEFT(AD3,4),RIGHT(AD3,2),1),"[$-en-US]mmmm yyyy") -> January 2026 | AG10: =TEXT(DATE(LEFT(AG3,4),RIGHT(AG3,2),1),"[$-en-US]mmmm yyyy") -> December 2025 | AJ10: =TEXT(DATE(LEFT(AJ3,4),RIGHT(AJ3,2),1),"[$-en-US]mmmm yyyy") -> November 2025 | AM10: =TEXT(DATE(LEFT(AM3,4),RIGHT(AM3,2),1),"[$-en-US]mmmm yyyy") -> October 2025 | AP10: =TEXT(DATE(LEFT(AP3,4),RIGHT(AP3,2),1),"[$-en-US]mmmm yyyy") -> September 2025 | AS10: =TEXT(DATE(LEFT(AS3,4),RIGHT(AS3,2),1),"[$-en-US]mmmm yyyy") -> August 2025 | AV10: =TEXT(DATE(LEFT(AV3,4),RIGHT(AV3,2),1),"[$-en-US]mmmm yyyy") -> July 2025 | AY10: =TEXT(DATE(LEFT(AY3,4),RIGHT(AY3,2),1),"[$-en-US]mmmm yyyy") -> June 2025 | BB10: December 2024 | BE10: December 2023 | BH10: December 2022 | BK10: December 2021
F11: Table 3.5.1 : Authorized institutions (HK$ million, unless otherwise specified) | H11: Proportion% | I11: YoY% | J11: HK$ | K11: Foreign currency | L11: Total | M11: HK$ | N11: Foreign currency | O11: Total | P11: HK$ | Q11: Foreign currency | R11: Total | S11: HK$ | T11: Foreign currency | U11: Total | V11: HK$ | W11: Foreign currency | X11: Total | Y11: HK$ | Z11: Foreign currency | AA11: Total | AB11: HK$ | AC11: Foreign currency | AD11: Total | AE11: HK$ | AF11: Foreign currency | AG11: Total | AH11: HK$ | AI11: Foreign currency | AJ11: Total | AK11: HK$ | AL11: Foreign currency | AM11: Total | AN11: HK$ | AO11: Foreign currency | AP11: Total | AQ11: HK$ | AR11: Foreign currency | AS11: Total | AT11: HK$ | AU11: Foreign currency | AV11: Total | AW11: HK$ | AX11: Foreign currency | AY11: Total | AZ11: HK$ | BA11: Foreign currency | BB11: Total | BC11: HK$ | BD11: Foreign currency | BE11: Total | BF11: HK$ | BG11: Foreign currency | BH11: Total | BI11: HK$ | BJ11: Foreign currency | BK11: Total
C12: loans_total | E12: Total loan and advances | H12: =O12/$O$12 -> 1 | I12: =IFERROR(L12/AV12-1,"") -> 0.076511392 | L12: =INDEX('[3]1.2'!$1:$104,MATCH(L$3,'[3]1.2'!$A:$A,0),MATCH(Summary!$C12,'[3]1.2'!$1:$1,0)) -> 10809854 | O12: =INDEX('[3]1.2'!$1:$104,MATCH(M$3,'[3]1.2'!$A:$A,0),MATCH(Summary!$C12,'[3]1.2'!$1:$1,0)) -> 10787896 | R12: =INDEX('[3]1.2'!$1:$104,MATCH(P$3,'[3]1.2'!$A:$A,0),MATCH(Summary!$C12,'[3]1.2'!$1:$1,0)) -> 10646152 | U12: =INDEX('[3]1.2'!$1:$104,MATCH(S$3,'[3]1.2'!$A:$A,0),MATCH(Summary!$C12,'[3]1.2'!$1:$1,0)) -> 10496858 | X12: =INDEX('[3]1.2'!$1:$104,MATCH(V$3,'[3]1.2'!$A:$A,0),MATCH(Summary!$C12,'[3]1.2'!$1:$1,0)) -> 10440278 | AA12: =INDEX('[3]1.2'!$1:$104,MATCH(Y$3,'[3]1.2'!$A:$A,0),MATCH(Summary!$C12,'[3]1.2'!$1:$1,0)) -> 10302290 | AD12: =INDEX('[3]1.2'!$1:$104,MATCH(AB$3,'[3]1.2'!$A:$A,0),MATCH(Summary!$C12,'[3]1.2'!$1:$1,0)) -> 10245411 | AG12: =INDEX('[3]1.2'!$1:$104,MATCH(AE$3,'[3]1.2'!$A:$A,0),MATCH(Summary!$C12,'[3]1.2'!$1:$1,0)) -> 10136142 | AJ12: =INDEX('[3]1.2'!$1:$104,MATCH(AH$3,'[3]1.2'!$A:$A,0),MATCH(Summary!$C12,'[3]1.2'!$1:$1,0)) -> 10002556 | AM12: =INDEX('[3]1.2'!$1:$104,MATCH(AK$3,'[3]1.2'!$A:$A,0),MATCH(Summary!$C12,'[3]1.2'!$1:$1,0)) -> 9997067.5 | AP12: =INDEX('[3]1.2'!$1:$104,MATCH(AN$3,'[3]1.2'!$A:$A,0),MATCH(Summary!$C12,'[3]1.2'!$1:$1,0)) -> 10068576 | AS12: =INDEX('[3]1.2'!$1:$104,MATCH(AQ$3,'[3]1.2'!$A:$A,0),MATCH(Summary!$C12,'[3]1.2'!$1:$1,0)) -> 10003516 | AV12: =INDEX('[3]1.2'!$1:$104,MATCH(AT$3,'[3]1.2'!$A:$A,0),MATCH(Summary!$C12,'[3]1.2'!$1:$1,0)) -> 10041560 | AY12: =INDEX('[3]1.2'!$1:$104,MATCH(AW$3,'[3]1.2'!$A:$A,0),MATCH(Summary!$C12,'[3]1.2'!$1:$1,0)) -> 10158381 | BB12: =INDEX('[3]1.2'!$1:$104,MATCH(AZ$3,'[3]1.2'!$A:$A,0),MATCH(Summary!$C12,'[3]1.2'!$1:$1,0)) -> 9907808 | BE12: =INDEX('[3]1.2'!$1:$104,MATCH(BC$3,'[3]1.2'!$A:$A,0),MATCH(Summary!$C12,'[3]1.2'!$1:$1,0)) -> 10191315 | BH12: =INDEX('[3]1.2'!$1:$104,MATCH(BF$3,'[3]1.2'!$A:$A,0),MATCH(Summary!$C12,'[3]1.2'!$1:$1,0)) -> 10571298 | BK12: =INDEX('[3]1.2'!$1:$104,MATCH(BI$3,'[3]1.2'!$A:$A,0),MATCH(Summary!$C12,'[3]1.2'!$1:$1,0)) -> 10893147
C13: loans_in_hk | E13: Loans for use in HK | H13: =O13/$O$12 -> 0.75040076 | I13: =IFERROR(L13/AV13-1,"") -> 0.065162006 | L13: =INDEX('[3]1.2'!$1:$104,MATCH(L$3,'[3]1.2'!$A:$A,0),MATCH(Summary!$C13,'[3]1.2'!$1:$1,0)) -> 8070867 | O13: =INDEX('[3]1.2'!$1:$104,MATCH(M$3,'[3]1.2'!$A:$A,0),MATCH(Summary!$C13,'[3]1.2'!$1:$1,0)) -> 8095245.2 | R13: =INDEX('[3]1.2'!$1:$104,MATCH(P$3,'[3]1.2'!$A:$A,0),MATCH(Summary!$C13,'[3]1.2'!$1:$1,0)) -> 7981206.3 | U13: =INDEX('[3]1.2'!$1:$104,MATCH(S$3,'[3]1.2'!$A:$A,0),MATCH(Summary!$C13,'[3]1.2'!$1:$1,0)) -> 7869195.5 | X13: =INDEX('[3]1.2'!$1:$104,MATCH(V$3,'[3]1.2'!$A:$A,0),MATCH(Summary!$C13,'[3]1.2'!$1:$1,0)) -> 7861821.8 | AA13: =INDEX('[3]1.2'!$1:$104,MATCH(Y$3,'[3]1.2'!$A:$A,0),MATCH(Summary!$C13,'[3]1.2'!$1:$1,0)) -> 7721916.9 | AD13: =INDEX('[3]1.2'!$1:$104,MATCH(AB$3,'[3]1.2'!$A:$A,0),MATCH(Summary!$C13,'[3]1.2'!$1:$1,0)) -> 7688694.2 | AG13: =INDEX('[3]1.2'!$1:$104,MATCH(AE$3,'[3]1.2'!$A:$A,0),MATCH(Summary!$C13,'[3]1.2'!$1:$1,0)) -> 7635305.1 | AJ13: =INDEX('[3]1.2'!$1:$104,MATCH(AH$3,'[3]1.2'!$A:$A,0),MATCH(Summary!$C13,'[3]1.2'!$1:$1,0)) -> 7546764.4 | AM13: =INDEX('[3]1.2'!$1:$104,MATCH(AK$3,'[3]1.2'!$A:$A,0),MATCH(Summary!$C13,'[3]1.2'!$1:$1,0)) -> 7551750.3 | AP13: =INDEX('[3]1.2'!$1:$104,MATCH(AN$3,'[3]1.2'!$A:$A,0),MATCH(Summary!$C13,'[3]1.2'!$1:$1,0)) -> 7617255.6 | AS13: =INDEX('[3]1.2'!$1:$104,MATCH(AQ$3,'[3]1.2'!$A:$A,0),MATCH(Summary!$C13,'[3]1.2'!$1:$1,0)) -> 7570020.6 | AV13: =INDEX('[3]1.2'!$1:$104,MATCH(AT$3,'[3]1.2'!$A:$A,0),MATCH(Summary!$C13,'[3]1.2'!$1:$1,0)) -> 7577126.3 | AY13: =INDEX('[3]1.2'!$1:$104,MATCH(AW$3,'[3]1.2'!$A:$A,0),MATCH(Summary!$C13,'[3]1.2'!$1:$1,0)) -> 7650101.4 | BB13: =INDEX('[3]1.2'!$1:$104,MATCH(AZ$3,'[3]1.2'!$A:$A,0),MATCH(Summary!$C13,'[3]1.2'!$1:$1,0)) -> 7489982.2 | BE13: =INDEX('[3]1.2'!$1:$104,MATCH(BC$3,'[3]1.2'!$A:$A,0),MATCH(Summary!$C13,'[3]1.2'!$1:$1,0)) -> 7627950.9 | BH13: =INDEX('[3]1.2'!$1:$104,MATCH(BF$3,'[3]1.2'!$A:$A,0),MATCH(Summary!$C13,'[3]1.2'!$1:$1,0)) -> 7710340.6 | BK13: =INDEX('[3]1.2'!$1:$104,MATCH(BI$3,'[3]1.2'!$A:$A,0),MATCH(Summary!$C13,'[3]1.2'!$1:$1,0)) -> 7712295.5
E14: Trade finance | G14: 貿易融資 | H14: =O14/$O$12 -> 0.040423935 | I14: =IFERROR(L14/AV14-1,"") -> 0.17121328 | J14: =J15+J16 -> 69564.467 | K14: =K15+K16 -> 352264.12 | L14: =L15+L16 -> 421828.59 | M14: =M15+M16 -> 69891.593 | N14: =N15+N16 -> 366197.6 | O14: =O15+O16 -> 436089.19 | P14: =P15+P16 -> 69479.415 | Q14: =Q15+Q16 -> 345283.6 | ... BK14: =BK15+BK16 -> 485030.24
A15: imp_exp_reexp_fromhk_hkd | B15: imp_exp_reexp_fromhk_fc | C15: imp_exp_reexp_fromhk_total | E15: To finance H.K.'s visible trade | G15: 香港貨物的出入口及轉口融資 | H15: =O15/$O$12 -> 0.024362226 | I15: =IFERROR(L15/AV15-1,"") -> 0.12876795 | J15: =INDEX('[3]3.4.1'!$1:$104,MATCH(J$4,'[3]3.4.1'!$A:$A,0),MATCH(Summary!$A15,'[3]3.4.1'!$1:$1,0)) -> 56511.102 | K15: =INDEX('[3]3.4.1'!$1:$104,MATCH(K$4,'[3]3.4.1'!$A:$A,0),MATCH(Summary!$B15,'[3]3.4.1'!$1:$1,0)) -> 193800.71 | L15: =INDEX('[3]3.4.1'!$1:$104,MATCH(L$4,'[3]3.4.1'!$A:$A,0),MATCH(Summary!$C15,'[3]3.4.1'!$1:$1,0)) -> 250311.81 | M15: =INDEX('[3]3.4.1'!$1:$104,MATCH(M$4,'[3]3.4.1'!$A:$A,0),MATCH(Summary!$A15,'[3]3.4.1'!$1:$1,0)) -> 57111.395 | N15: =INDEX('[3]3.4.1'!$1:$104,MATCH(N$4,'[3]3.4.1'!$A:$A,0),MATCH(Summary!$B15,'[3]3.4.1'!$1:$1,0)) -> 205705.76 | O15: =INDEX('[3]3.4.1'!$1:$104,MATCH(O$4,'[3]3.4.1'!$A:$A,0),MATCH(Summary!$C15,'[3]3.4.1'!$1:$1,0)) -> 262817.16 | P15: =INDEX('[3]3.4.1'!$1:$104,MATCH(P$4,'[3]3.4.1'!$A:$A,0),MATCH(Summary!$A15,'[3]3.4.1'!$1:$1,0)) -> 57013.091 | Q15: =INDEX('[3]3.4.1'!$1:$104,MATCH(Q$4,'[3]3.4.1'!$A:$A,0),MATCH(Summary!$B15,'[3]3.4.1'!$1:$1,0)) -> 186630.31 | R15: =INDEX('[3]3.4.1'!$1:$104,MATCH(R$4,'[3]3.4.1'!$A:$A,0),MATCH(Summary!$C15,'[3]3.4.1'!$1:$1,0)) -> 243643.4 | S15: =INDEX('[3]3.4.1'!$1:$104,MATCH(S$4,'[3]3.4.1'!$A:$A,0),MATCH(Summary!$A15,'[3]3.4.1'!$1:$1,0)) -> 59126.986 | T15: =INDEX('[3]3.4.1'!$1:$104,MATCH(T$4,'[3]3.4.1'!$A:$A,0),MATCH(Summary!$B15,'[3]3.4.1'!$1:$1,0)) -> 173799.62 | U15: =INDEX('[3]3.4.1'!$1:$104,MATCH(U$4,'[3]3.4.1'!$A:$A,0),MATCH(Summary!$C15,'[3]3.4.1'!$1:$1,0)) -> 232926.61 | V15: =INDEX('[3]3.4.1'!$1:$104,MATCH(V$4,'[3]3.4.1'!$A:$A,0),MATCH(Summary!$A15,'[3]3.4.1'!$1:$1,0)) -> 59339.624 | W15: =INDEX('[3]3.4.1'!$1:$104,MATCH(W$4,'[3]3.4.1'!$A:$A,0),MATCH(Summary!$B15,'[3]3.4.1'!$1:$1,0)) -> 182422.15 | X15: =INDEX('[3]3.4.1'!$1:$104,MATCH(X$4,'[3]3.4.1'!$A:$A,0),MATCH(Summary!$C15,'[3]3.4.1'!$1:$1,0)) -> 241761.77 | Y15: =INDEX('[3]3.4.1'!$1:$104,MATCH(Y$4,'[3]3.4.1'!$A:$A,0),MATCH(Summary!$A15,'[3]3.4.1'!$1:$1,0)) -> 58040.729 | Z15: =INDEX('[3]3.4.1'!$1:$104,MATCH(Z$4,'[3]3.4.1'!$A:$A,0),MATCH(Summary!$B15,'[3]3.4.1'!$1:$1,0)) -> 172201.21 | AA15: =INDEX('[3]3.4.1'!$1:$104,MATCH(AA$4,'[3]3.4.1'!$A:$A,0),MATCH(Summary!$C15,'[3]3.4.1'!$1:$1,0)) -> 230241.94 | AB15: =INDEX('[3]3.4.1'!$1:$104,MATCH(AB$4,'[3]3.4.1'!$A:$A,0),MATCH(Summary!$A15,'[3]3.4.1'!$1:$1,0)) -> 58057.961 | AC15: =INDEX('[3]3.4.1'!$1:$104,MATCH(AC$4,'[3]3.4.1'!$A:$A,0),MATCH(Summary!$B15,'[3]3.4.1'!$1:$1,0)) -> 166061.31 | AD15: =INDEX('[3]3.4.1'!$1:$104,MATCH(AD$4,'[3]3.4.1'!$A:$A,0),MATCH(Summary!$C15,'[3]3.4.1'!$1:$1,0)) -> 224119.27 | AE15: =INDEX('[3]3.4.1'!$1:$104,MATCH(AE$4,'[3]3.4.1'!$A:$A,0),MATCH(Summary!$A15,'[3]3.4.1'!$1:$1,0)) -> 55987.338 | AF15: =INDEX('[3]3.4.1'!$1:$104,MATCH(AF$4,'[3]3.4.1'!$A:$A,0),MATCH(Summary!$B15,'[3]3.4.1'!$1:$1,0)) -> 186177.14 | AG15: =INDEX('[3]3.4.1'!$1:$104,MATCH(AG$4,'[3]3.4.1'!$A:$A,0),MATCH(Summary!$C15,'[3]3.4.1'!$1:$1,0)) -> 242164.48 | AH15: =INDEX('[3]3.4.1'!$1:$104,MATCH(AH$4,'[3]3.4.1'!$A:$A,0),MATCH(Summary!$A15,'[3]3.4.1'!$1:$1,0)) -> 58570.371 | AI15: =INDEX('[3]3.4.1'!$1:$104,MATCH(AI$4,'[3]3.4.1'!$A:$A,0),MATCH(Summary!$B15,'[3]3.4.1'!$1:$1,0)) -> 154966.04 | AJ15: =INDEX('[3]3.4.1'!$1:$104,MATCH(AJ$4,'[3]3.4.1'!$A:$A,0),MATCH(Summary!$C15,'[3]3.4.1'!$1:$1,0)) -> 213536.41 | AK15: =INDEX('[3]3.4.1'!$1:$104,MATCH(AK$4,'[3]3.4.1'!$A:$A,0),MATCH(Summary!$A15,'[3]3.4.1'!$1:$1,0)) -> 57795.635 | AL15: =INDEX('[3]3.4.1'!$1:$104,MATCH(AL$4,'[3]3.4.1'!$A:$A,0),MATCH(Summary!$B15,'[3]3.4.1'!$1:$1,0)) -> 153915.67 | AM15: =INDEX('[3]3.4.1'!$1:$104,MATCH(AM$4,'[3]3.4.1'!$A:$A,0),MATCH(Summary!$C15,'[3]3.4.1'!$1:$1,0)) -> 211711.3 | AN15: =INDEX('[3]3.4.1'!$1:$104,MATCH(AN$4,'[3]3.4.1'!$A:$A,0),MATCH(Summary!$A15,'[3]3.4.1'!$1:$1,0)) -> 61251.15 | AO15: =INDEX('[3]3.4.1'!$1:$104,MATCH(AO$4,'[3]3.4.1'!$A:$A,0),MATCH(Summary!$B15,'[3]3.4.1'!$1:$1,0)) -> 166019.3 | AP15: =INDEX('[3]3.4.1'!$1:$104,MATCH(AP$4,'[3]3.4.1'!$A:$A,0),MATCH(Summary!$C15,'[3]3.4.1'!$1:$1,0)) -> 227270.45 | AQ15: =INDEX('[3]3.4.1'!$1:$104,MATCH(AQ$4,'[3]3.4.1'!$A:$A,0),MATCH(Summary!$A15,'[3]3.4.1'!$1:$1,0)) -> 64970.17 | AR15: =INDEX('[3]3.4.1'!$1:$104,MATCH(AR$4,'[3]3.4.1'!$A:$A,0),MATCH(Summary!$B15,'[3]3.4.1'!$1:$1,0)) -> 148628.36 | AS15: =INDEX('[3]3.4.1'!$1:$104,MATCH(AS$4,'[3]3.4.1'!$A:$A,0),MATCH(Summary!$C15,'[3]3.4.1'!$1:$1,0)) -> 213598.53 | AT15: =INDEX('[3]3.4.1'!$1:$104,MATCH(AT$4,'[3]3.4.1'!$A:$A,0),MATCH(Summary!$A15,'[3]3.4.1'!$1:$1,0)) -> 65997.963 | AU15: =INDEX('[3]3.4.1'!$1:$104,MATCH(AU$4,'[3]3.4.1'!$A:$A,0),MATCH(Summary!$B15,'[3]3.4.1'!$1:$1,0)) -> 155758.7 | AV15: =INDEX('[3]3.4.1'!$1:$104,MATCH(AV$4,'[3]3.4.1'!$A:$A,0),MATCH(Summary!$C15,'[3]3.4.1'!$1:$1,0)) -> 221756.66 | AW15: =INDEX('[3]3.4.1'!$1:$104,MATCH(AW$4,'[3]3.4.1'!$A:$A,0),MATCH(Summary!$A15,'[3]3.4.1'!$1:$1,0)) -> 64711.344 | AX15: =INDEX('[3]3.4.1'!$1:$104,MATCH(AX$4,'[3]3.4.1'!$A:$A,0),MATCH(Summary!$B15,'[3]3.4.1'!$1:$1,0)) -> 159163.17 | AY15: =INDEX('[3]3.4.1'!$1:$104,MATCH(AY$4,'[3]3.4.1'!$A:$A,0),MATCH(Summary!$C15,'[3]3.4.1'!$1:$1,0)) -> 223874.52 | AZ15: =INDEX('[3]3.4.1'!$1:$104,MATCH(AZ$4,'[3]3.4.1'!$A:$A,0),MATCH(Summary!$A15,'[3]3.4.1'!$1:$1,0)) -> 60444.762 | BA15: =INDEX('[3]3.4.1'!$1:$104,MATCH(BA$4,'[3]3.4.1'!$A:$A,0),MATCH(Summary!$B15,'[3]3.4.1'!$1:$1,0)) -> 171303.02 | BB15: =INDEX('[3]3.4.1'!$1:$104,MATCH(BB$4,'[3]3.4.1'!$A:$A,0),MATCH(Summary!$C15,'[3]3.4.1'!$1:$1,0)) -> 231747.78 | BC15: =INDEX('[3]3.4.1'!$1:$104,MATCH(BC$4,'[3]3.4.1'!$A:$A,0),MATCH(Summary!$A15,'[3]3.4.1'!$1:$1,0)) -> 55411.698 | BD15: =INDEX('[3]3.4.1'!$1:$104,MATCH(BD$4,'[3]3.4.1'!$A:$A,0),MATCH(Summary!$B15,'[3]3.4.1'!$1:$1,0)) -> 149701.38 | BE15: =INDEX('[3]3.4.1'!$1:$104,MATCH(BE$4,'[3]3.4.1'!$A:$A,0),MATCH(Summary!$C15,'[3]3.4.1'!$1:$1,0)) -> 205113.08 | BF15: =INDEX('[3]3.4.1'!$1:$104,MATCH(BF$4,'[3]3.4.1'!$A:$A,0),MATCH(Summary!$A15,'[3]3.4.1'!$1:$1,0)) -> 58068.637 | BG15: =INDEX('[3]3.4.1'!$1:$104,MATCH(BG$4,'[3]3.4.1'!$A:$A,0),MATCH(Summary!$B15,'[3]3.4.1'!$1:$1,0)) -> 189414.86 | BH15: =INDEX('[3]3.4.1'!$1:$104,MATCH(BH$4,'[3]3.4.1'!$A:$A,0),MATCH(Summary!$C15,'[3]3.4.1'!$1:$1,0)) -> 247483.5 | BI15: =INDEX('[3]3.4.1'!$1:$104,MATCH(BI$4,'[3]3.4.1'!$A:$A,0),MATCH(Summary!$A15,'[3]3.4.1'!$1:$1,0)) -> 55055.337 | BJ15: =INDEX('[3]3.4.1'!$1:$104,MATCH(BJ$4,'[3]3.4.1'!$A:$A,0),MATCH(Summary!$B15,'[3]3.4.1'!$1:$1,0)) -> 236330.96 | BK15: =INDEX('[3]3.4.1'!$1:$104,MATCH(BK$4,'[3]3.4.1'!$A:$A,0),MATCH(Summary!$C15,'[3]3.4.1'!$1:$1,0)) -> 291386.29
A16: merch_trade_nonhk_hkd | B16: merch_trade_nonhk_fc | C16: merch_trade_nonhk_total | E16: To finance merchandising trade not touching H.K. | G16: 香港境外的商品貿易融資 | H16: =O16/$O$12 -> 0.016061708 | I16: =IFERROR(L16/AV16-1,"") -> 0.23921942 | J16: =INDEX('[3]3.4.1'!$1:$104,MATCH(J$4,'[3]3.4.1'!$A:$A,0),MATCH(Summary!$A16,'[3]3.4.1'!$1:$1,0)) -> 13053.365 | K16: =INDEX('[3]3.4.1'!$1:$104,MATCH(K$4,'[3]3.4.1'!$A:$A,0),MATCH(Summary!$B16,'[3]3.4.1'!$1:$1,0)) -> 158463.42 | L16: =INDEX('[3]3.4.1'!$1:$104,MATCH(L$4,'[3]3.4.1'!$A:$A,0),MATCH(Summary!$C16,'[3]3.4.1'!$1:$1,0)) -> 171516.78 | M16: =INDEX('[3]3.4.1'!$1:$104,MATCH(M$4,'[3]3.4.1'!$A:$A,0),MATCH(Summary!$A16,'[3]3.4.1'!$1:$1,0)) -> 12780.198 | N16: =INDEX('[3]3.4.1'!$1:$104,MATCH(N$4,'[3]3.4.1'!$A:$A,0),MATCH(Summary!$B16,'[3]3.4.1'!$1:$1,0)) -> 160491.84 | O16: =INDEX('[3]3.4.1'!$1:$104,MATCH(O$4,'[3]3.4.1'!$A:$A,0),MATCH(Summary!$C16,'[3]3.4.1'!$1:$1,0)) -> 173272.03 | P16: =INDEX('[3]3.4.1'!$1:$104,MATCH(P$4,'[3]3.4.1'!$A:$A,0),MATCH(Summary!$A16,'[3]3.4.1'!$1:$1,0)) -> 12466.324 | Q16: =INDEX('[3]3.4.1'!$1:$104,MATCH(Q$4,'[3]3.4.1'!$A:$A,0),MATCH(Summary!$B16,'[3]3.4.1'!$1:$1,0)) -> 158653.3 | R16: =INDEX('[3]3.4.1'!$1:$104,MATCH(R$4,'[3]3.4.1'!$A:$A,0),MATCH(Summary!$C16,'[3]3.4.1'!$1:$1,0)) -> 171119.62 | S16: =INDEX('[3]3.4.1'!$1:$104,MATCH(S$4,'[3]3.4.1'!$A:$A,0),MATCH(Summary!$A16,'[3]3.4.1'!$1:$1,0)) -> 11984.01 | T16: =INDEX('[3]3.4.1'!$1:$104,MATCH(T$4,'[3]3.4.1'!$A:$A,0),MATCH(Summary!$B16,'[3]3.4.1'!$1:$1,0)) -> 160556.36 | U16: =INDEX('[3]3.4.1'!$1:$104,MATCH(U$4,'[3]3.4.1'!$A:$A,0),MATCH(Summary!$C16,'[3]3.4.1'!$1:$1,0)) -> 172540.37 | V16: =INDEX('[3]3.4.1'!$1:$104,MATCH(V$4,'[3]3.4.1'!$A:$A,0),MATCH(Summary!$A16,'[3]3.4.1'!$1:$1,0)) -> 11972.022 | W16: =INDEX('[3]3.4.1'!$1:$104,MATCH(W$4,'[3]3.4.1'!$A:$A,0),MATCH(Summary!$B16,'[3]3.4.1'!$1:$1,0)) -> 167767.32 | X16: =INDEX('[3]3.4.1'!$1:$104,MATCH(X$4,'[3]3.4.1'!$A:$A,0),MATCH(Summary!$C16,'[3]3.4.1'!$1:$1,0)) -> 179739.34 | Y16: =INDEX('[3]3.4.1'!$1:$104,MATCH(Y$4,'[3]3.4.1'!$A:$A,0),MATCH(Summary!$A16,'[3]3.4.1'!$1:$1,0)) -> 13041.727 | Z16: =INDEX('[3]3.4.1'!$1:$104,MATCH(Z$4,'[3]3.4.1'!$A:$A,0),MATCH(Summary!$B16,'[3]3.4.1'!$1:$1,0)) -> 126050.45 | AA16: =INDEX('[3]3.4.1'!$1:$104,MATCH(AA$4,'[3]3.4.1'!$A:$A,0),MATCH(Summary!$C16,'[3]3.4.1'!$1:$1,0)) -> 139092.18 | AB16: =INDEX('[3]3.4.1'!$1:$104,MATCH(AB$4,'[3]3.4.1'!$A:$A,0),MATCH(Summary!$A16,'[3]3.4.1'!$1:$1,0)) -> 13924.763 | AC16: =INDEX('[3]3.4.1'!$1:$104,MATCH(AC$4,'[3]3.4.1'!$A:$A,0),MATCH(Summary!$B16,'[3]3.4.1'!$1:$1,0)) -> 121553.74 | AD16: =INDEX('[3]3.4.1'!$1:$104,MATCH(AD$4,'[3]3.4.1'!$A:$A,0),MATCH(Summary!$C16,'[3]3.4.1'!$1:$1,0)) -> 135478.5 | AE16: =INDEX('[3]3.4.1'!$1:$104,MATCH(AE$4,'[3]3.4.1'!$A:$A,0),MATCH(Summary!$A16,'[3]3.4.1'!$1:$1,0)) -> 14415.68 | AF16: =INDEX('[3]3.4.1'!$1:$104,MATCH(AF$4,'[3]3.4.1'!$A:$A,0),MATCH(Summary!$B16,'[3]3.4.1'!$1:$1,0)) -> 134200.05 | AG16: =INDEX('[3]3.4.1'!$1:$104,MATCH(AG$4,'[3]3.4.1'!$A:$A,0),MATCH(Summary!$C16,'[3]3.4.1'!$1:$1,0)) -> 148615.73 | AH16: =INDEX('[3]3.4.1'!$1:$104,MATCH(AH$4,'[3]3.4.1'!$A:$A,0),MATCH(Summary!$A16,'[3]3.4.1'!$1:$1,0)) -> 13974.943 | AI16: =INDEX('[3]3.4.1'!$1:$104,MATCH(AI$4,'[3]3.4.1'!$A:$A,0),MATCH(Summary!$B16,'[3]3.4.1'!$1:$1,0)) -> 116204.61 | AJ16: =INDEX('[3]3.4.1'!$1:$104,MATCH(AJ$4,'[3]3.4.1'!$A:$A,0),MATCH(Summary!$C16,'[3]3.4.1'!$1:$1,0)) -> 130179.55 | AK16: =INDEX('[3]3.4.1'!$1:$104,MATCH(AK$4,'[3]3.4.1'!$A:$A,0),MATCH(Summary!$A16,'[3]3.4.1'!$1:$1,0)) -> 14483.044 | AL16: =INDEX('[3]3.4.1'!$1:$104,MATCH(AL$4,'[3]3.4.1'!$A:$A,0),MATCH(Summary!$B16,'[3]3.4.1'!$1:$1,0)) -> 113621.16 | AM16: =INDEX('[3]3.4.1'!$1:$104,MATCH(AM$4,'[3]3.4.1'!$A:$A,0),MATCH(Summary!$C16,'[3]3.4.1'!$1:$1,0)) -> 128104.21 | AN16: =INDEX('[3]3.4.1'!$1:$104,MATCH(AN$4,'[3]3.4.1'!$A:$A,0),MATCH(Summary!$A16,'[3]3.4.1'!$1:$1,0)) -> 15221.531 | AO16: =INDEX('[3]3.4.1'!$1:$104,MATCH(AO$4,'[3]3.4.1'!$A:$A,0),MATCH(Summary!$B16,'[3]3.4.1'!$1:$1,0)) -> 131263.17 | AP16: =INDEX('[3]3.4.1'!$1:$104,MATCH(AP$4,'[3]3.4.1'!$A:$A,0),MATCH(Summary!$C16,'[3]3.4.1'!$1:$1,0)) -> 146484.71 | AQ16: =INDEX('[3]3.4.1'!$1:$104,MATCH(AQ$4,'[3]3.4.1'!$A:$A,0),MATCH(Summary!$A16,'[3]3.4.1'!$1:$1,0)) -> 15025.371 | AR16: =INDEX('[3]3.4.1'!$1:$104,MATCH(AR$4,'[3]3.4.1'!$A:$A,0),MATCH(Summary!$B16,'[3]3.4.1'!$1:$1,0)) -> 121429.41 | AS16: =INDEX('[3]3.4.1'!$1:$104,MATCH(AS$4,'[3]3.4.1'!$A:$A,0),MATCH(Summary!$C16,'[3]3.4.1'!$1:$1,0)) -> 136454.78 | AT16: =INDEX('[3]3.4.1'!$1:$104,MATCH(AT$4,'[3]3.4.1'!$A:$A,0),MATCH(Summary!$A16,'[3]3.4.1'!$1:$1,0)) -> 14073.304 | AU16: =INDEX('[3]3.4.1'!$1:$104,MATCH(AU$4,'[3]3.4.1'!$A:$A,0),MATCH(Summary!$B16,'[3]3.4.1'!$1:$1,0)) -> 124333.81 | AV16: =INDEX('[3]3.4.1'!$1:$104,MATCH(AV$4,'[3]3.4.1'!$A:$A,0),MATCH(Summary!$C16,'[3]3.4.1'!$1:$1,0)) -> 138407.11 | AW16: =INDEX('[3]3.4.1'!$1:$104,MATCH(AW$4,'[3]3.4.1'!$A:$A,0),MATCH(Summary!$A16,'[3]3.4.1'!$1:$1,0)) -> 13226.637 | AX16: =INDEX('[3]3.4.1'!$1:$104,MATCH(AX$4,'[3]3.4.1'!$A:$A,0),MATCH(Summary!$B16,'[3]3.4.1'!$1:$1,0)) -> 139122.73 | AY16: =INDEX('[3]3.4.1'!$1:$104,MATCH(AY$4,'[3]3.4.1'!$A:$A,0),MATCH(Summary!$C16,'[3]3.4.1'!$1:$1,0)) -> 152349.36 | AZ16: =INDEX('[3]3.4.1'!$1:$104,MATCH(AZ$4,'[3]3.4.1'!$A:$A,0),MATCH(Summary!$A16,'[3]3.4.1'!$1:$1,0)) -> 10821.36 | BA16: =INDEX('[3]3.4.1'!$1:$104,MATCH(BA$4,'[3]3.4.1'!$A:$A,0),MATCH(Summary!$B16,'[3]3.4.1'!$1:$1,0)) -> 138673.73 | BB16: =INDEX('[3]3.4.1'!$1:$104,MATCH(BB$4,'[3]3.4.1'!$A:$A,0),MATCH(Summary!$C16,'[3]3.4.1'!$1:$1,0)) -> 149495.09 | BC16: =INDEX('[3]3.4.1'!$1:$104,MATCH(BC$4,'[3]3.4.1'!$A:$A,0),MATCH(Summary!$A16,'[3]3.4.1'!$1:$1,0)) -> 10577.562 | BD16: =INDEX('[3]3.4.1'!$1:$104,MATCH(BD$4,'[3]3.4.1'!$A:$A,0),MATCH(Summary!$B16,'[3]3.4.1'!$1:$1,0)) -> 148935.23 | BE16: =INDEX('[3]3.4.1'!$1:$104,MATCH(BE$4,'[3]3.4.1'!$A:$A,0),MATCH(Summary!$C16,'[3]3.4.1'!$1:$1,0)) -> 159512.79 | BF16: =INDEX('[3]3.4.1'!$1:$104,MATCH(BF$4,'[3]3.4.1'!$A:$A,0),MATCH(Summary!$A16,'[3]3.4.1'!$1:$1,0)) -> 12622.642 | BG16: =INDEX('[3]3.4.1'!$1:$104,MATCH(BG$4,'[3]3.4.1'!$A:$A,0),MATCH(Summary!$B16,'[3]3.4.1'!$1:$1,0)) -> 159585.63 | BH16: =INDEX('[3]3.4.1'!$1:$104,MATCH(BH$4,'[3]3.4.1'!$A:$A,0),MATCH(Summary!$C16,'[3]3.4.1'!$1:$1,0)) -> 172208.27 | BI16: =INDEX('[3]3.4.1'!$1:$104,MATCH(BI$4,'[3]3.4.1'!$A:$A,0),MATCH(Summary!$A16,'[3]3.4.1'!$1:$1,0)) -> 13888.557 | BJ16: =INDEX('[3]3.4.1'!$1:$104,MATCH(BJ$4,'[3]3.4.1'!$A:$A,0),MATCH(Summary!$B16,'[3]3.4.1'!$1:$1,0)) -> 179755.39 | BK16: =INDEX('[3]3.4.1'!$1:$104,MATCH(BK$4,'[3]3.4.1'!$A:$A,0),MATCH(Summary!$C16,'[3]3.4.1'!$1:$1,0)) -> 193643.95
A17: loans_inhk_hkd | B17: loans_inhk_fc | C17: loans_inhk_total | E17: Other loans for use in H.K(1) | H17: =O17/$O$12 -> 0.70997683 | I17: =IFERROR(L17/AV17-1,"") -> 0.059869499 | J17: =INDEX('[3]3.4.1'!$1:$104,MATCH(J$4,'[3]3.4.1'!$A:$A,0),MATCH(Summary!$A17,'[3]3.4.1'!$1:$1,0)) -> 5580470.7 | K17: =INDEX('[3]3.4.1'!$1:$104,MATCH(K$4,'[3]3.4.1'!$A:$A,0),MATCH(Summary!$B17,'[3]3.4.1'!$1:$1,0)) -> 2068567.8 | L17: =INDEX('[3]3.4.1'!$1:$104,MATCH(L$4,'[3]3.4.1'!$A:$A,0),MATCH(Summary!$C17,'[3]3.4.1'!$1:$1,0)) -> 7649038.4 | M17: =INDEX('[3]3.4.1'!$1:$104,MATCH(M$4,'[3]3.4.1'!$A:$A,0),MATCH(Summary!$A17,'[3]3.4.1'!$1:$1,0)) -> 5589675.4 | N17: =INDEX('[3]3.4.1'!$1:$104,MATCH(N$4,'[3]3.4.1'!$A:$A,0),MATCH(Summary!$B17,'[3]3.4.1'!$1:$1,0)) -> 2069480.6 | O17: =INDEX('[3]3.4.1'!$1:$104,MATCH(O$4,'[3]3.4.1'!$A:$A,0),MATCH(Summary!$C17,'[3]3.4.1'!$1:$1,0)) -> 7659156 | P17: =INDEX('[3]3.4.1'!$1:$104,MATCH(P$4,'[3]3.4.1'!$A:$A,0),MATCH(Summary!$A17,'[3]3.4.1'!$1:$1,0)) -> 5488152.2 | Q17: =INDEX('[3]3.4.1'!$1:$104,MATCH(Q$4,'[3]3.4.1'!$A:$A,0),MATCH(Summary!$B17,'[3]3.4.1'!$1:$1,0)) -> 2078291 | R17: =INDEX('[3]3.4.1'!$1:$104,MATCH(R$4,'[3]3.4.1'!$A:$A,0),MATCH(Summary!$C17,'[3]3.4.1'!$1:$1,0)) -> 7566443.3 | S17: =INDEX('[3]3.4.1'!$1:$104,MATCH(S$4,'[3]3.4.1'!$A:$A,0),MATCH(Summary!$A17,'[3]3.4.1'!$1:$1,0)) -> 5472828.6 | T17: =INDEX('[3]3.4.1'!$1:$104,MATCH(T$4,'[3]3.4.1'!$A:$A,0),MATCH(Summary!$B17,'[3]3.4.1'!$1:$1,0)) -> 1990899.9 | U17: =INDEX('[3]3.4.1'!$1:$104,MATCH(U$4,'[3]3.4.1'!$A:$A,0),MATCH(Summary!$C17,'[3]3.4.1'!$1:$1,0)) -> 7463728.5 | V17: =INDEX('[3]3.4.1'!$1:$104,MATCH(V$4,'[3]3.4.1'!$A:$A,0),MATCH(Summary!$A17,'[3]3.4.1'!$1:$1,0)) -> 5461882.5 | W17: =INDEX('[3]3.4.1'!$1:$104,MATCH(W$4,'[3]3.4.1'!$A:$A,0),MATCH(Summary!$B17,'[3]3.4.1'!$1:$1,0)) -> 1978438.2 | X17: =INDEX('[3]3.4.1'!$1:$104,MATCH(X$4,'[3]3.4.1'!$A:$A,0),MATCH(Summary!$C17,'[3]3.4.1'!$1:$1,0)) -> 7440320.7 | Y17: =INDEX('[3]3.4.1'!$1:$104,MATCH(Y$4,'[3]3.4.1'!$A:$A,0),MATCH(Summary!$A17,'[3]3.4.1'!$1:$1,0)) -> 5431952.5 | Z17: =INDEX('[3]3.4.1'!$1:$104,MATCH(Z$4,'[3]3.4.1'!$A:$A,0),MATCH(Summary!$B17,'[3]3.4.1'!$1:$1,0)) -> 1920630.3 | AA17: =INDEX('[3]3.4.1'!$1:$104,MATCH(AA$4,'[3]3.4.1'!$A:$A,0),MATCH(Summary!$C17,'[3]3.4.1'!$1:$1,0)) -> 7352582.8 | AB17: =INDEX('[3]3.4.1'!$1:$104,MATCH(AB$4,'[3]3.4.1'!$A:$A,0),MATCH(Summary!$A17,'[3]3.4.1'!$1:$1,0)) -> 5430504.2 | AC17: =INDEX('[3]3.4.1'!$1:$104,MATCH(AC$4,'[3]3.4.1'!$A:$A,0),MATCH(Summary!$B17,'[3]3.4.1'!$1:$1,0)) -> 1898592.3 | AD17: =INDEX('[3]3.4.1'!$1:$104,MATCH(AD$4,'[3]3.4.1'!$A:$A,0),MATCH(Summary!$C17,'[3]3.4.1'!$1:$1,0)) -> 7329096.5 | AE17: =INDEX('[3]3.4.1'!$1:$104,MATCH(AE$4,'[3]3.4.1'!$A:$A,0),MATCH(Summary!$A17,'[3]3.4.1'!$1:$1,0)) -> 5408698.2 | AF17: =INDEX('[3]3.4.1'!$1:$104,MATCH(AF$4,'[3]3.4.1'!$A:$A,0),MATCH(Summary!$B17,'[3]3.4.1'!$1:$1,0)) -> 1835826.7 | AG17: =INDEX('[3]3.4.1'!$1:$104,MATCH(AG$4,'[3]3.4.1'!$A:$A,0),MATCH(Summary!$C17,'[3]3.4.1'!$1:$1,0)) -> 7244524.9 | AH17: =INDEX('[3]3.4.1'!$1:$104,MATCH(AH$4,'[3]3.4.1'!$A:$A,0),MATCH(Summary!$A17,'[3]3.4.1'!$1:$1,0)) -> 5391482.5 | AI17: =INDEX('[3]3.4.1'!$1:$104,MATCH(AI$4,'[3]3.4.1'!$A:$A,0),MATCH(Summary!$B17,'[3]3.4.1'!$1:$1,0)) -> 1811566 | AJ17: =INDEX('[3]3.4.1'!$1:$104,MATCH(AJ$4,'[3]3.4.1'!$A:$A,0),MATCH(Summary!$C17,'[3]3.4.1'!$1:$1,0)) -> 7203048.4 | AK17: =INDEX('[3]3.4.1'!$1:$104,MATCH(AK$4,'[3]3.4.1'!$A:$A,0),MATCH(Summary!$A17,'[3]3.4.1'!$1:$1,0)) -> 5414751.6 | AL17: =INDEX('[3]3.4.1'!$1:$104,MATCH(AL$4,'[3]3.4.1'!$A:$A,0),MATCH(Summary!$B17,'[3]3.4.1'!$1:$1,0)) -> 1797183.2 | AM17: =INDEX('[3]3.4.1'!$1:$104,MATCH(AM$4,'[3]3.4.1'!$A:$A,0),MATCH(Summary!$C17,'[3]3.4.1'!$1:$1,0)) -> 7211934.8 | AN17: =INDEX('[3]3.4.1'!$1:$104,MATCH(AN$4,'[3]3.4.1'!$A:$A,0),MATCH(Summary!$A17,'[3]3.4.1'!$1:$1,0)) -> 5452570 | AO17: =INDEX('[3]3.4.1'!$1:$104,MATCH(AO$4,'[3]3.4.1'!$A:$A,0),MATCH(Summary!$B17,'[3]3.4.1'!$1:$1,0)) -> 1790930.5 | AP17: =INDEX('[3]3.4.1'!$1:$104,MATCH(AP$4,'[3]3.4.1'!$A:$A,0),MATCH(Summary!$C17,'[3]3.4.1'!$1:$1,0)) -> 7243500.5 | AQ17: =INDEX('[3]3.4.1'!$1:$104,MATCH(AQ$4,'[3]3.4.1'!$A:$A,0),MATCH(Summary!$A17,'[3]3.4.1'!$1:$1,0)) -> 5433198.2 | AR17: =INDEX('[3]3.4.1'!$1:$104,MATCH(AR$4,'[3]3.4.1'!$A:$A,0),MATCH(Summary!$B17,'[3]3.4.1'!$1:$1,0)) -> 1786769.1 | AS17: =INDEX('[3]3.4.1'!$1:$104,MATCH(AS$4,'[3]3.4.1'!$A:$A,0),MATCH(Summary!$C17,'[3]3.4.1'!$1:$1,0)) -> 7219967.3 | AT17: =INDEX('[3]3.4.1'!$1:$104,MATCH(AT$4,'[3]3.4.1'!$A:$A,0),MATCH(Summary!$A17,'[3]3.4.1'!$1:$1,0)) -> 5429428.7 | AU17: =INDEX('[3]3.4.1'!$1:$104,MATCH(AU$4,'[3]3.4.1'!$A:$A,0),MATCH(Summary!$B17,'[3]3.4.1'!$1:$1,0)) -> 1787533.8 | AV17: =INDEX('[3]3.4.1'!$1:$104,MATCH(AV$4,'[3]3.4.1'!$A:$A,0),MATCH(Summary!$C17,'[3]3.4.1'!$1:$1,0)) -> 7216962.5 | AW17: =INDEX('[3]3.4.1'!$1:$104,MATCH(AW$4,'[3]3.4.1'!$A:$A,0),MATCH(Summary!$A17,'[3]3.4.1'!$1:$1,0)) -> 5464932.4 | AX17: =INDEX('[3]3.4.1'!$1:$104,MATCH(AX$4,'[3]3.4.1'!$A:$A,0),MATCH(Summary!$B17,'[3]3.4.1'!$1:$1,0)) -> 1808945.2 | AY17: =INDEX('[3]3.4.1'!$1:$104,MATCH(AY$4,'[3]3.4.1'!$A:$A,0),MATCH(Summary!$C17,'[3]3.4.1'!$1:$1,0)) -> 7273877.6 | AZ17: =INDEX('[3]3.4.1'!$1:$104,MATCH(AZ$4,'[3]3.4.1'!$A:$A,0),MATCH(Summary!$A17,'[3]3.4.1'!$1:$1,0)) -> 5442170.1 | BA17: =INDEX('[3]3.4.1'!$1:$104,MATCH(BA$4,'[3]3.4.1'!$A:$A,0),MATCH(Summary!$B17,'[3]3.4.1'!$1:$1,0)) -> 1666569.3 | BB17: =INDEX('[3]3.4.1'!$1:$104,MATCH(BB$4,'[3]3.4.1'!$A:$A,0),MATCH(Summary!$C17,'[3]3.4.1'!$1:$1,0)) -> 7108739.3 | BC17: =INDEX('[3]3.4.1'!$1:$104,MATCH(BC$4,'[3]3.4.1'!$A:$A,0),MATCH(Summary!$A17,'[3]3.4.1'!$1:$1,0)) -> 5636493.2 | BD17: =INDEX('[3]3.4.1'!$1:$104,MATCH(BD$4,'[3]3.4.1'!$A:$A,0),MATCH(Summary!$B17,'[3]3.4.1'!$1:$1,0)) -> 1626831.8 | BE17: =INDEX('[3]3.4.1'!$1:$104,MATCH(BE$4,'[3]3.4.1'!$A:$A,0),MATCH(Summary!$C17,'[3]3.4.1'!$1:$1,0)) -> 7263325 | BF17: =INDEX('[3]3.4.1'!$1:$104,MATCH(BF$4,'[3]3.4.1'!$A:$A,0),MATCH(Summary!$A17,'[3]3.4.1'!$1:$1,0)) -> 5648487.7 | BG17: =INDEX('[3]3.4.1'!$1:$104,MATCH(BG$4,'[3]3.4.1'!$A:$A,0),MATCH(Summary!$B17,'[3]3.4.1'!$1:$1,0)) -> 1642161.1 | BH17: =INDEX('[3]3.4.1'!$1:$104,MATCH(BH$4,'[3]3.4.1'!$A:$A,0),MATCH(Summary!$C17,'[3]3.4.1'!$1:$1,0)) -> 7290648.8 | BI17: =INDEX('[3]3.4.1'!$1:$104,MATCH(BI$4,'[3]3.4.1'!$A:$A,0),MATCH(Summary!$A17,'[3]3.4.1'!$1:$1,0)) -> 5468186.2 | BJ17: =INDEX('[3]3.4.1'!$1:$104,MATCH(BJ$4,'[3]3.4.1'!$A:$A,0),MATCH(Summary!$B17,'[3]3.4.1'!$1:$1,0)) -> 1759079.1 | BK17: =INDEX('[3]3.4.1'!$1:$104,MATCH(BK$4,'[3]3.4.1'!$A:$A,0),MATCH(Summary!$C17,'[3]3.4.1'!$1:$1,0)) -> 7227265.3
C18: mfg | F18: Manufacturing | G18: 製造業 | H18: =O18/$O$12 -> 0.03370759 | I18: =IFERROR(L18/AV18-1,"") | L18: =_xlfn.IFNA(INDEX('[3]3.5.1'!$1:$104,MATCH(L$4,'[3]3.5.1'!$A:$A,0),MATCH(Summary!$C18,'[3]3.5.1'!$1:$1,0)),"") | O18: =_xlfn.IFNA(INDEX('[3]3.5.1'!$1:$104,MATCH(O$4,'[3]3.5.1'!$A:$A,0),MATCH(Summary!$C18,'[3]3.5.1'!$1:$1,0)),"") -> 363633.97 | R18: =_xlfn.IFNA(INDEX('[3]3.5.1'!$1:$104,MATCH(R$4,'[3]3.5.1'!$A:$A,0),MATCH(Summary!$C18,'[3]3.5.1'!$1:$1,0)),"") | U18: =_xlfn.IFNA(INDEX('[3]3.5.1'!$1:$104,MATCH(U$4,'[3]3.5.1'!$A:$A,0),MATCH(Summary!$C18,'[3]3.5.1'!$1:$1,0)),"") | X18: =_xlfn.IFNA(INDEX('[3]3.5.1'!$1:$104,MATCH(X$4,'[3]3.5.1'!$A:$A,0),MATCH(Summary!$C18,'[3]3.5.1'!$1:$1,0)),"") -> 328188.24 | AA18: =_xlfn.IFNA(INDEX('[3]3.5.1'!$1:$104,MATCH(AA$4,'[3]3.5.1'!$A:$A,0),MATCH(Summary!$C18,'[3]3.5.1'!$1:$1,0)),"") | AD18: =_xlfn.IFNA(INDEX('[3]3.5.1'!$1:$104,MATCH(AD$4,'[3]3.5.1'!$A:$A,0),MATCH(Summary!$C18,'[3]3.5.1'!$1:$1,0)),"") | AG18: =_xlfn.IFNA(INDEX('[3]3.5.1'!$1:$104,MATCH(AG$4,'[3]3.5.1'!$A:$A,0),MATCH(Summary!$C18,'[3]3.5.1'!$1:$1,0)),"") -> 306596.64 | AJ18: =_xlfn.IFNA(INDEX('[3]3.5.1'!$1:$104,MATCH(AJ$4,'[3]3.5.1'!$A:$A,0),MATCH(Summary!$C18,'[3]3.5.1'!$1:$1,0)),"") | AM18: =_xlfn.IFNA(INDEX('[3]3.5.1'!$1:$104,MATCH(AM$4,'[3]3.5.1'!$A:$A,0),MATCH(Summary!$C18,'[3]3.5.1'!$1:$1,0)),"") | AP18: =_xlfn.IFNA(INDEX('[3]3.5.1'!$1:$104,MATCH(AP$4,'[3]3.5.1'!$A:$A,0),MATCH(Summary!$C18,'[3]3.5.1'!$1:$1,0)),"") -> 322774.75 | AS18: =_xlfn.IFNA(INDEX('[3]3.5.1'!$1:$104,MATCH(AS$4,'[3]3.5.1'!$A:$A,0),MATCH(Summary!$C18,'[3]3.5.1'!$1:$1,0)),"") | AV18: =_xlfn.IFNA(INDEX('[3]3.5.1'!$1:$104,MATCH(AV$4,'[3]3.5.1'!$A:$A,0),MATCH(Summary!$C18,'[3]3.5.1'!$1:$1,0)),"") | AY18: =_xlfn.IFNA(INDEX('[3]3.5.1'!$1:$104,MATCH(AY$4,'[3]3.5.1'!$A:$A,0),MATCH(Summary!$C18,'[3]3.5.1'!$1:$1,0)),"") -> 324870.77 | BB18: =_xlfn.IFNA(INDEX('[3]3.5.1'!$1:$104,MATCH(BB$4,'[3]3.5.1'!$A:$A,0),MATCH(Summary!$C18,'[3]3.5.1'!$1:$1,0)),"") -> 295132.54 | BE18: =_xlfn.IFNA(INDEX('[3]3.5.1'!$1:$104,MATCH(BE$4,'[3]3.5.1'!$A:$A,0),MATCH(Summary!$C18,'[3]3.5.1'!$1:$1,0)),"") | BH18: =_xlfn.IFNA(INDEX('[3]3.5.1'!$1:$104,MATCH(BH$4,'[3]3.5.1'!$A:$A,0),MATCH(Summary!$C18,'[3]3.5.1'!$1:$1,0)),"") | BK18: =_xlfn.IFNA(INDEX('[3]3.5.1'!$1:$104,MATCH(BK$4,'[3]3.5.1'!$A:$A,0),MATCH(Summary!$C18,'[3]3.5.1'!$1:$1,0)),"")
