Workbook
Name __gdp2: #REF!
Name __nlp2: #REF!
Name __Old3: '[1]T103'!#REF!
Name __Old4: '[1]T208'!#REF!
Name __Old5: '[1]T208'!#REF!
Name __Old6: '[1]T208'!#REF!
Name __Old7: '[1]T208'!#REF!
Name __old8: '[1]T208'!#REF!
Name _gdp2: #REF!
Name _nlp2: #REF!
Name _PMI2: #REF!
Name bad_debt: #REF!
Name bankruptcy: #REF!
Name BoxPlot: "BoxPlot"
Name Bubble: "Bubble"
Name buy_rent_gap: #REF!
Name CAB: #REF!
Name Candlestick: "Candlestick"
Name car: #REF!
Name Chart: "Chart"
Name ChartImage: "ChartImage"
Name CMTH5: '[1]T208'!#REF!
Name CMTH6: '[1]T208'!#REF!
Name CMTH7: '[1]T208'!#REF!
Name ColumnRange: "ColumnRange"
Name cpi: #REF!
Name data: #REF!
Name DATA: '[1]T5011'!#REF!
Name DATA1: '[1]T502'!#REF!
Name data2: #REF!
Name DATA2: '[1]T502'!#REF!
Name deposits: #REF!
Name Dumbbell: "Dumbbell"
Name equity: #REF!
Name fiscal: #REF!
Name fwd: #REF!
Name gdp: #REF!
Name Heatmap: "Heatmap"
Name Histogram: "Histogram"
Name insert: [2]!insert
Name interest: #REF!
Name IQ_CH: 110000
Name IQ_CQ: 5000
Name IQ_CY: 10000
Name IQ_DAILY: 500000
Name IQ_FH: 100000
Name IQ_FQ: 500
Name IQ_FY: 1000
Name IQ_LTM: 2000
Name IQ_MONTH: 15000
Name IQ_NTM: 6000
Name IQ_WEEK: 50000
Name IQ_YTD: 3000
Name labour: #REF!
Name loan: #REF!
Name loans: #REF!
Name LTD: #REF!
Name Map: "Map"
Name mci: #REF!
Name money: #REF!

Sheet Summary
F3: Table 3.5.1 : Authorized institutions (HK$ million, unless otherwise specified) | H3: 1.2 | J3: 2026-07 | K3: 2026-07 | L3: 2026-07 | M3: =TEXT(EOMONTH(DATE(LEFT(L3,4),RIGHT(L3,2),1),-1),"yyyy-mm") -> 2026-06 | N3: =M3 -> 2026-06 | O3: =N3 -> 2026-06 | P3: =TEXT(EOMONTH(DATE(LEFT(O3,4),RIGHT(O3,2),1),-1),"yyyy-mm") -> 2026-05 | Q3: =P3 -> 2026-05 | R3: =Q3 -> 2026-05 | S3: =TEXT(EOMONTH(DATE(LEFT(R3,4),RIGHT(R3,2),1),-1),"yyyy-mm") -> 2026-04 | T3: =S3 -> 2026-04 | U3: =T3 -> 2026-04 | V3: =TEXT(EOMONTH(DATE(LEFT(U3,4),RIGHT(U3,2),1),-1),"yyyy-mm") -> 2026-03 | W3: =V3 -> 2026-03 | X3: =W3 -> 2026-03 | Y3: =TEXT(EOMONTH(DATE(LEFT(X3,4),RIGHT(X3,2),1),-1),"yyyy-mm") -> 2026-02 | Z3: =Y3 -> 2026-02 | AA3: =Z3 -> 2026-02 | AB3: =TEXT(EOMONTH(DATE(LEFT(AA3,4),RIGHT(AA3,2),1),-1),"yyyy-mm") -> 2026-01 | AC3: =AB3 -> 2026-01 | AD3: =AC3 -> 2026-01 | AE3: =TEXT(EOMONTH(DATE(LEFT(AD3,4),RIGHT(AD3,2),1),-1),"yyyy-mm") -> 2025-12 | AF3: =AE3 -> 2025-12 | AG3: =AF3 -> 2025-12 | AH3: =TEXT(EOMONTH(DATE(LEFT(AG3,4),RIGHT(AG3,2),1),-1),"yyyy-mm") -> 2025-11 | AI3: =AH3 -> 2025-11 | AJ3: =AI3 -> 2025-11 | AK3: =TEXT(EOMONTH(DATE(LEFT(AJ3,4),RIGHT(AJ3,2),1),-1),"yyyy-mm") -> 2025-10 | AL3: =AK3 -> 2025-10 | AM3: =AL3 -> 2025-10 | AN3: =TEXT(EOMONTH(DATE(LEFT(AM3,4),RIGHT(AM3,2),1),-1),"yyyy-mm") -> 2025-09 | AO3: =AN3 -> 2025-09 | AP3: =AO3 -> 2025-09 | AQ3: =TEXT(EOMONTH(DATE(LEFT(AP3,4),RIGHT(AP3,2),1),-1),"yyyy-mm") -> 2025-08 | AR3: =AQ3 -> 2025-08 | AS3: =AR3 -> 2025-08 | AT3: =TEXT(EOMONTH(DATE(LEFT(AS3,4),RIGHT(AS3,2),1),-1),"yyyy-mm") -> 2025-07 | AU3: =AT3 -> 2025-07 | AV3: =AU3 -> 2025-07 | AW3: =TEXT(EOMONTH(DATE(LEFT(AV3,4),RIGHT(AV3,2),1),-1),"yyyy-mm") -> 2025-06 | AX3: =AW3 -> 2025-06 | AY3: =AX3 -> 2025-06 | AZ3: 2024-00 | BA3: =AZ3 -> 2024-00 | BB3: =BA3 -> 2024-00 | BC3: 2023-00 | BD3: =BC3 -> 2023-00 | BE3: =BD3 -> 2023-00 | BF3: 2022-00 | BG3: =BF3 -> 2022-00 | BH3: =BG3 -> 2022-00 | BI3: 2021-00 | BJ3: =BI3 -> 2021-00 | BK3: =BJ3 -> 2021-00
F4: 認可機構 (百萬港元, 另有說明者除外) | H4: 3.4.1 | J4: =J3 -> 2026-07 | K4: =K3 -> 2026-07 | L4: =L3 -> 2026-07 | M4: =M3 -> 2026-06 | N4: =N3 -> 2026-06 | O4: =O3 -> 2026-06 | P4: =P3 -> 2026-05 | Q4: =Q3 -> 2026-05 | ... AY4: =AY3 -> 2025-06 | AZ4: 2024-12 | BA4: 2024-12 | BB4: 2024-12 | BC4: 2023-12 | BD4: 2023-12 | BE4: 2023-12 | BF4: 2022-12 | BG4: 2022-12 | BH4: 2022-12 | BI4: 2021-12 | BJ4: 2021-12 | BK4: 2021-12
F9: Table : Loans and advances
F10: 貸款及墊款 | L10: =TEXT(DATE(LEFT(L3,4),RIGHT(L3,2),1),"[$-en-US]mmmm yyyy") -> July 2026 | O10: =TEXT(DATE(LEFT(O3,4),RIGHT(O3,2),1),"[$-en-US]mmmm yyyy") -> June 2026 | R10: =TEXT(DATE(LEFT(R3,4),RIGHT(R3,2),1),"[$-en-US]mmmm yyyy") -> May 2026 | U10: =TEXT(DATE(LEFT(U3,4),RIGHT(U3,2),1),"[$-en-US]mmmm yyyy") -> April 2026 | X10: =TEXT(DATE(LEFT(X3,4),RIGHT(X3,2),1),"[$-en-US]mmmm yyyy") -> March 2026 | AA10: =TEXT(DATE(LEFT(AA3,4),RIGHT(AA3,2),1),"[$-en-US]mmmm yyyy") -> February 2026 | AD10: =TEXT(DATE(LEFT(AD3,4),RIGHT(AD3,2),1),"[$-en-US]mmmm yyyy") -> January 2026 | AG10: =TEXT(DATE(LEFT(AG3,4),RIGHT(AG3,2),1),"[$-en-US]mmmm yyyy") -> December 2025 | AJ10: =TEXT(DATE(LEFT(AJ3,4),RIGHT(AJ3,2),1),"[$-en-US]mmmm yyyy") -> November 2025 | AM10: =TEXT(DATE(LEFT(AM3,4),RIGHT(AM3,2),1),"[$-en-US]mmmm yyyy") -> October 2025 | AP10: =TEXT(DATE(LEFT(AP3,4),RIGHT(AP3,2),1),"[$-en-US]mmmm yyyy") -> September 2025 | AS10: =TEXT(DATE(LEFT(AS3,4),RIGHT(AS3,2),1),"[$-en-US]mmmm yyyy") -> August 2025 | AV10: =TEXT(DATE(LEFT(AV3,4),RIGHT(AV3,2),1),"[$-en-US]mmmm yyyy") -> July 2025 | AY10: =TEXT(DATE(LEFT(AY3,4),RIGHT(AY3,2),1),"[$-en-US]mmmm yyyy") -> June 2025 | BB10: December 2024 | BE10: December 2023 | BH10: December 2022 | BK10: December 2021
F11: Table 3.5.1 : Authorized institutions (HK$ million, unless otherwise specified) | H11: Proportion% | I11: YoY% | J11: HK$ | K11: Foreign currency | L11: Total | M11: HK$ | N11: Foreign currency | O11: Total | P11: HK$ | Q11: Foreign currency | R11: Total | S11: HK$ | T11: Foreign currency | U11: Total | V11: HK$ | W11: Foreign currency | X11: Total | Y11: HK$ | Z11: Foreign currency | AA11: Total | AB11: HK$ | AC11: Foreign currency | AD11: Total | AE11: HK$ | AF11: Foreign currency | AG11: Total | AH11: HK$ | AI11: Foreign currency | AJ11: Total | AK11: HK$ | AL11: Foreign currency | AM11: Total | AN11: HK$ | AO11: Foreign currency | AP11: Total | AQ11: HK$ | AR11: Foreign currency | AS11: Total | AT11: HK$ | AU11: Foreign currency | AV11: Total | AW11: HK$ | AX11: Foreign currency | AY11: Total | AZ11: HK$ | BA11: Foreign currency | BB11: Total | BC11: HK$ | BD11: Foreign currency | BE11: Total | BF11: HK$ | BG11: Foreign currency | BH11: Total | BI11: HK$ | BJ11: Foreign currency | BK11: Total
C12: loans_total | E12: Total loan and advances | H12: =O12/$O$12 -> 1 | I12: =IFERROR(L12/AV12-1,"") -> 0.076511392 | L12: =INDEX('1.2'!$1:$104,MATCH(L$3,'1.2'!$A:$A,0),MATCH(Summary!$C12,'1.2'!$1:$1,0)) -> 10809854 | O12: =INDEX('1.2'!$1:$104,MATCH(M$3,'1.2'!$A:$A,0),MATCH(Summary!$C12,'1.2'!$1:$1,0)) -> 10787896 | R12: =INDEX('1.2'!$1:$104,MATCH(P$3,'1.2'!$A:$A,0),MATCH(Summary!$C12,'1.2'!$1:$1,0)) -> 10646152 | U12: =INDEX('1.2'!$1:$104,MATCH(S$3,'1.2'!$A:$A,0),MATCH(Summary!$C12,'1.2'!$1:$1,0)) -> 10496858 | X12: =INDEX('1.2'!$1:$104,MATCH(V$3,'1.2'!$A:$A,0),MATCH(Summary!$C12,'1.2'!$1:$1,0)) -> 10440278 | AA12: =INDEX('1.2'!$1:$104,MATCH(Y$3,'1.2'!$A:$A,0),MATCH(Summary!$C12,'1.2'!$1:$1,0)) -> 10302290 | AD12: =INDEX('1.2'!$1:$104,MATCH(AB$3,'1.2'!$A:$A,0),MATCH(Summary!$C12,'1.2'!$1:$1,0)) -> 10245411 | AG12: =INDEX('1.2'!$1:$104,MATCH(AE$3,'1.2'!$A:$A,0),MATCH(Summary!$C12,'1.2'!$1:$1,0)) -> 10136142 | AJ12: =INDEX('1.2'!$1:$104,MATCH(AH$3,'1.2'!$A:$A,0),MATCH(Summary!$C12,'1.2'!$1:$1,0)) -> 10002556 | AM12: =INDEX('1.2'!$1:$104,MATCH(AK$3,'1.2'!$A:$A,0),MATCH(Summary!$C12,'1.2'!$1:$1,0)) -> 9997067.5 | AP12: =INDEX('1.2'!$1:$104,MATCH(AN$3,'1.2'!$A:$A,0),MATCH(Summary!$C12,'1.2'!$1:$1,0)) -> 10068576 | AS12: =INDEX('1.2'!$1:$104,MATCH(AQ$3,'1.2'!$A:$A,0),MATCH(Summary!$C12,'1.2'!$1:$1,0)) -> 10003516 | AV12: =INDEX('1.2'!$1:$104,MATCH(AT$3,'1.2'!$A:$A,0),MATCH(Summary!$C12,'1.2'!$1:$1,0)) -> 10041560 | AY12: =INDEX('1.2'!$1:$104,MATCH(AW$3,'1.2'!$A:$A,0),MATCH(Summary!$C12,'1.2'!$1:$1,0)) -> 10158381 | BB12: =INDEX('1.2'!$1:$104,MATCH(AZ$3,'1.2'!$A:$A,0),MATCH(Summary!$C12,'1.2'!$1:$1,0)) -> 9907808 | BE12: =INDEX('1.2'!$1:$104,MATCH(BC$3,'1.2'!$A:$A,0),MATCH(Summary!$C12,'1.2'!$1:$1,0)) -> 10191315 | BH12: =INDEX('1.2'!$1:$104,MATCH(BF$3,'1.2'!$A:$A,0),MATCH(Summary!$C12,'1.2'!$1:$1,0)) -> 10571298 | BK12: =INDEX('1.2'!$1:$104,MATCH(BI$3,'1.2'!$A:$A,0),MATCH(Summary!$C12,'1.2'!$1:$1,0)) -> 10893147
C13: loans_in_hk | E13: Loans for use in HK | H13: =O13/$O$12 -> 0.75040076 | I13: =IFERROR(L13/AV13-1,"") -> 0.065162006 | L13: =INDEX('1.2'!$1:$104,MATCH(L$3,'1.2'!$A:$A,0),MATCH(Summary!$C13,'1.2'!$1:$1,0)) -> 8070867 | O13: =INDEX('1.2'!$1:$104,MATCH(M$3,'1.2'!$A:$A,0),MATCH(Summary!$C13,'1.2'!$1:$1,0)) -> 8095245.2 | R13: =INDEX('1.2'!$1:$104,MATCH(P$3,'1.2'!$A:$A,0),MATCH(Summary!$C13,'1.2'!$1:$1,0)) -> 7981206.3 | U13: =INDEX('1.2'!$1:$104,MATCH(S$3,'1.2'!$A:$A,0),MATCH(Summary!$C13,'1.2'!$1:$1,0)) -> 7869195.5 | X13: =INDEX('1.2'!$1:$104,MATCH(V$3,'1.2'!$A:$A,0),MATCH(Summary!$C13,'1.2'!$1:$1,0)) -> 7861821.8 | AA13: =INDEX('1.2'!$1:$104,MATCH(Y$3,'1.2'!$A:$A,0),MATCH(Summary!$C13,'1.2'!$1:$1,0)) -> 7721916.9 | AD13: =INDEX('1.2'!$1:$104,MATCH(AB$3,'1.2'!$A:$A,0),MATCH(Summary!$C13,'1.2'!$1:$1,0)) -> 7688694.2 | AG13: =INDEX('1.2'!$1:$104,MATCH(AE$3,'1.2'!$A:$A,0),MATCH(Summary!$C13,'1.2'!$1:$1,0)) -> 7635305.1 | AJ13: =INDEX('1.2'!$1:$104,MATCH(AH$3,'1.2'!$A:$A,0),MATCH(Summary!$C13,'1.2'!$1:$1,0)) -> 7546764.4 | AM13: =INDEX('1.2'!$1:$104,MATCH(AK$3,'1.2'!$A:$A,0),MATCH(Summary!$C13,'1.2'!$1:$1,0)) -> 7551750.3 | AP13: =INDEX('1.2'!$1:$104,MATCH(AN$3,'1.2'!$A:$A,0),MATCH(Summary!$C13,'1.2'!$1:$1,0)) -> 7617255.6 | AS13: =INDEX('1.2'!$1:$104,MATCH(AQ$3,'1.2'!$A:$A,0),MATCH(Summary!$C13,'1.2'!$1:$1,0)) -> 7570020.6 | AV13: =INDEX('1.2'!$1:$104,MATCH(AT$3,'1.2'!$A:$A,0),MATCH(Summary!$C13,'1.2'!$1:$1,0)) -> 7577126.3 | AY13: =INDEX('1.2'!$1:$104,MATCH(AW$3,'1.2'!$A:$A,0),MATCH(Summary!$C13,'1.2'!$1:$1,0)) -> 7650101.4 | BB13: =INDEX('1.2'!$1:$104,MATCH(AZ$3,'1.2'!$A:$A,0),MATCH(Summary!$C13,'1.2'!$1:$1,0)) -> 7489982.2 | BE13: =INDEX('1.2'!$1:$104,MATCH(BC$3,'1.2'!$A:$A,0),MATCH(Summary!$C13,'1.2'!$1:$1,0)) -> 7627950.9 | BH13: =INDEX('1.2'!$1:$104,MATCH(BF$3,'1.2'!$A:$A,0),MATCH(Summary!$C13,'1.2'!$1:$1,0)) -> 7710340.6 | BK13: =INDEX('1.2'!$1:$104,MATCH(BI$3,'1.2'!$A:$A,0),MATCH(Summary!$C13,'1.2'!$1:$1,0)) -> 7712295.5
E14: Trade finance | G14: 貿易融資 | H14: =O14/$O$12 -> 0.040423935 | I14: =IFERROR(L14/AV14-1,"") -> 0.17121328 | J14: =J15+J16 -> 69564.467 | K14: =K15+K16 -> 352264.12 | L14: =L15+L16 -> 421828.59 | M14: =M15+M16 -> 69891.593 | N14: =N15+N16 -> 366197.6 | O14: =O15+O16 -> 436089.19 | P14: =P15+P16 -> 69479.415 | Q14: =Q15+Q16 -> 345283.6 | ... BK14: =BK15+BK16 -> 485030.24
A15: imp_exp_reexp_fromhk_hkd | B15: imp_exp_reexp_fromhk_fc | C15: imp_exp_reexp_fromhk_total | E15: To finance H.K.'s visible trade | G15: 香港貨物的出入口及轉口融資 | H15: =O15/$O$12 -> 0.024362226 | I15: =IFERROR(L15/AV15-1,"") -> 0.12876795 | J15: =INDEX('3.4.1'!$1:$104,MATCH(J$4,'3.4.1'!$A:$A,0),MATCH(Summary!$A15,'3.4.1'!$1:$1,0)) -> 56511.102 | K15: =INDEX('3.4.1'!$1:$104,MATCH(K$4,'3.4.1'!$A:$A,0),MATCH(Summary!$B15,'3.4.1'!$1:$1,0)) -> 193800.71 | L15: =INDEX('3.4.1'!$1:$104,MATCH(L$4,'3.4.1'!$A:$A,0),MATCH(Summary!$C15,'3.4.1'!$1:$1,0)) -> 250311.81 | M15: =INDEX('3.4.1'!$1:$104,MATCH(M$4,'3.4.1'!$A:$A,0),MATCH(Summary!$A15,'3.4.1'!$1:$1,0)) -> 57111.395 | N15: =INDEX('3.4.1'!$1:$104,MATCH(N$4,'3.4.1'!$A:$A,0),MATCH(Summary!$B15,'3.4.1'!$1:$1,0)) -> 205705.76 | O15: =INDEX('3.4.1'!$1:$104,MATCH(O$4,'3.4.1'!$A:$A,0),MATCH(Summary!$C15,'3.4.1'!$1:$1,0)) -> 262817.16 | P15: =INDEX('3.4.1'!$1:$104,MATCH(P$4,'3.4.1'!$A:$A,0),MATCH(Summary!$A15,'3.4.1'!$1:$1,0)) -> 57013.091 | Q15: =INDEX('3.4.1'!$1:$104,MATCH(Q$4,'3.4.1'!$A:$A,0),MATCH(Summary!$B15,'3.4.1'!$1:$1,0)) -> 186630.31 | R15: =INDEX('3.4.1'!$1:$104,MATCH(R$4,'3.4.1'!$A:$A,0),MATCH(Summary!$C15,'3.4.1'!$1:$1,0)) -> 243643.4 | S15: =INDEX('3.4.1'!$1:$104,MATCH(S$4,'3.4.1'!$A:$A,0),MATCH(Summary!$A15,'3.4.1'!$1:$1,0)) -> 59126.986 | T15: =INDEX('3.4.1'!$1:$104,MATCH(T$4,'3.4.1'!$A:$A,0),MATCH(Summary!$B15,'3.4.1'!$1:$1,0)) -> 173799.62 | U15: =INDEX('3.4.1'!$1:$104,MATCH(U$4,'3.4.1'!$A:$A,0),MATCH(Summary!$C15,'3.4.1'!$1:$1,0)) -> 232926.61 | V15: =INDEX('3.4.1'!$1:$104,MATCH(V$4,'3.4.1'!$A:$A,0),MATCH(Summary!$A15,'3.4.1'!$1:$1,0)) -> 59339.624 | W15: =INDEX('3.4.1'!$1:$104,MATCH(W$4,'3.4.1'!$A:$A,0),MATCH(Summary!$B15,'3.4.1'!$1:$1,0)) -> 182422.15 | X15: =INDEX('3.4.1'!$1:$104,MATCH(X$4,'3.4.1'!$A:$A,0),MATCH(Summary!$C15,'3.4.1'!$1:$1,0)) -> 241761.77 | Y15: =INDEX('3.4.1'!$1:$104,MATCH(Y$4,'3.4.1'!$A:$A,0),MATCH(Summary!$A15,'3.4.1'!$1:$1,0)) -> 58040.729 | Z15: =INDEX('3.4.1'!$1:$104,MATCH(Z$4,'3.4.1'!$A:$A,0),MATCH(Summary!$B15,'3.4.1'!$1:$1,0)) -> 172201.21 | AA15: =INDEX('3.4.1'!$1:$104,MATCH(AA$4,'3.4.1'!$A:$A,0),MATCH(Summary!$C15,'3.4.1'!$1:$1,0)) -> 230241.94 | AB15: =INDEX('3.4.1'!$1:$104,MATCH(AB$4,'3.4.1'!$A:$A,0),MATCH(Summary!$A15,'3.4.1'!$1:$1,0)) -> 58057.961 | AC15: =INDEX('3.4.1'!$1:$104,MATCH(AC$4,'3.4.1'!$A:$A,0),MATCH(Summary!$B15,'3.4.1'!$1:$1,0)) -> 166061.31 | AD15: =INDEX('3.4.1'!$1:$104,MATCH(AD$4,'3.4.1'!$A:$A,0),MATCH(Summary!$C15,'3.4.1'!$1:$1,0)) -> 224119.27 | AE15: =INDEX('3.4.1'!$1:$104,MATCH(AE$4,'3.4.1'!$A:$A,0),MATCH(Summary!$A15,'3.4.1'!$1:$1,0)) -> 55987.338 | AF15: =INDEX('3.4.1'!$1:$104,MATCH(AF$4,'3.4.1'!$A:$A,0),MATCH(Summary!$B15,'3.4.1'!$1:$1,0)) -> 186177.14 | AG15: =INDEX('3.4.1'!$1:$104,MATCH(AG$4,'3.4.1'!$A:$A,0),MATCH(Summary!$C15,'3.4.1'!$1:$1,0)) -> 242164.48 | AH15: =INDEX('3.4.1'!$1:$104,MATCH(AH$4,'3.4.1'!$A:$A,0),MATCH(Summary!$A15,'3.4.1'!$1:$1,0)) -> 58570.371 | AI15: =INDEX('3.4.1'!$1:$104,MATCH(AI$4,'3.4.1'!$A:$A,0),MATCH(Summary!$B15,'3.4.1'!$1:$1,0)) -> 154966.04 | AJ15: =INDEX('3.4.1'!$1:$104,MATCH(AJ$4,'3.4.1'!$A:$A,0),MATCH(Summary!$C15,'3.4.1'!$1:$1,0)) -> 213536.41 | AK15: =INDEX('3.4.1'!$1:$104,MATCH(AK$4,'3.4.1'!$A:$A,0),MATCH(Summary!$A15,'3.4.1'!$1:$1,0)) -> 57795.635 | AL15: =INDEX('3.4.1'!$1:$104,MATCH(AL$4,'3.4.1'!$A:$A,0),MATCH(Summary!$B15,'3.4.1'!$1:$1,0)) -> 153915.67 | AM15: =INDEX('3.4.1'!$1:$104,MATCH(AM$4,'3.4.1'!$A:$A,0),MATCH(Summary!$C15,'3.4.1'!$1:$1,0)) -> 211711.3 | AN15: =INDEX('3.4.1'!$1:$104,MATCH(AN$4,'3.4.1'!$A:$A,0),MATCH(Summary!$A15,'3.4.1'!$1:$1,0)) -> 61251.15 | AO15: =INDEX('3.4.1'!$1:$104,MATCH(AO$4,'3.4.1'!$A:$A,0),MATCH(Summary!$B15,'3.4.1'!$1:$1,0)) -> 166019.3 | AP15: =INDEX('3.4.1'!$1:$104,MATCH(AP$4,'3.4.1'!$A:$A,0),MATCH(Summary!$C15,'3.4.1'!$1:$1,0)) -> 227270.45 | AQ15: =INDEX('3.4.1'!$1:$104,MATCH(AQ$4,'3.4.1'!$A:$A,0),MATCH(Summary!$A15,'3.4.1'!$1:$1,0)) -> 64970.17 | AR15: =INDEX('3.4.1'!$1:$104,MATCH(AR$4,'3.4.1'!$A:$A,0),MATCH(Summary!$B15,'3.4.1'!$1:$1,0)) -> 148628.36 | AS15: =INDEX('3.4.1'!$1:$104,MATCH(AS$4,'3.4.1'!$A:$A,0),MATCH(Summary!$C15,'3.4.1'!$1:$1,0)) -> 213598.53 | AT15: =INDEX('3.4.1'!$1:$104,MATCH(AT$4,'3.4.1'!$A:$A,0),MATCH(Summary!$A15,'3.4.1'!$1:$1,0)) -> 65997.963 | AU15: =INDEX('3.4.1'!$1:$104,MATCH(AU$4,'3.4.1'!$A:$A,0),MATCH(Summary!$B15,'3.4.1'!$1:$1,0)) -> 155758.7 | AV15: =INDEX('3.4.1'!$1:$104,MATCH(AV$4,'3.4.1'!$A:$A,0),MATCH(Summary!$C15,'3.4.1'!$1:$1,0)) -> 221756.66 | AW15: =INDEX('3.4.1'!$1:$104,MATCH(AW$4,'3.4.1'!$A:$A,0),MATCH(Summary!$A15,'3.4.1'!$1:$1,0)) -> 64711.344 | AX15: =INDEX('3.4.1'!$1:$104,MATCH(AX$4,'3.4.1'!$A:$A,0),MATCH(Summary!$B15,'3.4.1'!$1:$1,0)) -> 159163.17 | AY15: =INDEX('3.4.1'!$1:$104,MATCH(AY$4,'3.4.1'!$A:$A,0),MATCH(Summary!$C15,'3.4.1'!$1:$1,0)) -> 223874.52 | AZ15: =INDEX('3.4.1'!$1:$104,MATCH(AZ$4,'3.4.1'!$A:$A,0),MATCH(Summary!$A15,'3.4.1'!$1:$1,0)) -> 60444.762 | BA15: =INDEX('3.4.1'!$1:$104,MATCH(BA$4,'3.4.1'!$A:$A,0),MATCH(Summary!$B15,'3.4.1'!$1:$1,0)) -> 171303.02 | BB15: =INDEX('3.4.1'!$1:$104,MATCH(BB$4,'3.4.1'!$A:$A,0),MATCH(Summary!$C15,'3.4.1'!$1:$1,0)) -> 231747.78 | BC15: =INDEX('3.4.1'!$1:$104,MATCH(BC$4,'3.4.1'!$A:$A,0),MATCH(Summary!$A15,'3.4.1'!$1:$1,0)) -> 55411.698 | BD15: =INDEX('3.4.1'!$1:$104,MATCH(BD$4,'3.4.1'!$A:$A,0),MATCH(Summary!$B15,'3.4.1'!$1:$1,0)) -> 149701.38 | BE15: =INDEX('3.4.1'!$1:$104,MATCH(BE$4,'3.4.1'!$A:$A,0),MATCH(Summary!$C15,'3.4.1'!$1:$1,0)) -> 205113.08 | BF15: =INDEX('3.4.1'!$1:$104,MATCH(BF$4,'3.4.1'!$A:$A,0),MATCH(Summary!$A15,'3.4.1'!$1:$1,0)) -> 58068.637 | BG15: =INDEX('3.4.1'!$1:$104,MATCH(BG$4,'3.4.1'!$A:$A,0),MATCH(Summary!$B15,'3.4.1'!$1:$1,0)) -> 189414.86 | BH15: =INDEX('3.4.1'!$1:$104,MATCH(BH$4,'3.4.1'!$A:$A,0),MATCH(Summary!$C15,'3.4.1'!$1:$1,0)) -> 247483.5 | BI15: =INDEX('3.4.1'!$1:$104,MATCH(BI$4,'3.4.1'!$A:$A,0),MATCH(Summary!$A15,'3.4.1'!$1:$1,0)) -> 55055.337 | BJ15: =INDEX('3.4.1'!$1:$104,MATCH(BJ$4,'3.4.1'!$A:$A,0),MATCH(Summary!$B15,'3.4.1'!$1:$1,0)) -> 236330.96 | BK15: =INDEX('3.4.1'!$1:$104,MATCH(BK$4,'3.4.1'!$A:$A,0),MATCH(Summary!$C15,'3.4.1'!$1:$1,0)) -> 291386.29
A16: merch_trade_nonhk_hkd | B16: merch_trade_nonhk_fc | C16: merch_trade_nonhk_total | E16: To finance merchandising trade not touching H.K. | G16: 香港境外的商品貿易融資 | H16: =O16/$O$12 -> 0.016061708 | I16: =IFERROR(L16/AV16-1,"") -> 0.23921942 | J16: =INDEX('3.4.1'!$1:$104,MATCH(J$4,'3.4.1'!$A:$A,0),MATCH(Summary!$A16,'3.4.1'!$1:$1,0)) -> 13053.365 | K16: =INDEX('3.4.1'!$1:$104,MATCH(K$4,'3.4.1'!$A:$A,0),MATCH(Summary!$B16,'3.4.1'!$1:$1,0)) -> 158463.42 | L16: =INDEX('3.4.1'!$1:$104,MATCH(L$4,'3.4.1'!$A:$A,0),MATCH(Summary!$C16,'3.4.1'!$1:$1,0)) -> 171516.78 | M16: =INDEX('3.4.1'!$1:$104,MATCH(M$4,'3.4.1'!$A:$A,0),MATCH(Summary!$A16,'3.4.1'!$1:$1,0)) -> 12780.198 | N16: =INDEX('3.4.1'!$1:$104,MATCH(N$4,'3.4.1'!$A:$A,0),MATCH(Summary!$B16,'3.4.1'!$1:$1,0)) -> 160491.84 | O16: =INDEX('3.4.1'!$1:$104,MATCH(O$4,'3.4.1'!$A:$A,0),MATCH(Summary!$C16,'3.4.1'!$1:$1,0)) -> 173272.03 | P16: =INDEX('3.4.1'!$1:$104,MATCH(P$4,'3.4.1'!$A:$A,0),MATCH(Summary!$A16,'3.4.1'!$1:$1,0)) -> 12466.324 | Q16: =INDEX('3.4.1'!$1:$104,MATCH(Q$4,'3.4.1'!$A:$A,0),MATCH(Summary!$B16,'3.4.1'!$1:$1,0)) -> 158653.3 | R16: =INDEX('3.4.1'!$1:$104,MATCH(R$4,'3.4.1'!$A:$A,0),MATCH(Summary!$C16,'3.4.1'!$1:$1,0)) -> 171119.62 | S16: =INDEX('3.4.1'!$1:$104,MATCH(S$4,'3.4.1'!$A:$A,0),MATCH(Summary!$A16,'3.4.1'!$1:$1,0)) -> 11984.01 | T16: =INDEX('3.4.1'!$1:$104,MATCH(T$4,'3.4.1'!$A:$A,0),MATCH(Summary!$B16,'3.4.1'!$1:$1,0)) -> 160556.36 | U16: =INDEX('3.4.1'!$1:$104,MATCH(U$4,'3.4.1'!$A:$A,0),MATCH(Summary!$C16,'3.4.1'!$1:$1,0)) -> 172540.37 | V16: =INDEX('3.4.1'!$1:$104,MATCH(V$4,'3.4.1'!$A:$A,0),MATCH(Summary!$A16,'3.4.1'!$1:$1,0)) -> 11972.022 | W16: =INDEX('3.4.1'!$1:$104,MATCH(W$4,'3.4.1'!$A:$A,0),MATCH(Summary!$B16,'3.4.1'!$1:$1,0)) -> 167767.32 | X16: =INDEX('3.4.1'!$1:$104,MATCH(X$4,'3.4.1'!$A:$A,0),MATCH(Summary!$C16,'3.4.1'!$1:$1,0)) -> 179739.34 | Y16: =INDEX('3.4.1'!$1:$104,MATCH(Y$4,'3.4.1'!$A:$A,0),MATCH(Summary!$A16,'3.4.1'!$1:$1,0)) -> 13041.727 | Z16: =INDEX('3.4.1'!$1:$104,MATCH(Z$4,'3.4.1'!$A:$A,0),MATCH(Summary!$B16,'3.4.1'!$1:$1,0)) -> 126050.45 | AA16: =INDEX('3.4.1'!$1:$104,MATCH(AA$4,'3.4.1'!$A:$A,0),MATCH(Summary!$C16,'3.4.1'!$1:$1,0)) -> 139092.18 | AB16: =INDEX('3.4.1'!$1:$104,MATCH(AB$4,'3.4.1'!$A:$A,0),MATCH(Summary!$A16,'3.4.1'!$1:$1,0)) -> 13924.763 | AC16: =INDEX('3.4.1'!$1:$104,MATCH(AC$4,'3.4.1'!$A:$A,0),MATCH(Summary!$B16,'3.4.1'!$1:$1,0)) -> 121553.74 | AD16: =INDEX('3.4.1'!$1:$104,MATCH(AD$4,'3.4.1'!$A:$A,0),MATCH(Summary!$C16,'3.4.1'!$1:$1,0)) -> 135478.5 | AE16: =INDEX('3.4.1'!$1:$104,MATCH(AE$4,'3.4.1'!$A:$A,0),MATCH(Summary!$A16,'3.4.1'!$1:$1,0)) -> 14415.68 | AF16: =INDEX('3.4.1'!$1:$104,MATCH(AF$4,'3.4.1'!$A:$A,0),MATCH(Summary!$B16,'3.4.1'!$1:$1,0)) -> 134200.05 | AG16: =INDEX('3.4.1'!$1:$104,MATCH(AG$4,'3.4.1'!$A:$A,0),MATCH(Summary!$C16,'3.4.1'!$1:$1,0)) -> 148615.73 | AH16: =INDEX('3.4.1'!$1:$104,MATCH(AH$4,'3.4.1'!$A:$A,0),MATCH(Summary!$A16,'3.4.1'!$1:$1,0)) -> 13974.943 | AI16: =INDEX('3.4.1'!$1:$104,MATCH(AI$4,'3.4.1'!$A:$A,0),MATCH(Summary!$B16,'3.4.1'!$1:$1,0)) -> 116204.61 | AJ16: =INDEX('3.4.1'!$1:$104,MATCH(AJ$4,'3.4.1'!$A:$A,0),MATCH(Summary!$C16,'3.4.1'!$1:$1,0)) -> 130179.55 | AK16: =INDEX('3.4.1'!$1:$104,MATCH(AK$4,'3.4.1'!$A:$A,0),MATCH(Summary!$A16,'3.4.1'!$1:$1,0)) -> 14483.044 | AL16: =INDEX('3.4.1'!$1:$104,MATCH(AL$4,'3.4.1'!$A:$A,0),MATCH(Summary!$B16,'3.4.1'!$1:$1,0)) -> 113621.16 | AM16: =INDEX('3.4.1'!$1:$104,MATCH(AM$4,'3.4.1'!$A:$A,0),MATCH(Summary!$C16,'3.4.1'!$1:$1,0)) -> 128104.21 | AN16: =INDEX('3.4.1'!$1:$104,MATCH(AN$4,'3.4.1'!$A:$A,0),MATCH(Summary!$A16,'3.4.1'!$1:$1,0)) -> 15221.531 | AO16: =INDEX('3.4.1'!$1:$104,MATCH(AO$4,'3.4.1'!$A:$A,0),MATCH(Summary!$B16,'3.4.1'!$1:$1,0)) -> 131263.17 | AP16: =INDEX('3.4.1'!$1:$104,MATCH(AP$4,'3.4.1'!$A:$A,0),MATCH(Summary!$C16,'3.4.1'!$1:$1,0)) -> 146484.71 | AQ16: =INDEX('3.4.1'!$1:$104,MATCH(AQ$4,'3.4.1'!$A:$A,0),MATCH(Summary!$A16,'3.4.1'!$1:$1,0)) -> 15025.371 | AR16: =INDEX('3.4.1'!$1:$104,MATCH(AR$4,'3.4.1'!$A:$A,0),MATCH(Summary!$B16,'3.4.1'!$1:$1,0)) -> 121429.41 | AS16: =INDEX('3.4.1'!$1:$104,MATCH(AS$4,'3.4.1'!$A:$A,0),MATCH(Summary!$C16,'3.4.1'!$1:$1,0)) -> 136454.78 | AT16: =INDEX('3.4.1'!$1:$104,MATCH(AT$4,'3.4.1'!$A:$A,0),MATCH(Summary!$A16,'3.4.1'!$1:$1,0)) -> 14073.304 | AU16: =INDEX('3.4.1'!$1:$104,MATCH(AU$4,'3.4.1'!$A:$A,0),MATCH(Summary!$B16,'3.4.1'!$1:$1,0)) -> 124333.81 | AV16: =INDEX('3.4.1'!$1:$104,MATCH(AV$4,'3.4.1'!$A:$A,0),MATCH(Summary!$C16,'3.4.1'!$1:$1,0)) -> 138407.11 | AW16: =INDEX('3.4.1'!$1:$104,MATCH(AW$4,'3.4.1'!$A:$A,0),MATCH(Summary!$A16,'3.4.1'!$1:$1,0)) -> 13226.637 | AX16: =INDEX('3.4.1'!$1:$104,MATCH(AX$4,'3.4.1'!$A:$A,0),MATCH(Summary!$B16,'3.4.1'!$1:$1,0)) -> 139122.73 | AY16: =INDEX('3.4.1'!$1:$104,MATCH(AY$4,'3.4.1'!$A:$A,0),MATCH(Summary!$C16,'3.4.1'!$1:$1,0)) -> 152349.36 | AZ16: =INDEX('3.4.1'!$1:$104,MATCH(AZ$4,'3.4.1'!$A:$A,0),MATCH(Summary!$A16,'3.4.1'!$1:$1,0)) -> 10821.36 | BA16: =INDEX('3.4.1'!$1:$104,MATCH(BA$4,'3.4.1'!$A:$A,0),MATCH(Summary!$B16,'3.4.1'!$1:$1,0)) -> 138673.73 | BB16: =INDEX('3.4.1'!$1:$104,MATCH(BB$4,'3.4.1'!$A:$A,0),MATCH(Summary!$C16,'3.4.1'!$1:$1,0)) -> 149495.09 | BC16: =INDEX('3.4.1'!$1:$104,MATCH(BC$4,'3.4.1'!$A:$A,0),MATCH(Summary!$A16,'3.4.1'!$1:$1,0)) -> 10577.562 | BD16: =INDEX('3.4.1'!$1:$104,MATCH(BD$4,'3.4.1'!$A:$A,0),MATCH(Summary!$B16,'3.4.1'!$1:$1,0)) -> 148935.23 | BE16: =INDEX('3.4.1'!$1:$104,MATCH(BE$4,'3.4.1'!$A:$A,0),MATCH(Summary!$C16,'3.4.1'!$1:$1,0)) -> 159512.79 | BF16: =INDEX('3.4.1'!$1:$104,MATCH(BF$4,'3.4.1'!$A:$A,0),MATCH(Summary!$A16,'3.4.1'!$1:$1,0)) -> 12622.642 | BG16: =INDEX('3.4.1'!$1:$104,MATCH(BG$4,'3.4.1'!$A:$A,0),MATCH(Summary!$B16,'3.4.1'!$1:$1,0)) -> 159585.63 | BH16: =INDEX('3.4.1'!$1:$104,MATCH(BH$4,'3.4.1'!$A:$A,0),MATCH(Summary!$C16,'3.4.1'!$1:$1,0)) -> 172208.27 | BI16: =INDEX('3.4.1'!$1:$104,MATCH(BI$4,'3.4.1'!$A:$A,0),MATCH(Summary!$A16,'3.4.1'!$1:$1,0)) -> 13888.557 | BJ16: =INDEX('3.4.1'!$1:$104,MATCH(BJ$4,'3.4.1'!$A:$A,0),MATCH(Summary!$B16,'3.4.1'!$1:$1,0)) -> 179755.39 | BK16: =INDEX('3.4.1'!$1:$104,MATCH(BK$4,'3.4.1'!$A:$A,0),MATCH(Summary!$C16,'3.4.1'!$1:$1,0)) -> 193643.95
A17: loans_inhk_hkd | B17: loans_inhk_fc | C17: loans_inhk_total | E17: Other loans for use in H.K(1) | H17: =O17/$O$12 -> 0.70997683 | I17: =IFERROR(L17/AV17-1,"") -> 0.059869499 | J17: =INDEX('3.4.1'!$1:$104,MATCH(J$4,'3.4.1'!$A:$A,0),MATCH(Summary!$A17,'3.4.1'!$1:$1,0)) -> 5580470.7 | K17: =INDEX('3.4.1'!$1:$104,MATCH(K$4,'3.4.1'!$A:$A,0),MATCH(Summary!$B17,'3.4.1'!$1:$1,0)) -> 2068567.8 | L17: =INDEX('3.4.1'!$1:$104,MATCH(L$4,'3.4.1'!$A:$A,0),MATCH(Summary!$C17,'3.4.1'!$1:$1,0)) -> 7649038.4 | M17: =INDEX('3.4.1'!$1:$104,MATCH(M$4,'3.4.1'!$A:$A,0),MATCH(Summary!$A17,'3.4.1'!$1:$1,0)) -> 5589675.4 | N17: =INDEX('3.4.1'!$1:$104,MATCH(N$4,'3.4.1'!$A:$A,0),MATCH(Summary!$B17,'3.4.1'!$1:$1,0)) -> 2069480.6 | O17: =INDEX('3.4.1'!$1:$104,MATCH(O$4,'3.4.1'!$A:$A,0),MATCH(Summary!$C17,'3.4.1'!$1:$1,0)) -> 7659156 | P17: =INDEX('3.4.1'!$1:$104,MATCH(P$4,'3.4.1'!$A:$A,0),MATCH(Summary!$A17,'3.4.1'!$1:$1,0)) -> 5488152.2 | Q17: =INDEX('3.4.1'!$1:$104,MATCH(Q$4,'3.4.1'!$A:$A,0),MATCH(Summary!$B17,'3.4.1'!$1:$1,0)) -> 2078291 | R17: =INDEX('3.4.1'!$1:$104,MATCH(R$4,'3.4.1'!$A:$A,0),MATCH(Summary!$C17,'3.4.1'!$1:$1,0)) -> 7566443.3 | S17: =INDEX('3.4.1'!$1:$104,MATCH(S$4,'3.4.1'!$A:$A,0),MATCH(Summary!$A17,'3.4.1'!$1:$1,0)) -> 5472828.6 | T17: =INDEX('3.4.1'!$1:$104,MATCH(T$4,'3.4.1'!$A:$A,0),MATCH(Summary!$B17,'3.4.1'!$1:$1,0)) -> 1990899.9 | U17: =INDEX('3.4.1'!$1:$104,MATCH(U$4,'3.4.1'!$A:$A,0),MATCH(Summary!$C17,'3.4.1'!$1:$1,0)) -> 7463728.5 | V17: =INDEX('3.4.1'!$1:$104,MATCH(V$4,'3.4.1'!$A:$A,0),MATCH(Summary!$A17,'3.4.1'!$1:$1,0)) -> 5461882.5 | W17: =INDEX('3.4.1'!$1:$104,MATCH(W$4,'3.4.1'!$A:$A,0),MATCH(Summary!$B17,'3.4.1'!$1:$1,0)) -> 1978438.2 | X17: =INDEX('3.4.1'!$1:$104,MATCH(X$4,'3.4.1'!$A:$A,0),MATCH(Summary!$C17,'3.4.1'!$1:$1,0)) -> 7440320.7 | Y17: =INDEX('3.4.1'!$1:$104,MATCH(Y$4,'3.4.1'!$A:$A,0),MATCH(Summary!$A17,'3.4.1'!$1:$1,0)) -> 5431952.5 | Z17: =INDEX('3.4.1'!$1:$104,MATCH(Z$4,'3.4.1'!$A:$A,0),MATCH(Summary!$B17,'3.4.1'!$1:$1,0)) -> 1920630.3 | AA17: =INDEX('3.4.1'!$1:$104,MATCH(AA$4,'3.4.1'!$A:$A,0),MATCH(Summary!$C17,'3.4.1'!$1:$1,0)) -> 7352582.8 | AB17: =INDEX('3.4.1'!$1:$104,MATCH(AB$4,'3.4.1'!$A:$A,0),MATCH(Summary!$A17,'3.4.1'!$1:$1,0)) -> 5430504.2 | AC17: =INDEX('3.4.1'!$1:$104,MATCH(AC$4,'3.4.1'!$A:$A,0),MATCH(Summary!$B17,'3.4.1'!$1:$1,0)) -> 1898592.3 | AD17: =INDEX('3.4.1'!$1:$104,MATCH(AD$4,'3.4.1'!$A:$A,0),MATCH(Summary!$C17,'3.4.1'!$1:$1,0)) -> 7329096.5 | AE17: =INDEX('3.4.1'!$1:$104,MATCH(AE$4,'3.4.1'!$A:$A,0),MATCH(Summary!$A17,'3.4.1'!$1:$1,0)) -> 5408698.2 | AF17: =INDEX('3.4.1'!$1:$104,MATCH(AF$4,'3.4.1'!$A:$A,0),MATCH(Summary!$B17,'3.4.1'!$1:$1,0)) -> 1835826.7 | AG17: =INDEX('3.4.1'!$1:$104,MATCH(AG$4,'3.4.1'!$A:$A,0),MATCH(Summary!$C17,'3.4.1'!$1:$1,0)) -> 7244524.9 | AH17: =INDEX('3.4.1'!$1:$104,MATCH(AH$4,'3.4.1'!$A:$A,0),MATCH(Summary!$A17,'3.4.1'!$1:$1,0)) -> 5391482.5 | AI17: =INDEX('3.4.1'!$1:$104,MATCH(AI$4,'3.4.1'!$A:$A,0),MATCH(Summary!$B17,'3.4.1'!$1:$1,0)) -> 1811566 | AJ17: =INDEX('3.4.1'!$1:$104,MATCH(AJ$4,'3.4.1'!$A:$A,0),MATCH(Summary!$C17,'3.4.1'!$1:$1,0)) -> 7203048.4 | AK17: =INDEX('3.4.1'!$1:$104,MATCH(AK$4,'3.4.1'!$A:$A,0),MATCH(Summary!$A17,'3.4.1'!$1:$1,0)) -> 5414751.6 | AL17: =INDEX('3.4.1'!$1:$104,MATCH(AL$4,'3.4.1'!$A:$A,0),MATCH(Summary!$B17,'3.4.1'!$1:$1,0)) -> 1797183.2 | AM17: =INDEX('3.4.1'!$1:$104,MATCH(AM$4,'3.4.1'!$A:$A,0),MATCH(Summary!$C17,'3.4.1'!$1:$1,0)) -> 7211934.8 | AN17: =INDEX('3.4.1'!$1:$104,MATCH(AN$4,'3.4.1'!$A:$A,0),MATCH(Summary!$A17,'3.4.1'!$1:$1,0)) -> 5452570 | AO17: =INDEX('3.4.1'!$1:$104,MATCH(AO$4,'3.4.1'!$A:$A,0),MATCH(Summary!$B17,'3.4.1'!$1:$1,0)) -> 1790930.5 | AP17: =INDEX('3.4.1'!$1:$104,MATCH(AP$4,'3.4.1'!$A:$A,0),MATCH(Summary!$C17,'3.4.1'!$1:$1,0)) -> 7243500.5 | AQ17: =INDEX('3.4.1'!$1:$104,MATCH(AQ$4,'3.4.1'!$A:$A,0),MATCH(Summary!$A17,'3.4.1'!$1:$1,0)) -> 5433198.2 | AR17: =INDEX('3.4.1'!$1:$104,MATCH(AR$4,'3.4.1'!$A:$A,0),MATCH(Summary!$B17,'3.4.1'!$1:$1,0)) -> 1786769.1 | AS17: =INDEX('3.4.1'!$1:$104,MATCH(AS$4,'3.4.1'!$A:$A,0),MATCH(Summary!$C17,'3.4.1'!$1:$1,0)) -> 7219967.3 | AT17: =INDEX('3.4.1'!$1:$104,MATCH(AT$4,'3.4.1'!$A:$A,0),MATCH(Summary!$A17,'3.4.1'!$1:$1,0)) -> 5429428.7 | AU17: =INDEX('3.4.1'!$1:$104,MATCH(AU$4,'3.4.1'!$A:$A,0),MATCH(Summary!$B17,'3.4.1'!$1:$1,0)) -> 1787533.8 | AV17: =INDEX('3.4.1'!$1:$104,MATCH(AV$4,'3.4.1'!$A:$A,0),MATCH(Summary!$C17,'3.4.1'!$1:$1,0)) -> 7216962.5 | AW17: =INDEX('3.4.1'!$1:$104,MATCH(AW$4,'3.4.1'!$A:$A,0),MATCH(Summary!$A17,'3.4.1'!$1:$1,0)) -> 5464932.4 | AX17: =INDEX('3.4.1'!$1:$104,MATCH(AX$4,'3.4.1'!$A:$A,0),MATCH(Summary!$B17,'3.4.1'!$1:$1,0)) -> 1808945.2 | AY17: =INDEX('3.4.1'!$1:$104,MATCH(AY$4,'3.4.1'!$A:$A,0),MATCH(Summary!$C17,'3.4.1'!$1:$1,0)) -> 7273877.6 | AZ17: =INDEX('3.4.1'!$1:$104,MATCH(AZ$4,'3.4.1'!$A:$A,0),MATCH(Summary!$A17,'3.4.1'!$1:$1,0)) -> 5442170.1 | BA17: =INDEX('3.4.1'!$1:$104,MATCH(BA$4,'3.4.1'!$A:$A,0),MATCH(Summary!$B17,'3.4.1'!$1:$1,0)) -> 1666569.3 | BB17: =INDEX('3.4.1'!$1:$104,MATCH(BB$4,'3.4.1'!$A:$A,0),MATCH(Summary!$C17,'3.4.1'!$1:$1,0)) -> 7108739.3 | BC17: =INDEX('3.4.1'!$1:$104,MATCH(BC$4,'3.4.1'!$A:$A,0),MATCH(Summary!$A17,'3.4.1'!$1:$1,0)) -> 5636493.2 | BD17: =INDEX('3.4.1'!$1:$104,MATCH(BD$4,'3.4.1'!$A:$A,0),MATCH(Summary!$B17,'3.4.1'!$1:$1,0)) -> 1626831.8 | BE17: =INDEX('3.4.1'!$1:$104,MATCH(BE$4,'3.4.1'!$A:$A,0),MATCH(Summary!$C17,'3.4.1'!$1:$1,0)) -> 7263325 | BF17: =INDEX('3.4.1'!$1:$104,MATCH(BF$4,'3.4.1'!$A:$A,0),MATCH(Summary!$A17,'3.4.1'!$1:$1,0)) -> 5648487.7 | BG17: =INDEX('3.4.1'!$1:$104,MATCH(BG$4,'3.4.1'!$A:$A,0),MATCH(Summary!$B17,'3.4.1'!$1:$1,0)) -> 1642161.1 | BH17: =INDEX('3.4.1'!$1:$104,MATCH(BH$4,'3.4.1'!$A:$A,0),MATCH(Summary!$C17,'3.4.1'!$1:$1,0)) -> 7290648.8 | BI17: =INDEX('3.4.1'!$1:$104,MATCH(BI$4,'3.4.1'!$A:$A,0),MATCH(Summary!$A17,'3.4.1'!$1:$1,0)) -> 5468186.2 | BJ17: =INDEX('3.4.1'!$1:$104,MATCH(BJ$4,'3.4.1'!$A:$A,0),MATCH(Summary!$B17,'3.4.1'!$1:$1,0)) -> 1759079.1 | BK17: =INDEX('3.4.1'!$1:$104,MATCH(BK$4,'3.4.1'!$A:$A,0),MATCH(Summary!$C17,'3.4.1'!$1:$1,0)) -> 7227265.3
C18: mfg | F18: Manufacturing | G18: 製造業 | H18: =O18/$O$12 -> 0.03370759 | I18: =IFERROR(L18/AV18-1,"") | L18: =_xlfn.IFNA(INDEX('3.5.1'!$1:$104,MATCH(L$4,'3.5.1'!$A:$A,0),MATCH(Summary!$C18,'3.5.1'!$1:$1,0)),"") | O18: =_xlfn.IFNA(INDEX('3.5.1'!$1:$104,MATCH(O$4,'3.5.1'!$A:$A,0),MATCH(Summary!$C18,'3.5.1'!$1:$1,0)),"") -> 363633.97 | R18: =_xlfn.IFNA(INDEX('3.5.1'!$1:$104,MATCH(R$4,'3.5.1'!$A:$A,0),MATCH(Summary!$C18,'3.5.1'!$1:$1,0)),"") | U18: =_xlfn.IFNA(INDEX('3.5.1'!$1:$104,MATCH(U$4,'3.5.1'!$A:$A,0),MATCH(Summary!$C18,'3.5.1'!$1:$1,0)),"") | X18: =_xlfn.IFNA(INDEX('3.5.1'!$1:$104,MATCH(X$4,'3.5.1'!$A:$A,0),MATCH(Summary!$C18,'3.5.1'!$1:$1,0)),"") -> 328188.24 | AA18: =_xlfn.IFNA(INDEX('3.5.1'!$1:$104,MATCH(AA$4,'3.5.1'!$A:$A,0),MATCH(Summary!$C18,'3.5.1'!$1:$1,0)),"") | AD18: =_xlfn.IFNA(INDEX('3.5.1'!$1:$104,MATCH(AD$4,'3.5.1'!$A:$A,0),MATCH(Summary!$C18,'3.5.1'!$1:$1,0)),"") | AG18: =_xlfn.IFNA(INDEX('3.5.1'!$1:$104,MATCH(AG$4,'3.5.1'!$A:$A,0),MATCH(Summary!$C18,'3.5.1'!$1:$1,0)),"") -> 306596.64 | AJ18: =_xlfn.IFNA(INDEX('3.5.1'!$1:$104,MATCH(AJ$4,'3.5.1'!$A:$A,0),MATCH(Summary!$C18,'3.5.1'!$1:$1,0)),"") | AM18: =_xlfn.IFNA(INDEX('3.5.1'!$1:$104,MATCH(AM$4,'3.5.1'!$A:$A,0),MATCH(Summary!$C18,'3.5.1'!$1:$1,0)),"") | AP18: =_xlfn.IFNA(INDEX('3.5.1'!$1:$104,MATCH(AP$4,'3.5.1'!$A:$A,0),MATCH(Summary!$C18,'3.5.1'!$1:$1,0)),"") -> 322774.75 | AS18: =_xlfn.IFNA(INDEX('3.5.1'!$1:$104,MATCH(AS$4,'3.5.1'!$A:$A,0),MATCH(Summary!$C18,'3.5.1'!$1:$1,0)),"") | AV18: =_xlfn.IFNA(INDEX('3.5.1'!$1:$104,MATCH(AV$4,'3.5.1'!$A:$A,0),MATCH(Summary!$C18,'3.5.1'!$1:$1,0)),"") | AY18: =_xlfn.IFNA(INDEX('3.5.1'!$1:$104,MATCH(AY$4,'3.5.1'!$A:$A,0),MATCH(Summary!$C18,'3.5.1'!$1:$1,0)),"") -> 324870.77 | BB18: =_xlfn.IFNA(INDEX('3.5.1'!$1:$104,MATCH(BB$4,'3.5.1'!$A:$A,0),MATCH(Summary!$C18,'3.5.1'!$1:$1,0)),"") -> 295132.54 | BE18: =_xlfn.IFNA(INDEX('3.5.1'!$1:$104,MATCH(BE$4,'3.5.1'!$A:$A,0),MATCH(Summary!$C18,'3.5.1'!$1:$1,0)),"") | BH18: =_xlfn.IFNA(INDEX('3.5.1'!$1:$104,MATCH(BH$4,'3.5.1'!$A:$A,0),MATCH(Summary!$C18,'3.5.1'!$1:$1,0)),"") | BK18: =_xlfn.IFNA(INDEX('3.5.1'!$1:$104,MATCH(BK$4,'3.5.1'!$A:$A,0),MATCH(Summary!$C18,'3.5.1'!$1:$1,0)),"")
C19: mfg_textiles | F19: Textiles | G19: 紡織 | H19: =O19/$O$12 -> 0.00098331336 | I19: =IFERROR(L19/AV19-1,"") | L19: =_xlfn.IFNA(INDEX('3.5.1'!$1:$104,MATCH(L$4,'3.5.1'!$A:$A,0),MATCH(Summary!$C19,'3.5.1'!$1:$1,0)),"") | O19: =_xlfn.IFNA(INDEX('3.5.1'!$1:$104,MATCH(O$4,'3.5.1'!$A:$A,0),MATCH(Summary!$C19,'3.5.1'!$1:$1,0)),"") -> 10607.882 | R19: =_xlfn.IFNA(INDEX('3.5.1'!$1:$104,MATCH(R$4,'3.5.1'!$A:$A,0),MATCH(Summary!$C19,'3.5.1'!$1:$1,0)),"") | U19: =_xlfn.IFNA(INDEX('3.5.1'!$1:$104,MATCH(U$4,'3.5.1'!$A:$A,0),MATCH(Summary!$C19,'3.5.1'!$1:$1,0)),"") | X19: =_xlfn.IFNA(INDEX('3.5.1'!$1:$104,MATCH(X$4,'3.5.1'!$A:$A,0),MATCH(Summary!$C19,'3.5.1'!$1:$1,0)),"") -> 10407.843 | AA19: =_xlfn.IFNA(INDEX('3.5.1'!$1:$104,MATCH(AA$4,'3.5.1'!$A:$A,0),MATCH(Summary!$C19,'3.5.1'!$1:$1,0)),"") | AD19: =_xlfn.IFNA(INDEX('3.5.1'!$1:$104,MATCH(AD$4,'3.5.1'!$A:$A,0),MATCH(Summary!$C19,'3.5.1'!$1:$1,0)),"") | AG19: =_xlfn.IFNA(INDEX('3.5.1'!$1:$104,MATCH(AG$4,'3.5.1'!$A:$A,0),MATCH(Summary!$C19,'3.5.1'!$1:$1,0)),"") -> 10579.608 | AJ19: =_xlfn.IFNA(INDEX('3.5.1'!$1:$104,MATCH(AJ$4,'3.5.1'!$A:$A,0),MATCH(Summary!$C19,'3.5.1'!$1:$1,0)),"") | AM19: =_xlfn.IFNA(INDEX('3.5.1'!$1:$104,MATCH(AM$4,'3.5.1'!$A:$A,0),MATCH(Summary!$C19,'3.5.1'!$1:$1,0)),"") | AP19: =_xlfn.IFNA(INDEX('3.5.1'!$1:$104,MATCH(AP$4,'3.5.1'!$A:$A,0),MATCH(Summary!$C19,'3.5.1'!$1:$1,0)),"") -> 10888.719 | AS19: =_xlfn.IFNA(INDEX('3.5.1'!$1:$104,MATCH(AS$4,'3.5.1'!$A:$A,0),MATCH(Summary!$C19,'3.5.1'!$1:$1,0)),"") | AV19: =_xlfn.IFNA(INDEX('3.5.1'!$1:$104,MATCH(AV$4,'3.5.1'!$A:$A,0),MATCH(Summary!$C19,'3.5.1'!$1:$1,0)),"") | AY19: =_xlfn.IFNA(INDEX('3.5.1'!$1:$104,MATCH(AY$4,'3.5.1'!$A:$A,0),MATCH(Summary!$C19,'3.5.1'!$1:$1,0)),"") -> 10105.352 | BB19: =_xlfn.IFNA(INDEX('3.5.1'!$1:$104,MATCH(BB$4,'3.5.1'!$A:$A,0),MATCH(Summary!$C19,'3.5.1'!$1:$1,0)),"") -> 12543.956 | BE19: =_xlfn.IFNA(INDEX('3.5.1'!$1:$104,MATCH(BE$4,'3.5.1'!$A:$A,0),MATCH(Summary!$C19,'3.5.1'!$1:$1,0)),"") | BH19: =_xlfn.IFNA(INDEX('3.5.1'!$1:$104,MATCH(BH$4,'3.5.1'!$A:$A,0),MATCH(Summary!$C19,'3.5.1'!$1:$1,0)),"") | BK19: =_xlfn.IFNA(INDEX('3.5.1'!$1:$104,MATCH(BK$4,'3.5.1'!$A:$A,0),MATCH(Summary!$C19,'3.5.1'!$1:$1,0)),"")
C20: mfg_footwear | F20: Footwear and wearing apparel | G20: 鞋類及衣飾 | H20: =O20/$O$12 -> 0.0029058091 | I20: =IFERROR(L20/AV20-1,"") | L20: =_xlfn.IFNA(INDEX('3.5.1'!$1:$104,MATCH(L$4,'3.5.1'!$A:$A,0),MATCH(Summary!$C20,'3.5.1'!$1:$1,0)),"") | O20: =_xlfn.IFNA(INDEX('3.5.1'!$1:$104,MATCH(O$4,'3.5.1'!$A:$A,0),MATCH(Summary!$C20,'3.5.1'!$1:$1,0)),"") -> 31347.566 | R20: =_xlfn.IFNA(INDEX('3.5.1'!$1:$104,MATCH(R$4,'3.5.1'!$A:$A,0),MATCH(Summary!$C20,'3.5.1'!$1:$1,0)),"") | U20: =_xlfn.IFNA(INDEX('3.5.1'!$1:$104,MATCH(U$4,'3.5.1'!$A:$A,0),MATCH(Summary!$C20,'3.5.1'!$1:$1,0)),"") | X20: =_xlfn.IFNA(INDEX('3.5.1'!$1:$104,MATCH(X$4,'3.5.1'!$A:$A,0),MATCH(Summary!$C20,'3.5.1'!$1:$1,0)),"") -> 27516.138 | AA20: =_xlfn.IFNA(INDEX('3.5.1'!$1:$104,MATCH(AA$4,'3.5.1'!$A:$A,0),MATCH(Summary!$C20,'3.5.1'!$1:$1,0)),"") | AD20: =_xlfn.IFNA(INDEX('3.5.1'!$1:$104,MATCH(AD$4,'3.5.1'!$A:$A,0),MATCH(Summary!$C20,'3.5.1'!$1:$1,0)),"") | AG20: =_xlfn.IFNA(INDEX('3.5.1'!$1:$104,MATCH(AG$4,'3.5.1'!$A:$A,0),MATCH(Summary!$C20,'3.5.1'!$1:$1,0)),"") -> 26813.224 | AJ20: =_xlfn.IFNA(INDEX('3.5.1'!$1:$104,MATCH(AJ$4,'3.5.1'!$A:$A,0),MATCH(Summary!$C20,'3.5.1'!$1:$1,0)),"") | AM20: =_xlfn.IFNA(INDEX('3.5.1'!$1:$104,MATCH(AM$4,'3.5.1'!$A:$A,0),MATCH(Summary!$C20,'3.5.1'!$1:$1,0)),"") | AP20: =_xlfn.IFNA(INDEX('3.5.1'!$1:$104,MATCH(AP$4,'3.5.1'!$A:$A,0),MATCH(Summary!$C20,'3.5.1'!$1:$1,0)),"") -> 27397.964 | AS20: =_xlfn.IFNA(INDEX('3.5.1'!$1:$104,MATCH(AS$4,'3.5.1'!$A:$A,0),MATCH(Summary!$C20,'3.5.1'!$1:$1,0)),"") | AV20: =_xlfn.IFNA(INDEX('3.5.1'!$1:$104,MATCH(AV$4,'3.5.1'!$A:$A,0),MATCH(Summary!$C20,'3.5.1'!$1:$1,0)),"") | AY20: =_xlfn.IFNA(INDEX('3.5.1'!$1:$104,MATCH(AY$4,'3.5.1'!$A:$A,0),MATCH(Summary!$C20,'3.5.1'!$1:$1,0)),"") -> 27564.337 | BB20: =_xlfn.IFNA(INDEX('3.5.1'!$1:$104,MATCH(BB$4,'3.5.1'!$A:$A,0),MATCH(Summary!$C20,'3.5.1'!$1:$1,0)),"") -> 21597.563 | BE20: =_xlfn.IFNA(INDEX('3.5.1'!$1:$104,MATCH(BE$4,'3.5.1'!$A:$A,0),MATCH(Summary!$C20,'3.5.1'!$1:$1,0)),"") | BH20: =_xlfn.IFNA(INDEX('3.5.1'!$1:$104,MATCH(BH$4,'3.5.1'!$A:$A,0),MATCH(Summary!$C20,'3.5.1'!$1:$1,0)),"") | BK20: =_xlfn.IFNA(INDEX('3.5.1'!$1:$104,MATCH(BK$4,'3.5.1'!$A:$A,0),MATCH(Summary!$C20,'3.5.1'!$1:$1,0)),"")
C21: mfg_metalengr | F21: Metal products and engineering | G21: 金屬製品及工程 | H21: =O21/$O$12 -> 0.0042592287 | I21: =IFERROR(L21/AV21-1,"") | L21: =_xlfn.IFNA(INDEX('3.5.1'!$1:$104,MATCH(L$4,'3.5.1'!$A:$A,0),MATCH(Summary!$C21,'3.5.1'!$1:$1,0)),"") | O21: =_xlfn.IFNA(INDEX('3.5.1'!$1:$104,MATCH(O$4,'3.5.1'!$A:$A,0),MATCH(Summary!$C21,'3.5.1'!$1:$1,0)),"") -> 45948.115 | R21: =_xlfn.IFNA(INDEX('3.5.1'!$1:$104,MATCH(R$4,'3.5.1'!$A:$A,0),MATCH(Summary!$C21,'3.5.1'!$1:$1,0)),"") | U21: =_xlfn.IFNA(INDEX('3.5.1'!$1:$104,MATCH(U$4,'3.5.1'!$A:$A,0),MATCH(Summary!$C21,'3.5.1'!$1:$1,0)),"") | X21: =_xlfn.IFNA(INDEX('3.5.1'!$1:$104,MATCH(X$4,'3.5.1'!$A:$A,0),MATCH(Summary!$C21,'3.5.1'!$1:$1,0)),"") -> 44021.965 | AA21: =_xlfn.IFNA(INDEX('3.5.1'!$1:$104,MATCH(AA$4,'3.5.1'!$A:$A,0),MATCH(Summary!$C21,'3.5.1'!$1:$1,0)),"") | AD21: =_xlfn.IFNA(INDEX('3.5.1'!$1:$104,MATCH(AD$4,'3.5.1'!$A:$A,0),MATCH(Summary!$C21,'3.5.1'!$1:$1,0)),"") | AG21: =_xlfn.IFNA(INDEX('3.5.1'!$1:$104,MATCH(AG$4,'3.5.1'!$A:$A,0),MATCH(Summary!$C21,'3.5.1'!$1:$1,0)),"") -> 39803.767 | AJ21: =_xlfn.IFNA(INDEX('3.5.1'!$1:$104,MATCH(AJ$4,'3.5.1'!$A:$A,0),MATCH(Summary!$C21,'3.5.1'!$1:$1,0)),"") | AM21: =_xlfn.IFNA(INDEX('3.5.1'!$1:$104,MATCH(AM$4,'3.5.1'!$A:$A,0),MATCH(Summary!$C21,'3.5.1'!$1:$1,0)),"") | AP21: =_xlfn.IFNA(INDEX('3.5.1'!$1:$104,MATCH(AP$4,'3.5.1'!$A:$A,0),MATCH(Summary!$C21,'3.5.1'!$1:$1,0)),"") -> 43053.556 | AS21: =_xlfn.IFNA(INDEX('3.5.1'!$1:$104,MATCH(AS$4,'3.5.1'!$A:$A,0),MATCH(Summary!$C21,'3.5.1'!$1:$1,0)),"") | AV21: =_xlfn.IFNA(INDEX('3.5.1'!$1:$104,MATCH(AV$4,'3.5.1'!$A:$A,0),MATCH(Summary!$C21,'3.5.1'!$1:$1,0)),"") | AY21: =_xlfn.IFNA(INDEX('3.5.1'!$1:$104,MATCH(AY$4,'3.5.1'!$A:$A,0),MATCH(Summary!$C21,'3.5.1'!$1:$1,0)),"") -> 43381.244 | BB21: =_xlfn.IFNA(INDEX('3.5.1'!$1:$104,MATCH(BB$4,'3.5.1'!$A:$A,0),MATCH(Summary!$C21,'3.5.1'!$1:$1,0)),"") -> 37385.872 | BE21: =_xlfn.IFNA(INDEX('3.5.1'!$1:$104,MATCH(BE$4,'3.5.1'!$A:$A,0),MATCH(Summary!$C21,'3.5.1'!$1:$1,0)),"") | BH21: =_xlfn.IFNA(INDEX('3.5.1'!$1:$104,MATCH(BH$4,'3.5.1'!$A:$A,0),MATCH(Summary!$C21,'3.5.1'!$1:$1,0)),"") | BK21: =_xlfn.IFNA(INDEX('3.5.1'!$1:$104,MATCH(BK$4,'3.5.1'!$A:$A,0),MATCH(Summary!$C21,'3.5.1'!$1:$1,0)),"")
C22: mfg_rubbplastchem | F22: Rubber, plastic and chemicals | G22: 橡膠、塑膠及化工 | H22: =O22/$O$12 -> 0.0067788867 | I22: =IFERROR(L22/AV22-1,"") | L22: =_xlfn.IFNA(INDEX('3.5.1'!$1:$104,MATCH(L$4,'3.5.1'!$A:$A,0),MATCH(Summary!$C22,'3.5.1'!$1:$1,0)),"") | O22: =_xlfn.IFNA(INDEX('3.5.1'!$1:$104,MATCH(O$4,'3.5.1'!$A:$A,0),MATCH(Summary!$C22,'3.5.1'!$1:$1,0)),"") -> 73129.923 | R22: =_xlfn.IFNA(INDEX('3.5.1'!$1:$104,MATCH(R$4,'3.5.1'!$A:$A,0),MATCH(Summary!$C22,'3.5.1'!$1:$1,0)),"") | U22: =_xlfn.IFNA(INDEX('3.5.1'!$1:$104,MATCH(U$4,'3.5.1'!$A:$A,0),MATCH(Summary!$C22,'3.5.1'!$1:$1,0)),"") | X22: =_xlfn.IFNA(INDEX('3.5.1'!$1:$104,MATCH(X$4,'3.5.1'!$A:$A,0),MATCH(Summary!$C22,'3.5.1'!$1:$1,0)),"") -> 63578.479 | AA22: =_xlfn.IFNA(INDEX('3.5.1'!$1:$104,MATCH(AA$4,'3.5.1'!$A:$A,0),MATCH(Summary!$C22,'3.5.1'!$1:$1,0)),"") | AD22: =_xlfn.IFNA(INDEX('3.5.1'!$1:$104,MATCH(AD$4,'3.5.1'!$A:$A,0),MATCH(Summary!$C22,'3.5.1'!$1:$1,0)),"") | AG22: =_xlfn.IFNA(INDEX('3.5.1'!$1:$104,MATCH(AG$4,'3.5.1'!$A:$A,0),MATCH(Summary!$C22,'3.5.1'!$1:$1,0)),"") -> 62683.653 | AJ22: =_xlfn.IFNA(INDEX('3.5.1'!$1:$104,MATCH(AJ$4,'3.5.1'!$A:$A,0),MATCH(Summary!$C22,'3.5.1'!$1:$1,0)),"") | AM22: =_xlfn.IFNA(INDEX('3.5.1'!$1:$104,MATCH(AM$4,'3.5.1'!$A:$A,0),MATCH(Summary!$C22,'3.5.1'!$1:$1,0)),"") | AP22: =_xlfn.IFNA(INDEX('3.5.1'!$1:$104,MATCH(AP$4,'3.5.1'!$A:$A,0),MATCH(Summary!$C22,'3.5.1'!$1:$1,0)),"") -> 72133.026 | AS22: =_xlfn.IFNA(INDEX('3.5.1'!$1:$104,MATCH(AS$4,'3.5.1'!$A:$A,0),MATCH(Summary!$C22,'3.5.1'!$1:$1,0)),"") | AV22: =_xlfn.IFNA(INDEX('3.5.1'!$1:$104,MATCH(AV$4,'3.5.1'!$A:$A,0),MATCH(Summary!$C22,'3.5.1'!$1:$1,0)),"") | AY22: =_xlfn.IFNA(INDEX('3.5.1'!$1:$104,MATCH(AY$4,'3.5.1'!$A:$A,0),MATCH(Summary!$C22,'3.5.1'!$1:$1,0)),"") -> 64991.74 | BB22: =_xlfn.IFNA(INDEX('3.5.1'!$1:$104,MATCH(BB$4,'3.5.1'!$A:$A,0),MATCH(Summary!$C22,'3.5.1'!$1:$1,0)),"") -> 57264.194 | BE22: =_xlfn.IFNA(INDEX('3.5.1'!$1:$104,MATCH(BE$4,'3.5.1'!$A:$A,0),MATCH(Summary!$C22,'3.5.1'!$1:$1,0)),"") | BH22: =_xlfn.IFNA(INDEX('3.5.1'!$1:$104,MATCH(BH$4,'3.5.1'!$A:$A,0),MATCH(Summary!$C22,'3.5.1'!$1:$1,0)),"") | BK22: =_xlfn.IFNA(INDEX('3.5.1'!$1:$104,MATCH(BK$4,'3.5.1'!$A:$A,0),MATCH(Summary!$C22,'3.5.1'!$1:$1,0)),"")
C23: mfg_shipbuildrepair | F23: Shipbuilding and repair 3 | G23: 造船及修理3 | H23: =O23/$O$12 -> 0 | I23: =IFERROR(L23/AV23-1,"") | L23: =_xlfn.IFNA(INDEX('3.5.1'!$1:$104,MATCH(L$4,'3.5.1'!$A:$A,0),MATCH(Summary!$C23,'3.5.1'!$1:$1,0)),"") | O23: =_xlfn.IFNA(INDEX('3.5.1'!$1:$104,MATCH(O$4,'3.5.1'!$A:$A,0),MATCH(Summary!$C23,'3.5.1'!$1:$1,0)),"") -> 0 | R23: =_xlfn.IFNA(INDEX('3.5.1'!$1:$104,MATCH(R$4,'3.5.1'!$A:$A,0),MATCH(Summary!$C23,'3.5.1'!$1:$1,0)),"") | U23: =_xlfn.IFNA(INDEX('3.5.1'!$1:$104,MATCH(U$4,'3.5.1'!$A:$A,0),MATCH(Summary!$C23,'3.5.1'!$1:$1,0)),"") | X23: =_xlfn.IFNA(INDEX('3.5.1'!$1:$104,MATCH(X$4,'3.5.1'!$A:$A,0),MATCH(Summary!$C23,'3.5.1'!$1:$1,0)),"") -> 0 | AA23: =_xlfn.IFNA(INDEX('3.5.1'!$1:$104,MATCH(AA$4,'3.5.1'!$A:$A,0),MATCH(Summary!$C23,'3.5.1'!$1:$1,0)),"") | AD23: =_xlfn.IFNA(INDEX('3.5.1'!$1:$104,MATCH(AD$4,'3.5.1'!$A:$A,0),MATCH(Summary!$C23,'3.5.1'!$1:$1,0)),"") | AG23: =_xlfn.IFNA(INDEX('3.5.1'!$1:$104,MATCH(AG$4,'3.5.1'!$A:$A,0),MATCH(Summary!$C23,'3.5.1'!$1:$1,0)),"") -> 0 | AJ23: =_xlfn.IFNA(INDEX('3.5.1'!$1:$104,MATCH(AJ$4,'3.5.1'!$A:$A,0),MATCH(Summary!$C23,'3.5.1'!$1:$1,0)),"") | AM23: =_xlfn.IFNA(INDEX('3.5.1'!$1:$104,MATCH(AM$4,'3.5.1'!$A:$A,0),MATCH(Summary!$C23,'3.5.1'!$1:$1,0)),"") | AP23: =_xlfn.IFNA(INDEX('3.5.1'!$1:$104,MATCH(AP$4,'3.5.1'!$A:$A,0),MATCH(Summary!$C23,'3.5.1'!$1:$1,0)),"") -> 0 | AS23: =_xlfn.IFNA(INDEX('3.5.1'!$1:$104,MATCH(AS$4,'3.5.1'!$A:$A,0),MATCH(Summary!$C23,'3.5.1'!$1:$1,0)),"") | AV23: =_xlfn.IFNA(INDEX('3.5.1'!$1:$104,MATCH(AV$4,'3.5.1'!$A:$A,0),MATCH(Summary!$C23,'3.5.1'!$1:$1,0)),"") | AY23: =_xlfn.IFNA(INDEX('3.5.1'!$1:$104,MATCH(AY$4,'3.5.1'!$A:$A,0),MATCH(Summary!$C23,'3.5.1'!$1:$1,0)),"") -> 0 | BB23: =_xlfn.IFNA(INDEX('3.5.1'!$1:$104,MATCH(BB$4,'3.5.1'!$A:$A,0),MATCH(Summary!$C23,'3.5.1'!$1:$1,0)),"") -> 0 | BE23: =_xlfn.IFNA(INDEX('3.5.1'!$1:$104,MATCH(BE$4,'3.5.1'!$A:$A,0),MATCH(Summary!$C23,'3.5.1'!$1:$1,0)),"") | BH23: =_xlfn.IFNA(INDEX('3.5.1'!$1:$104,MATCH(BH$4,'3.5.1'!$A:$A,0),MATCH(Summary!$C23,'3.5.1'!$1:$1,0)),"") | BK23: =_xlfn.IFNA(INDEX('3.5.1'!$1:$104,MATCH(BK$4,'3.5.1'!$A:$A,0),MATCH(Summary!$C23,'3.5.1'!$1:$1,0)),"")
C24: mfg_ee | F24: Electrical and electronic4 | G24: 電器及電子4 | H24: =O24/$O$12 -> 0.0056476257 | I24: =IFERROR(L24/AV24-1,"") | L24: =_xlfn.IFNA(INDEX('3.5.1'!$1:$104,MATCH(L$4,'3.5.1'!$A:$A,0),MATCH(Summary!$C24,'3.5.1'!$1:$1,0)),"") | O24: =_xlfn.IFNA(INDEX('3.5.1'!$1:$104,MATCH(O$4,'3.5.1'!$A:$A,0),MATCH(Summary!$C24,'3.5.1'!$1:$1,0)),"") -> 60925.997 | R24: =_xlfn.IFNA(INDEX('3.5.1'!$1:$104,MATCH(R$4,'3.5.1'!$A:$A,0),MATCH(Summary!$C24,'3.5.1'!$1:$1,0)),"") | U24: =_xlfn.IFNA(INDEX('3.5.1'!$1:$104,MATCH(U$4,'3.5.1'!$A:$A,0),MATCH(Summary!$C24,'3.5.1'!$1:$1,0)),"") | X24: =_xlfn.IFNA(INDEX('3.5.1'!$1:$104,MATCH(X$4,'3.5.1'!$A:$A,0),MATCH(Summary!$C24,'3.5.1'!$1:$1,0)),"") -> 61296.591 | AA24: =_xlfn.IFNA(INDEX('3.5.1'!$1:$104,MATCH(AA$4,'3.5.1'!$A:$A,0),MATCH(Summary!$C24,'3.5.1'!$1:$1,0)),"") | AD24: =_xlfn.IFNA(INDEX('3.5.1'!$1:$104,MATCH(AD$4,'3.5.1'!$A:$A,0),MATCH(Summary!$C24,'3.5.1'!$1:$1,0)),"") | AG24: =_xlfn.IFNA(INDEX('3.5.1'!$1:$104,MATCH(AG$4,'3.5.1'!$A:$A,0),MATCH(Summary!$C24,'3.5.1'!$1:$1,0)),"") -> 54150.184 | AJ24: =_xlfn.IFNA(INDEX('3.5.1'!$1:$104,MATCH(AJ$4,'3.5.1'!$A:$A,0),MATCH(Summary!$C24,'3.5.1'!$1:$1,0)),"") | AM24: =_xlfn.IFNA(INDEX('3.5.1'!$1:$104,MATCH(AM$4,'3.5.1'!$A:$A,0),MATCH(Summary!$C24,'3.5.1'!$1:$1,0)),"") | AP24: =_xlfn.IFNA(INDEX('3.5.1'!$1:$104,MATCH(AP$4,'3.5.1'!$A:$A,0),MATCH(Summary!$C24,'3.5.1'!$1:$1,0)),"") -> 49492.873 | AS24: =_xlfn.IFNA(INDEX('3.5.1'!$1:$104,MATCH(AS$4,'3.5.1'!$A:$A,0),MATCH(Summary!$C24,'3.5.1'!$1:$1,0)),"") | AV24: =_xlfn.IFNA(INDEX('3.5.1'!$1:$104,MATCH(AV$4,'3.5.1'!$A:$A,0),MATCH(Summary!$C24,'3.5.1'!$1:$1,0)),"") | AY24: =_xlfn.IFNA(INDEX('3.5.1'!$1:$104,MATCH(AY$4,'3.5.1'!$A:$A,0),MATCH(Summary!$C24,'3.5.1'!$1:$1,0)),"") -> 51873.188 | BB24: =_xlfn.IFNA(INDEX('3.5.1'!$1:$104,MATCH(BB$4,'3.5.1'!$A:$A,0),MATCH(Summary!$C24,'3.5.1'!$1:$1,0)),"") -> 52623.241 | BE24: =_xlfn.IFNA(INDEX('3.5.1'!$1:$104,MATCH(BE$4,'3.5.1'!$A:$A,0),MATCH(Summary!$C24,'3.5.1'!$1:$1,0)),"") | BH24: =_xlfn.IFNA(INDEX('3.5.1'!$1:$104,MATCH(BH$4,'3.5.1'!$A:$A,0),MATCH(Summary!$C24,'3.5.1'!$1:$1,0)),"") | BK24: =_xlfn.IFNA(INDEX('3.5.1'!$1:$104,MATCH(BK$4,'3.5.1'!$A:$A,0),MATCH(Summary!$C24,'3.5.1'!$1:$1,0)),"")
C25: mfg_ee_teleequip | F25: Telecommunication equipment | G25: 電子通訊設備 | H25: =O25/$O$12 -> 0.00092683942 | I25: =IFERROR(L25/AV25-1,"") | L25: =_xlfn.IFNA(INDEX('3.5.1'!$1:$104,MATCH(L$4,'3.5.1'!$A:$A,0),MATCH(Summary!$C25,'3.5.1'!$1:$1,0)),"") | O25: =_xlfn.IFNA(INDEX('3.5.1'!$1:$104,MATCH(O$4,'3.5.1'!$A:$A,0),MATCH(Summary!$C25,'3.5.1'!$1:$1,0)),"") -> 9998.647 | R25: =_xlfn.IFNA(INDEX('3.5.1'!$1:$104,MATCH(R$4,'3.5.1'!$A:$A,0),MATCH(Summary!$C25,'3.5.1'!$1:$1,0)),"") | U25: =_xlfn.IFNA(INDEX('3.5.1'!$1:$104,MATCH(U$4,'3.5.1'!$A:$A,0),MATCH(Summary!$C25,'3.5.1'!$1:$1,0)),"") | X25: =_xlfn.IFNA(INDEX('3.5.1'!$1:$104,MATCH(X$4,'3.5.1'!$A:$A,0),MATCH(Summary!$C25,'3.5.1'!$1:$1,0)),"") -> 6636.04 | AA25: =_xlfn.IFNA(INDEX('3.5.1'!$1:$104,MATCH(AA$4,'3.5.1'!$A:$A,0),MATCH(Summary!$C25,'3.5.1'!$1:$1,0)),"") | AD25: =_xlfn.IFNA(INDEX('3.5.1'!$1:$104,MATCH(AD$4,'3.5.1'!$A:$A,0),MATCH(Summary!$C25,'3.5.1'!$1:$1,0)),"") | AG25: =_xlfn.IFNA(INDEX('3.5.1'!$1:$104,MATCH(AG$4,'3.5.1'!$A:$A,0),MATCH(Summary!$C25,'3.5.1'!$1:$1,0)),"") -> 6090.297 | AJ25: =_xlfn.IFNA(INDEX('3.5.1'!$1:$104,MATCH(AJ$4,'3.5.1'!$A:$A,0),MATCH(Summary!$C25,'3.5.1'!$1:$1,0)),"") | AM25: =_xlfn.IFNA(INDEX('3.5.1'!$1:$104,MATCH(AM$4,'3.5.1'!$A:$A,0),MATCH(Summary!$C25,'3.5.1'!$1:$1,0)),"") | AP25: =_xlfn.IFNA(INDEX('3.5.1'!$1:$104,MATCH(AP$4,'3.5.1'!$A:$A,0),MATCH(Summary!$C25,'3.5.1'!$1:$1,0)),"") -> 5069.957 | AS25: =_xlfn.IFNA(INDEX('3.5.1'!$1:$104,MATCH(AS$4,'3.5.1'!$A:$A,0),MATCH(Summary!$C25,'3.5.1'!$1:$1,0)),"") | AV25: =_xlfn.IFNA(INDEX('3.5.1'!$1:$104,MATCH(AV$4,'3.5.1'!$A:$A,0),MATCH(Summary!$C25,'3.5.1'!$1:$1,0)),"") | AY25: =_xlfn.IFNA(INDEX('3.5.1'!$1:$104,MATCH(AY$4,'3.5.1'!$A:$A,0),MATCH(Summary!$C25,'3.5.1'!$1:$1,0)),"") -> 5434.78 | BB25: =_xlfn.IFNA(INDEX('3.5.1'!$1:$104,MATCH(BB$4,'3.5.1'!$A:$A,0),MATCH(Summary!$C25,'3.5.1'!$1:$1,0)),"") -> 6571.414 | BE25: =_xlfn.IFNA(INDEX('3.5.1'!$1:$104,MATCH(BE$4,'3.5.1'!$A:$A,0),MATCH(Summary!$C25,'3.5.1'!$1:$1,0)),"") | BH25: =_xlfn.IFNA(INDEX('3.5.1'!$1:$104,MATCH(BH$4,'3.5.1'!$A:$A,0),MATCH(Summary!$C25,'3.5.1'!$1:$1,0)),"") | BK25: =_xlfn.IFNA(INDEX('3.5.1'!$1:$104,MATCH(BK$4,'3.5.1'!$A:$A,0),MATCH(Summary!$C25,'3.5.1'!$1:$1,0)),"")
C26: mfg_ee_other | F26: Others | G26: 其他 | H26: =O26/$O$12 -> 0.0047207863 | I26: =IFERROR(L26/AV26-1,"") | L26: =_xlfn.IFNA(INDEX('3.5.1'!$1:$104,MATCH(L$4,'3.5.1'!$A:$A,0),MATCH(Summary!$C26,'3.5.1'!$1:$1,0)),"") | O26: =_xlfn.IFNA(INDEX('3.5.1'!$1:$104,MATCH(O$4,'3.5.1'!$A:$A,0),MATCH(Summary!$C26,'3.5.1'!$1:$1,0)),"") -> 50927.35 | R26: =_xlfn.IFNA(INDEX('3.5.1'!$1:$104,MATCH(R$4,'3.5.1'!$A:$A,0),MATCH(Summary!$C26,'3.5.1'!$1:$1,0)),"") | U26: =_xlfn.IFNA(INDEX('3.5.1'!$1:$104,MATCH(U$4,'3.5.1'!$A:$A,0),MATCH(Summary!$C26,'3.5.1'!$1:$1,0)),"") | X26: =_xlfn.IFNA(INDEX('3.5.1'!$1:$104,MATCH(X$4,'3.5.1'!$A:$A,0),MATCH(Summary!$C26,'3.5.1'!$1:$1,0)),"") -> 54660.551 | AA26: =_xlfn.IFNA(INDEX('3.5.1'!$1:$104,MATCH(AA$4,'3.5.1'!$A:$A,0),MATCH(Summary!$C26,'3.5.1'!$1:$1,0)),"") | AD26: =_xlfn.IFNA(INDEX('3.5.1'!$1:$104,MATCH(AD$4,'3.5.1'!$A:$A,0),MATCH(Summary!$C26,'3.5.1'!$1:$1,0)),"") | AG26: =_xlfn.IFNA(INDEX('3.5.1'!$1:$104,MATCH(AG$4,'3.5.1'!$A:$A,0),MATCH(Summary!$C26,'3.5.1'!$1:$1,0)),"") -> 48059.887 | AJ26: =_xlfn.IFNA(INDEX('3.5.1'!$1:$104,MATCH(AJ$4,'3.5.1'!$A:$A,0),MATCH(Summary!$C26,'3.5.1'!$1:$1,0)),"") | AM26: =_xlfn.IFNA(INDEX('3.5.1'!$1:$104,MATCH(AM$4,'3.5.1'!$A:$A,0),MATCH(Summary!$C26,'3.5.1'!$1:$1,0)),"") | AP26: =_xlfn.IFNA(INDEX('3.5.1'!$1:$104,MATCH(AP$4,'3.5.1'!$A:$A,0),MATCH(Summary!$C26,'3.5.1'!$1:$1,0)),"") -> 44422.916 | AS26: =_xlfn.IFNA(INDEX('3.5.1'!$1:$104,MATCH(AS$4,'3.5.1'!$A:$A,0),MATCH(Summary!$C26,'3.5.1'!$1:$1,0)),"") | AV26: =_xlfn.IFNA(INDEX('3.5.1'!$1:$104,MATCH(AV$4,'3.5.1'!$A:$A,0),MATCH(Summary!$C26,'3.5.1'!$1:$1,0)),"") | AY26: =_xlfn.IFNA(INDEX('3.5.1'!$1:$104,MATCH(AY$4,'3.5.1'!$A:$A,0),MATCH(Summary!$C26,'3.5.1'!$1:$1,0)),"") -> 46438.408 | BB26: =_xlfn.IFNA(INDEX('3.5.1'!$1:$104,MATCH(BB$4,'3.5.1'!$A:$A,0),MATCH(Summary!$C26,'3.5.1'!$1:$1,0)),"") -> 46051.827 | BE26: =_xlfn.IFNA(INDEX('3.5.1'!$1:$104,MATCH(BE$4,'3.5.1'!$A:$A,0),MATCH(Summary!$C26,'3.5.1'!$1:$1,0)),"") | BH26: =_xlfn.IFNA(INDEX('3.5.1'!$1:$104,MATCH(BH$4,'3.5.1'!$A:$A,0),MATCH(Summary!$C26,'3.5.1'!$1:$1,0)),"") | BK26: =_xlfn.IFNA(INDEX('3.5.1'!$1:$104,MATCH(BK$4,'3.5.1'!$A:$A,0),MATCH(Summary!$C26,'3.5.1'!$1:$1,0)),"")
C27: mfg_food | F27: Food | G27: 食品 | H27: =O27/$O$12 -> 0.0023406006 | I27: =IFERROR(L27/AV27-1,"") | L27: =_xlfn.IFNA(INDEX('3.5.1'!$1:$104,MATCH(L$4,'3.5.1'!$A:$A,0),MATCH(Summary!$C27,'3.5.1'!$1:$1,0)),"") | O27: =_xlfn.IFNA(INDEX('3.5.1'!$1:$104,MATCH(O$4,'3.5.1'!$A:$A,0),MATCH(Summary!$C27,'3.5.1'!$1:$1,0)),"") -> 25250.155 | R27: =_xlfn.IFNA(INDEX('3.5.1'!$1:$104,MATCH(R$4,'3.5.1'!$A:$A,0),MATCH(Summary!$C27,'3.5.1'!$1:$1,0)),"") | U27: =_xlfn.IFNA(INDEX('3.5.1'!$1:$104,MATCH(U$4,'3.5.1'!$A:$A,0),MATCH(Summary!$C27,'3.5.1'!$1:$1,0)),"") | X27: =_xlfn.IFNA(INDEX('3.5.1'!$1:$104,MATCH(X$4,'3.5.1'!$A:$A,0),MATCH(Summary!$C27,'3.5.1'!$1:$1,0)),"") -> 21536.222 | AA27: =_xlfn.IFNA(INDEX('3.5.1'!$1:$104,MATCH(AA$4,'3.5.1'!$A:$A,0),MATCH(Summary!$C27,'3.5.1'!$1:$1,0)),"") | AD27: =_xlfn.IFNA(INDEX('3.5.1'!$1:$104,MATCH(AD$4,'3.5.1'!$A:$A,0),MATCH(Summary!$C27,'3.5.1'!$1:$1,0)),"") | AG27: =_xlfn.IFNA(INDEX('3.5.1'!$1:$104,MATCH(AG$4,'3.5.1'!$A:$A,0),MATCH(Summary!$C27,'3.5.1'!$1:$1,0)),"") -> 21795.043 | AJ27: =_xlfn.IFNA(INDEX('3.5.1'!$1:$104,MATCH(AJ$4,'3.5.1'!$A:$A,0),MATCH(Summary!$C27,'3.5.1'!$1:$1,0)),"") | AM27: =_xlfn.IFNA(INDEX('3.5.1'!$1:$104,MATCH(AM$4,'3.5.1'!$A:$A,0),MATCH(Summary!$C27,'3.5.1'!$1:$1,0)),"") | AP27: =_xlfn.IFNA(INDEX('3.5.1'!$1:$104,MATCH(AP$4,'3.5.1'!$A:$A,0),MATCH(Summary!$C27,'3.5.1'!$1:$1,0)),"") -> 26661.418 | AS27: =_xlfn.IFNA(INDEX('3.5.1'!$1:$104,MATCH(AS$4,'3.5.1'!$A:$A,0),MATCH(Summary!$C27,'3.5.1'!$1:$1,0)),"") | AV27: =_xlfn.IFNA(INDEX('3.5.1'!$1:$104,MATCH(AV$4,'3.5.1'!$A:$A,0),MATCH(Summary!$C27,'3.5.1'!$1:$1,0)),"") | AY27: =_xlfn.IFNA(INDEX('3.5.1'!$1:$104,MATCH(AY$4,'3.5.1'!$A:$A,0),MATCH(Summary!$C27,'3.5.1'!$1:$1,0)),"") -> 26633.559 | BB27: =_xlfn.IFNA(INDEX('3.5.1'!$1:$104,MATCH(BB$4,'3.5.1'!$A:$A,0),MATCH(Summary!$C27,'3.5.1'!$1:$1,0)),"") -> 23465.175 | BE27: =_xlfn.IFNA(INDEX('3.5.1'!$1:$104,MATCH(BE$4,'3.5.1'!$A:$A,0),MATCH(Summary!$C27,'3.5.1'!$1:$1,0)),"") | BH27: =_xlfn.IFNA(INDEX('3.5.1'!$1:$104,MATCH(BH$4,'3.5.1'!$A:$A,0),MATCH(Summary!$C27,'3.5.1'!$1:$1,0)),"") | BK27: =_xlfn.IFNA(INDEX('3.5.1'!$1:$104,MATCH(BK$4,'3.5.1'!$A:$A,0),MATCH(Summary!$C27,'3.5.1'!$1:$1,0)),"")
C28: mfg_bevtob | F28: Beverages and tobacco | G28: 飲料及煙草 | H28: =O28/$O$12 -> 0.0016299045 | I28: =IFERROR(L28/AV28-1,"") | L28: =_xlfn.IFNA(INDEX('3.5.1'!$1:$104,MATCH(L$4,'3.5.1'!$A:$A,0),MATCH(Summary!$C28,'3.5.1'!$1:$1,0)),"") | O28: =_xlfn.IFNA(INDEX('3.5.1'!$1:$104,MATCH(O$4,'3.5.1'!$A:$A,0),MATCH(Summary!$C28,'3.5.1'!$1:$1,0)),"") -> 17583.24 | R28: =_xlfn.IFNA(INDEX('3.5.1'!$1:$104,MATCH(R$4,'3.5.1'!$A:$A,0),MATCH(Summary!$C28,'3.5.1'!$1:$1,0)),"") | U28: =_xlfn.IFNA(INDEX('3.5.1'!$1:$104,MATCH(U$4,'3.5.1'!$A:$A,0),MATCH(Summary!$C28,'3.5.1'!$1:$1,0)),"") | X28: =_xlfn.IFNA(INDEX('3.5.1'!$1:$104,MATCH(X$4,'3.5.1'!$A:$A,0),MATCH(Summary!$C28,'3.5.1'!$1:$1,0)),"") -> 13861.623 | AA28: =_xlfn.IFNA(INDEX('3.5.1'!$1:$104,MATCH(AA$4,'3.5.1'!$A:$A,0),MATCH(Summary!$C28,'3.5.1'!$1:$1,0)),"") | AD28: =_xlfn.IFNA(INDEX('3.5.1'!$1:$104,MATCH(AD$4,'3.5.1'!$A:$A,0),MATCH(Summary!$C28,'3.5.1'!$1:$1,0)),"") | AG28: =_xlfn.IFNA(INDEX('3.5.1'!$1:$104,MATCH(AG$4,'3.5.1'!$A:$A,0),MATCH(Summary!$C28,'3.5.1'!$1:$1,0)),"") -> 10977.891 | AJ28: =_xlfn.IFNA(INDEX('3.5.1'!$1:$104,MATCH(AJ$4,'3.5.1'!$A:$A,0),MATCH(Summary!$C28,'3.5.1'!$1:$1,0)),"") | AM28: =_xlfn.IFNA(INDEX('3.5.1'!$1:$104,MATCH(AM$4,'3.5.1'!$A:$A,0),MATCH(Summary!$C28,'3.5.1'!$1:$1,0)),"") | AP28: =_xlfn.IFNA(INDEX('3.5.1'!$1:$104,MATCH(AP$4,'3.5.1'!$A:$A,0),MATCH(Summary!$C28,'3.5.1'!$1:$1,0)),"") -> 14172.343 | AS28: =_xlfn.IFNA(INDEX('3.5.1'!$1:$104,MATCH(AS$4,'3.5.1'!$A:$A,0),MATCH(Summary!$C28,'3.5.1'!$1:$1,0)),"") | AV28: =_xlfn.IFNA(INDEX('3.5.1'!$1:$104,MATCH(AV$4,'3.5.1'!$A:$A,0),MATCH(Summary!$C28,'3.5.1'!$1:$1,0)),"") | AY28: =_xlfn.IFNA(INDEX('3.5.1'!$1:$104,MATCH(AY$4,'3.5.1'!$A:$A,0),MATCH(Summary!$C28,'3.5.1'!$1:$1,0)),"") -> 12774.037 | BB28: =_xlfn.IFNA(INDEX('3.5.1'!$1:$104,MATCH(BB$4,'3.5.1'!$A:$A,0),MATCH(Summary!$C28,'3.5.1'!$1:$1,0)),"") -> 13452.56 | BE28: =_xlfn.IFNA(INDEX('3.5.1'!$1:$104,MATCH(BE$4,'3.5.1'!$A:$A,0),MATCH(Summary!$C28,'3.5.1'!$1:$1,0)),"") | BH28: =_xlfn.IFNA(INDEX('3.5.1'!$1:$104,MATCH(BH$4,'3.5.1'!$A:$A,0),MATCH(Summary!$C28,'3.5.1'!$1:$1,0)),"") | BK28: =_xlfn.IFNA(INDEX('3.5.1'!$1:$104,MATCH(BK$4,'3.5.1'!$A:$A,0),MATCH(Summary!$C28,'3.5.1'!$1:$1,0)),"")
C29: mfg_printpub | F29: Printing and publishing | G29: 印刷及出版 | H29: =O29/$O$12 -> 0.0004226625 | I29: =IFERROR(L29/AV29-1,"") | L29: =_xlfn.IFNA(INDEX('3.5.1'!$1:$104,MATCH(L$4,'3.5.1'!$A:$A,0),MATCH(Summary!$C29,'3.5.1'!$1:$1,0)),"") | O29: =_xlfn.IFNA(INDEX('3.5.1'!$1:$104,MATCH(O$4,'3.5.1'!$A:$A,0),MATCH(Summary!$C29,'3.5.1'!$1:$1,0)),"") -> 4559.639 | R29: =_xlfn.IFNA(INDEX('3.5.1'!$1:$104,MATCH(R$4,'3.5.1'!$A:$A,0),MATCH(Summary!$C29,'3.5.1'!$1:$1,0)),"") | U29: =_xlfn.IFNA(INDEX('3.5.1'!$1:$104,MATCH(U$4,'3.5.1'!$A:$A,0),MATCH(Summary!$C29,'3.5.1'!$1:$1,0)),"") | X29: =_xlfn.IFNA(INDEX('3.5.1'!$1:$104,MATCH(X$4,'3.5.1'!$A:$A,0),MATCH(Summary!$C29,'3.5.1'!$1:$1,0)),"") -> 4752.796 | AA29: =_xlfn.IFNA(INDEX('3.5.1'!$1:$104,MATCH(AA$4,'3.5.1'!$A:$A,0),MATCH(Summary!$C29,'3.5.1'!$1:$1,0)),"") | AD29: =_xlfn.IFNA(INDEX('3.5.1'!$1:$104,MATCH(AD$4,'3.5.1'!$A:$A,0),MATCH(Summary!$C29,'3.5.1'!$1:$1,0)),"") | AG29: =_xlfn.IFNA(INDEX('3.5.1'!$1:$104,MATCH(AG$4,'3.5.1'!$A:$A,0),MATCH(Summary!$C29,'3.5.1'!$1:$1,0)),"") -> 4592.36 | AJ29: =_xlfn.IFNA(INDEX('3.5.1'!$1:$104,MATCH(AJ$4,'3.5.1'!$A:$A,0),MATCH(Summary!$C29,'3.5.1'!$1:$1,0)),"") | AM29: =_xlfn.IFNA(INDEX('3.5.1'!$1:$104,MATCH(AM$4,'3.5.1'!$A:$A,0),MATCH(Summary!$C29,'3.5.1'!$1:$1,0)),"") | AP29: =_xlfn.IFNA(INDEX('3.5.1'!$1:$104,MATCH(AP$4,'3.5.1'!$A:$A,0),MATCH(Summary!$C29,'3.5.1'!$1:$1,0)),"") -> 4926.074 | AS29: =_xlfn.IFNA(INDEX('3.5.1'!$1:$104,MATCH(AS$4,'3.5.1'!$A:$A,0),MATCH(Summary!$C29,'3.5.1'!$1:$1,0)),"") | AV29: =_xlfn.IFNA(INDEX('3.5.1'!$1:$104,MATCH(AV$4,'3.5.1'!$A:$A,0),MATCH(Summary!$C29,'3.5.1'!$1:$1,0)),"") | AY29: =_xlfn.IFNA(INDEX('3.5.1'!$1:$104,MATCH(AY$4,'3.5.1'!$A:$A,0),MATCH(Summary!$C29,'3.5.1'!$1:$1,0)),"") -> 4869.311 | BB29: =_xlfn.IFNA(INDEX('3.5.1'!$1:$104,MATCH(BB$4,'3.5.1'!$A:$A,0),MATCH(Summary!$C29,'3.5.1'!$1:$1,0)),"") -> 4312.302 | BE29: =_xlfn.IFNA(INDEX('3.5.1'!$1:$104,MATCH(BE$4,'3.5.1'!$A:$A,0),MATCH(Summary!$C29,'3.5.1'!$1:$1,0)),"") | BH29: =_xlfn.IFNA(INDEX('3.5.1'!$1:$104,MATCH(BH$4,'3.5.1'!$A:$A,0),MATCH(Summary!$C29,'3.5.1'!$1:$1,0)),"") | BK29: =_xlfn.IFNA(INDEX('3.5.1'!$1:$104,MATCH(BK$4,'3.5.1'!$A:$A,0),MATCH(Summary!$C29,'3.5.1'!$1:$1,0)),"")
... C66: misc_prof_purschflat | F66: For the purchase of flats in Home Ownership | G66: 購買「居者有其屋計劃」、「私人機構 | H66: =O66/$O$12 -> 0.015537359 | I66: =IFERROR(L66/AV66-1,"") | L66: =_xlfn.IFNA(INDEX('3.5.1'!$1:$104,MATCH(L$4,'3.5.1'!$A:$A,0),MATCH(Summary!$C66,'3.5.1'!$1:$1,0)),"") | O66: =_xlfn.IFNA(INDEX('3.5.1'!$1:$104,MATCH(O$4,'3.5.1'!$A:$A,0),MATCH(Summary!$C66,'3.5.1'!$1:$1,0)),"") -> 167615.41 | R66: =_xlfn.IFNA(INDEX('3.5.1'!$1:$104,MATCH(R$4,'3.5.1'!$A:$A,0),MATCH(Summary!$C66,'3.5.1'!$1:$1,0)),"") | U66: =_xlfn.IFNA(INDEX('3.5.1'!$1:$104,MATCH(U$4,'3.5.1'!$A:$A,0),MATCH(Summary!$C66,'3.5.1'!$1:$1,0)),"") | X66: =_xlfn.IFNA(INDEX('3.5.1'!$1:$104,MATCH(X$4,'3.5.1'!$A:$A,0),MATCH(Summary!$C66,'3.5.1'!$1:$1,0)),"") -> 156519.89 | AA66: =_xlfn.IFNA(INDEX('3.5.1'!$1:$104,MATCH(AA$4,'3.5.1'!$A:$A,0),MATCH(Summary!$C66,'3.5.1'!$1:$1,0)),"") | AD66: =_xlfn.IFNA(INDEX('3.5.1'!$1:$104,MATCH(AD$4,'3.5.1'!$A:$A,0),MATCH(Summary!$C66,'3.5.1'!$1:$1,0)),"") | AG66: =_xlfn.IFNA(INDEX('3.5.1'!$1:$104,MATCH(AG$4,'3.5.1'!$A:$A,0),MATCH(Summary!$C66,'3.5.1'!$1:$1,0)),"") -> 153280.41 | AJ66: =_xlfn.IFNA(INDEX('3.5.1'!$1:$104,MATCH(AJ$4,'3.5.1'!$A:$A,0),MATCH(Summary!$C66,'3.5.1'!$1:$1,0)),"") | AM66: =_xlfn.IFNA(INDEX('3.5.1'!$1:$104,MATCH(AM$4,'3.5.1'!$A:$A,0),MATCH(Summary!$C66,'3.5.1'!$1:$1,0)),"") | AP66: =_xlfn.IFNA(INDEX('3.5.1'!$1:$104,MATCH(AP$4,'3.5.1'!$A:$A,0),MATCH(Summary!$C66,'3.5.1'!$1:$1,0)),"") -> 152236.39 | AS66: =_xlfn.IFNA(INDEX('3.5.1'!$1:$104,MATCH(AS$4,'3.5.1'!$A:$A,0),MATCH(Summary!$C66,'3.5.1'!$1:$1,0)),"") | AV66: =_xlfn.IFNA(INDEX('3.5.1'!$1:$104,MATCH(AV$4,'3.5.1'!$A:$A,0),MATCH(Summary!$C66,'3.5.1'!$1:$1,0)),"") | AY66: =_xlfn.IFNA(INDEX('3.5.1'!$1:$104,MATCH(AY$4,'3.5.1'!$A:$A,0),MATCH(Summary!$C66,'3.5.1'!$1:$1,0)),"") -> 141918.08 | BB66: =_xlfn.IFNA(INDEX('3.5.1'!$1:$104,MATCH(BB$4,'3.5.1'!$A:$A,0),MATCH(Summary!$C66,'3.5.1'!$1:$1,0)),"") -> 132720.03 | BE66: =_xlfn.IFNA(INDEX('3.5.1'!$1:$104,MATCH(BE$4,'3.5.1'!$A:$A,0),MATCH(Summary!$C66,'3.5.1'!$1:$1,0)),"") | BH66: =_xlfn.IFNA(INDEX('3.5.1'!$1:$104,MATCH(BH$4,'3.5.1'!$A:$A,0),MATCH(Summary!$C66,'3.5.1'!$1:$1,0)),"") | BK66: =_xlfn.IFNA(INDEX('3.5.1'!$1:$104,MATCH(BK$4,'3.5.1'!$A:$A,0),MATCH(Summary!$C66,'3.5.1'!$1:$1,0)),"")
F67: Scheme, Private Sector Participation | G67: 參建居屋計劃」及「租者置其屋計劃」 | H67: =O67/$O$12 -> 0 | I67: =IFERROR(L67/AV67-1,"")
F68: Scheme & Tenants Purchase Scheme | G68: 單位 | H68: =O68/$O$12 -> 0 | I68: =IFERROR(L68/AV68-1,"")
C69: misc_prof_purother | F69: For the purchase of other residential properties | G69: 購買其他住宅樓宇 | H69: =O69/$O$12 -> 0.18153148 | I69: =IFERROR(L69/AV69-1,"") | L69: =_xlfn.IFNA(INDEX('3.5.1'!$1:$104,MATCH(L$4,'3.5.1'!$A:$A,0),MATCH(Summary!$C69,'3.5.1'!$1:$1,0)),"") | O69: =_xlfn.IFNA(INDEX('3.5.1'!$1:$104,MATCH(O$4,'3.5.1'!$A:$A,0),MATCH(Summary!$C69,'3.5.1'!$1:$1,0)),"") -> 1958342.7 | R69: =_xlfn.IFNA(INDEX('3.5.1'!$1:$104,MATCH(R$4,'3.5.1'!$A:$A,0),MATCH(Summary!$C69,'3.5.1'!$1:$1,0)),"") | U69: =_xlfn.IFNA(INDEX('3.5.1'!$1:$104,MATCH(U$4,'3.5.1'!$A:$A,0),MATCH(Summary!$C69,'3.5.1'!$1:$1,0)),"") | X69: =_xlfn.IFNA(INDEX('3.5.1'!$1:$104,MATCH(X$4,'3.5.1'!$A:$A,0),MATCH(Summary!$C69,'3.5.1'!$1:$1,0)),"") -> 1937565.9 | AA69: =_xlfn.IFNA(INDEX('3.5.1'!$1:$104,MATCH(AA$4,'3.5.1'!$A:$A,0),MATCH(Summary!$C69,'3.5.1'!$1:$1,0)),"") | AD69: =_xlfn.IFNA(INDEX('3.5.1'!$1:$104,MATCH(AD$4,'3.5.1'!$A:$A,0),MATCH(Summary!$C69,'3.5.1'!$1:$1,0)),"") | AG69: =_xlfn.IFNA(INDEX('3.5.1'!$1:$104,MATCH(AG$4,'3.5.1'!$A:$A,0),MATCH(Summary!$C69,'3.5.1'!$1:$1,0)),"") -> 1920476.5 | AJ69: =_xlfn.IFNA(INDEX('3.5.1'!$1:$104,MATCH(AJ$4,'3.5.1'!$A:$A,0),MATCH(Summary!$C69,'3.5.1'!$1:$1,0)),"") | AM69: =_xlfn.IFNA(INDEX('3.5.1'!$1:$104,MATCH(AM$4,'3.5.1'!$A:$A,0),MATCH(Summary!$C69,'3.5.1'!$1:$1,0)),"") | AP69: =_xlfn.IFNA(INDEX('3.5.1'!$1:$104,MATCH(AP$4,'3.5.1'!$A:$A,0),MATCH(Summary!$C69,'3.5.1'!$1:$1,0)),"") -> 1894347 | AS69: =_xlfn.IFNA(INDEX('3.5.1'!$1:$104,MATCH(AS$4,'3.5.1'!$A:$A,0),MATCH(Summary!$C69,'3.5.1'!$1:$1,0)),"") | AV69: =_xlfn.IFNA(INDEX('3.5.1'!$1:$104,MATCH(AV$4,'3.5.1'!$A:$A,0),MATCH(Summary!$C69,'3.5.1'!$1:$1,0)),"") | AY69: =_xlfn.IFNA(INDEX('3.5.1'!$1:$104,MATCH(AY$4,'3.5.1'!$A:$A,0),MATCH(Summary!$C69,'3.5.1'!$1:$1,0)),"") -> 1889329.5 | BB69: =_xlfn.IFNA(INDEX('3.5.1'!$1:$104,MATCH(BB$4,'3.5.1'!$A:$A,0),MATCH(Summary!$C69,'3.5.1'!$1:$1,0)),"") -> 1873532.5 | BE69: =_xlfn.IFNA(INDEX('3.5.1'!$1:$104,MATCH(BE$4,'3.5.1'!$A:$A,0),MATCH(Summary!$C69,'3.5.1'!$1:$1,0)),"") | BH69: =_xlfn.IFNA(INDEX('3.5.1'!$1:$104,MATCH(BH$4,'3.5.1'!$A:$A,0),MATCH(Summary!$C69,'3.5.1'!$1:$1,0)),"") | BK69: =_xlfn.IFNA(INDEX('3.5.1'!$1:$104,MATCH(BK$4,'3.5.1'!$A:$A,0),MATCH(Summary!$C69,'3.5.1'!$1:$1,0)),"")
